Workbook

Sheet Summary - SFR - Global
A2: Sony France
A4: FY | B4: FY24 | Q4: FY | R4: FY23
A5: PO Status | B5: (Tous) | Q5: PO Status | R5: PO en attente
A7: Sum of Total Value | D7: Month | Q7: Sum of Total Value | T7: Month
A8: Team | B8: Contact | C8: Project | D8: 01-APR | E8: 02-MAY | F8: 03-JUN | G8: 04-JUL | H8: 05-AUG | I8: 06-SEP | J8: 07-OCT | K8: 08-NOV | L8: 10-JAN | M8: 11-FEB | N8: 12-MAR | O8: Total | Q8: Team | R8: Category | S8: Project | T8: Total
A9: (vide) | B9: Alice Mucke | I9: 120 | O9: 120 | Q9: Total
B10: Kenza Touili | I10: 215 | O10: 215
B11: Justine RODRIGUES | C11: SDLP - Leaflet Vlogging | I11: 180 | O11: 180
A12: CM | B12: Alice Mucke | D12: 605 | E12: 2120 | F12: 1210 | G12: 1245 | H12: 895 | I12: 70 | M12: 270 | N12: 825 | O12: 7240
B13: Lucia Alvaro | D13: 1295 | E13: 1170 | L13: 600 | O13: 3065
B14: Mylène Pellet | D14: 1410 | G14: 645 | O14: 2055
B15: Xanthi Ountzoudi | J15: 775 | O15: 775
A16: BA | B16: Anissa Azediou | D16: 3020 | E16: 440 | G16: 160 | H16: 2450 | I16: 405 | J16: 540 | N16: 495 | O16: 7510
B17: Astrid Jean-Baptiste | D17: 1860 | E17: 2765 | F17: 2270 | G17: 5490 | H17: 540 | N17: 1960 | O17: 14885
B18: Françoise Burgarella | D18: 70 | O18: 70
B19: Héloïse Leroy | C19: Stickers vitrines - Dealer Days 2024 | M19: 175 | O19: 175
C20: Mise au format visuel JPO FNAC Audio | E20: 40 | O20: 40
C21: Insertion pub | G21: 135 | O21: 135
C22: URGENT : Visuel pour stand Fnac | H22: 40 | O22: 40
B23: Ivet Rico | C23: BRIEF CREA_Magnet ZV 1II | I23: 180 | O23: 180
C24: Comparaison Table Xperia 5 V | I24: 135 | O24: 135
B25: Kenza Touili | D25: 6515 | E25: 1530 | F25: 1720 | G25: 635 | H25: 465 | I25: 315 | N25: 915 | O25: 12095
B26: Léa Novio | J26: 465 | O26: 465
B27: Sébastien Minaux | E27: 180 | K27: 105 | O27: 285
B28: Kenza Touilli | C28: AN1000 Award | E28: 70 | O28: 70
C29: TV SONY format demi-page | N29: 135 | O29: 135
B30: Antoine Cuvillier | C30: Visuels page produits S40R | D30: 315 | O30: 315
B31: Valentin Gibaud | C31: BRAVIA 8 BVB screenfill | F31: 35 | O31: 35
C32: Adaptations Header web | F32: 105 | O32: 105
B33: Orianne Hochweiker | C33: Visuel 800 x 418 - Lancement ZVE10M2B | G33: 70 | O33: 70
B34: Lisa Peron | C34: Panneau - Visuel pour un événement interne Sony | H34: 180 | O34: 180
B35: Justine RODRIGUES | C35: OP IP&S AOUT_Focales Fixes et TRADE IN | I35: 720 | O35: 720
C36: OP LENSES BACK TO SCHOOL | I36: 120 | O36: 120
C37: SDLP - LEAFLET MICROS | I37: 250 | O37: 250
A38: Total | D38: 15090 | E38: 8315 | F38: 5340 | G38: 8380 | H38: 4570 | I38: 2710 | J38: 1780 | K38: 105 | L38: 600 | M38: 445 | N38: 4330 | O38: 51665

Sheet Summary - SFR - CM
A2: Sony France - CM
A3: FY | B3: FY24
A4: Team | B4: (Tous)
A5: PO Status | B5: (Plusieurs éléments)
A7: Category | B7: Quarter | C7: PO | D7: Project | E7: Total
A8: Cross | B8: Q2 | C8: 4200670036 | D8: Panneau - Visuel pour un événement interne Sony | E8: 180
A9: DI | B9: Q1 | C9: (vide) | E9: 0
C10: 4200663622 | D10: BOULANGER OP AVRIL | E10: 70
C11: 4200665908 | D11: Visuel ZV E10-format FNAC | E11: 40
D12: Affiche A9M_ Decli Vitrine IP CHOLET | E12: 40
D13: Lancement nouvel Objectif_BANNERS | E13: 435
D14: OP LANDSCAPE_banners | E14: 540
C15: 4200665859 | D15: OP 500€ de remise_ KIT A7M4 ou A7M3 | E15: 235
C16: 4200663622 | D16: FRENCH DAYS | Adaptation des créas | E16: 70
D17: Fnac Darty - Brief Habillage & Bannières OP Photo | E17: 500
C18: 4200667507 | D18: DI | Brief 21x21 OPENEYE | E18: 120
D19: Print always on DI - Juin | E19: 120
D20: DI | FY24 Always ON DI - Flight 1 | E20: 400
C21: 4200667761 | D21: STUDENT CASHBACK France | E21: 670
B22: Q2 | C22: (vide) | E22: 960
C23: 4200668080 | D23: BOULANGER | Offres braderie | E23: 535
D24: BOULANGER | Opération de reprise Gaming | E24: 195
B25: Q3 | C25: (vide) | E25: 1240
B26: Q4 | C26: (vide) | E26: 775
C27: 4200665906 | D27: Newsletter PRT - Janvier 2024 | E27: 600
C28: 4200665859 | D28: OP SUMMER FY24 | E28: 1960
C29: 4200664144 | D29: XV500 Subtitles | E29: 240
A30: HAV | B30: Q1 | C30: 4200663723 | D30: Visuels page produits S40R | E30: 315
C31: 4200667872 | D31: BOULANGER | Newsletter 65BRAVIA7 + QUAD | E31: 120
A32: MDR | B32: Q1 | C32: 4200663610 | D32: BOULANGER | Offre XM4 | E32: 155
D33: BOULANGER | Offres sur la 1000X Family | E33: 155
D34: Brief Créa ULT - Megastar/Impulse Fnac Darty | E34: 275
D35: ULT WEAR - AMS bannières statiques | E35: 400
D36: ULT WEAR - REC AMAZON | E36: 410
D37: Nouveau format Megastar ULT | E37: 35
C38: 4200665082 | D38: BRIEF INLAYS ULT | E38: 215
C39: 4200665083 | D39: FICHES PRODUITS ULT FAMILY | E39: 1000
C40: 4200665081 | D40: ULT | Bannières | E40: 510
C41: 4200665074 | D41: ULT - CHALLENGE POS | E41: 810
C42: 4200665900 | D42: Assets Vidéos - Campagne Social Ads Fnac Darty | E42: 1020
...

Sheet Sony France - CM
A1: Price File | Q1: Online | X1: Offline | AG1: Presentations | AH1: Web | AN1: Videos | AU1: Virtualization | AW1: Copy
A2: Project | E2: Details | Q2: Banner creation (static) | R2: Banner adaptation (static) | S2: Banner creation (animated) | T2: Banner adaptation (animated) | U2: Logo | V2: Lifestyle Picture | W2: Wallpapers | X2: Offline creation (standard) | Y2: Offline creation (adaptation) | Z2: Leaflet (1 page) | AA2: Leaflet (2 pages) | AB2: Packaging (box) | AC2: Merchandising Plan | AD2: Roll-up / Wall creation | AE2: Chart | AF2: Brochure (20 pages) | AG2: Slide | AH2: Newsletter (design only) | AI2: Newsletter (complete) | AJ2: Landing page (design only) | AK2: Landing page (complete) | AL2: Website (design only) | AM2: Website (complete) | AN2: Simple Edition | AO2: Longer Edition | AP2: Social Media Video (up to 30s) | AQ2: Social Media Video (up to 1 min) | AR2: Promotional | AS2: 2D Video (up to 3min) | AT2: 3D Video (up to 3min) | AU2: Virtual space | AV2: Virtual showroom | AW2: Translation (per word) | AX2: Copywrite (per word)
A3: Customer | B3: Division | C3: Date | D3: Project | E3: Contact | F3: Status | G3: Category | H3: Link | I3: Assets | J3: Total Value | K3: Quote | L3: PO | M3: Mois de paiement | N3: Invoice | O3: N° Invoice | P3: Status | Q3: 120 | R3: 35 | S3: 220 | T3: 60 | U3: 250 | V3: 500 | W3: 100 | X3: 135 | Y3: 40 | Z3: 180 | AA3: 250 | AB3: 200 | AC3: 250 | AD3: 180 | AE3: 400 | AF3: sa | AG3: 35 | AH3: 500 | AI3: 600 | AJ3: 500 | AK3: 1200 | AL3: 5000 | AM3: 7000 | AN3: 80 | AO3: 150 | AP3: 260 | AQ3: 360 | AR3: 5000 | AS3: 6500 | AT3: 10000 | AU3: 2500 | AV3: 10000 | AW3: 0.1 | AX3: 0.25
A4: Sony | B4: SFR | C4: 45013 | D4: Bannières de lancement A80L + ZV-E1 | E4: Alice Mucke | F4: Delivered | G4: TV | H4: https://saranistudio-my.sharepoint.com/:f:/g/personal/team_sarani_studio/EmtLIsoaTzxJnuMVqwFkEXEBRLxiJIn6Dx3sdurRJBv18Q?e=SUZpe2 | I4: =IF(SUM(Q4:AX4)=0,"-",SUM(Q4:AX4)) -> 6 | J4: =IF(SUMPRODUCT('Sony France - CM'!$Q$3:$AX$3,Q4:AX4)=0,"-",SUMPRODUCT('Sony France - CM'!$Q$3:$AX$3,Q4:AX4)) -> 210 | K4: 45023 | L4: 4200641929 | M4: Avril | R4: 6
A5: Sony | B5: SFR | C5: 45008 | D5: Adaptation Offres MEGASTAR | E5: Mylène Pellet | F5: Delivered | G5: TV | H5: https://saranistudio-my.sharepoint.com/:f:/g/personal/team_sarani_studio/Em9OAsLQ3rVAsCjuhjlyf9ABulvOo8C6xbY6ZkPMG8hkFQ?e=cTZegr | I5: =IF(SUM(Q5:AX5)=0,"-",SUM(Q5:AX5)) -> 3 | J5: =IF(SUMPRODUCT('Sony France - CM'!$Q$3:$AX$3,Q5:AX5)=0,"-",SUMPRODUCT('Sony France - CM'!$Q$3:$AX$3,Q5:AX5)) -> 105 | K5: 45071 | L5: 4200641929 | M5: Avril | N5: sent | R5: 3
A6: Sony | B6: SFR | C6: 45034 | D6: Habillages de site Lancement TV FY23 | E6: Maureen Masson | F6: Delivered | G6: TV | H6: https://saranistudio-my.sharepoint.com/:f:/g/personal/team_sarani_studio/ErYK9M-zOA5Hl_9y0WcmEwsBwd5R8qMMwATIAABc168MWQ?e=kSNAdo | I6: =IF(SUM(Q6:AX6)=0,"-",SUM(Q6:AX6)) -> 3 | J6: =IF(SUMPRODUCT('Sony France - CM'!$Q$3:$AX$3,Q6:AX6)=0,"-",SUMPRODUCT('Sony France - CM'!$Q$3:$AX$3,Q6:AX6)) -> 190 | K6: 45041 | L6: 4200641929 | M6: Mai | N6: sent | Q6: 1 | R6: 2
A7: Sony | B7: SFR | C7: 26/04/23 | D7: Adaptation Megastar Cashback TV HAV | E7: Mylène Pellet | F7: Delivered | G7: TV | H7: https://saranistudio-my.sharepoint.com/:f:/g/personal/team_sarani_studio/EryFOZSDujNAvnhAwzgHd6YBejy68T4VHXJZQ1QAcVGLmw?e=rKtkku | I7: =IF(SUM(Q7:AX7)=0,"-",SUM(Q7:AX7)) -> 1 | J7: =IF(SUMPRODUCT($Q$3:$AX$3,Q7:AX7)=0,"-",SUMPRODUCT($Q$3:$AX$3,Q7:AX7)) -> 35 | K7: 45047 | L7: 4200641929 | M7: Juin | N7: sent | R7: 1
A8: Sony | B8: SFR | C8: 26/04/23 | D8: Campagne TV launch FNAC DARTY | E8: Mylène Pellet | F8: Delivered | G8: TV | H8: https://saranistudio-my.sharepoint.com/:f:/g/personal/team_sarani_studio/Eq7SJAAGtLFPt3_OkqT-cAUBgqmFSKdaWA6Q3fjNYYyZLw?e=Kf8H76 | I8: =IF(SUM(Q8:AX8)=0,"-",SUM(Q8:AX8)) -> 7 | J8: =IF(SUMPRODUCT($Q$3:$AX$3,Q8:AX8)=0,"-",SUMPRODUCT($Q$3:$AX$3,Q8:AX8)) -> 245 | K8: 45047 | L8: 4200641929 | M8: Mai | N8: sent | R8: 7
A9: Sony | B9: SFR | C9: 28/04/23 | D9: Webpop TV FY23 | E9: Joelle Mechache | F9: Delivered | G9: TV | H9: https://saranistudio-my.sharepoint.com/:f:/g/personal/team_sarani_studio/EksaPdiWfxhMnbU7goZGW3wBNMdtyNVXPZFQGY1IHS_P8w?e=K0olFY | I9: =IF(SUM(Q9:AX9)=0,"-",SUM(Q9:AX9)) -> 1 | J9: =IF(SUMPRODUCT('Sony France - CM'!$Q$3:$AX$3,Q9:AX9)=0,"-",SUMPRODUCT('Sony France - CM'!$Q$3:$AX$3,Q9:AX9)) -> 120 | K9: 45061 | L9: 4200641929 | M9: Juin | N9: sent | Q9: 1
A10: Sony | B10: SFR | C10: 45054 | D10: Mockup Newsletter Micromania | E10: Alice Mucke | F10: Delivered | G10: TV | H10: https://saranistudio-my.sharepoint.com/:f:/g/personal/team_sarani_studio/EhXJcziQF1VOliqxaNrnlb0BfZuNE9G1FoVfA52_LbSH2A?e=KNakVW | I10: 0,5 | J10: 250 € | K10: 45064 | L10: 4200641929 | M10: Juin | N10: Sent | AH10: 0,5
A11: Sony | B11: SFR | C11: 45056 | D11: Cashback TV HAV - Adaptation Impulse | E11: Mylène Pellet | F11: Delivered | G11: TV | H11: https://saranistudio-my.sharepoint.com/:f:/g/personal/team_sarani_studio/Ekai1uZu5I1DjFQDqtNMglUB-a9khXEpgHVGO6Ehmq4loA?e=O64h2s | I11: =IF(SUM(Q11:AX11)=0,"-",SUM(Q11:AX11)) -> 4 | J11: =IF(SUMPRODUCT($Q$3:$AX$3,Q11:AX11)=0,"-",SUMPRODUCT($Q$3:$AX$3,Q11:AX11)) -> 140 | K11: 45082 | L11: 4200641929 | M11: Juin | N11: Sent | R11: 4
A12: Sony | B12: SFR | C12: 45057 | D12: Spiderman Micromania banners | E12: Alice Mucke | F12: Delivered | G12: TV | H12: https://saranistudio-my.sharepoint.com/:f:/g/personal/team_sarani_studio/Ej9SOLBtCcBHld_gbUxWxU4Bj5ZI1lZOhveurJhxJ-lshA?e=zgWyyk | I12: =IF(SUM(Q12:AX12)=0,"-",SUM(Q12:AX12)) -> 7 | J12: =IF(SUMPRODUCT($Q$3:$AX$3,Q12:AX12)=0,"-",SUMPRODUCT($Q$3:$AX$3,Q12:AX12)) -> 330 | K12: 45064 | L12: 4200641929 | M12: Juin | N12: Sent | Q12: 1 | R12: 6
A13: Sony | B13: SFR | C13: 17/05/23 | D13: HAV bundle - Réseaux sociaux | E13: Alice Mucke | F13: Delivered | G13: TV | H13: https://saranistudio-my.sharepoint.com/:f:/g/personal/team_sarani_studio/Eno1hTwc6CZOpOaDyfuFXzEBK3IEmmBUsIThhxjU7-HINg?e=eUPBG7 | I13: =IF(SUM(Q13:AX13)=0,"-",SUM(Q13:AX13)) -> 6 | J13: =IF(SUMPRODUCT($Q$3:$AX$3,Q13:AX13)=0,"-",SUMPRODUCT($Q$3:$AX$3,Q13:AX13)) -> 380 | K13: 45064 | L13: 4200641929 | M13: Juin | N13: Sent | Q13: 2 | R13: 4
A14: Sony | B14: SFR | C14: 30/05/23 | D14: Jeu Concours PS5 - Banners Boulanger | E14: Maureen Masson | F14: Delivered | G14: TV | H14: https://saranistudio-my.sharepoint.com/:f:/g/personal/team_sarani_studio/Et4JEQ0pJl5Kp_gFcv6IrzAB9iSZfuy0HfDvSRmUsm9szw?e=pEDdUu | I14: =IF(SUM(Q14:AX14)=0,"-",SUM(Q14:AX14)) -> 2 | J14: =IF(SUMPRODUCT($Q$3:$AX$3,Q14:AX14)=0,"-",SUMPRODUCT($Q$3:$AX$3,Q14:AX14)) -> 155 | K14: 45047 | L14: 4200641929 | M14: Juin | N14: Sent | Q14: 1 | R14: 1
A15: Sony | B15: SFR | C15: 30/05/23 | D15: Lancement TA-AN1000 - Banners Boulanger | E15: Maureen Masson | F15: Delivered | G15: HAV | H15: https://saranistudio-my.sharepoint.com/:f:/g/personal/team_sarani_studio/Ei_NmotrYflMp_lWmHZy990BpLoLZi4cDnXnEJa6yjOecw?e=dGyo9B | I15: =IF(SUM(Q15:AX15)=0,"-",SUM(Q15:AX15)) -> 2 | J15: =IF(SUMPRODUCT($Q$3:$AX$3,Q15:AX15)=0,"-",SUMPRODUCT($Q$3:$AX$3,Q15:AX15)) -> 155 | K15: 45047 | L15: 4200641929 | M15: Juin | N15: Sent | Q15: 1 | R15: 1
A16: Sony | B16: SFR | C16: 45019 | D16: New C700 Video - Short Video Editing | E16: Joelle Mechache | F16: Delivered | G16: MDR | H16: https://saranistudio-my.sharepoint.com/:f:/g/personal/team_sarani_studio/EkiROo65MdxOl4foCK_JnkMB7b1GqAM5JaGtE7NM2E563A?e=zgcdCi | I16: =IF(SUM(Q16:AX16)=0,"-",SUM(Q16:AX16)) -> 1 | J16: 260 | K16: 45023 | L16: 4200641950 | M16: Mai | N16: Sent | AQ16: 1
A17: Sony | B17: SFR | C17: 45089 | D17: Adaptations C700 / CH520 / XG300 | E17: Alice Mucke | F17: Delivered | G17: MDR | H17: https://saranistudio-my.sharepoint.com/:f:/g/personal/team_sarani_studio/EnY_cb3_b3FBkuyHMMgrIqABI3LhFTYtdKHZJVa7a7n45w?e=c3qr6G | I17: =IF(SUM(Q17:AX17)=0,"-",SUM(Q17:AX17)) -> 6 | J17: =IF(SUMPRODUCT($Q$3:$AX$3,Q17:AX17)=0,"-",SUMPRODUCT($Q$3:$AX$3,Q17:AX17)) -> 210 | L17: 4200647984 | M17: Juillet | N17: Sent | R17: 6
A18: Sony | B18: SFR | C18: 45103 | D18: Patacos nouveautés MDR | E18: Alice Mucke | F18: Delivered | G18: MDR | H18: https://saranistudio-my.sharepoint.com/:f:/g/personal/team_sarani_studio/EhWQhvikpjJAs9fRKuPWGgEBkfzxAmfMaaWw3wA91WzwdQ?e=0urtbw | I18: =IF(SUM(Q18:AX18)=0,"-",SUM(Q18:AX18)) -> 3 | J18: =IF(SUMPRODUCT($Q$3:$AX$3,Q18:AX18)=0,"-",SUMPRODUCT($Q$3:$AX$3,Q18:AX18)) -> 120 | L18: 4200641950 | M18: Aout | N18: Sent | Y18: 3
A19: Sony | B19: SFR | C19: 45012 | D19: Déclinaisons TV / DI | E19: Alice Mucke | F19: Delivered | G19: DI | H19: https://saranistudio-my.sharepoint.com/:f:/g/personal/team_sarani_studio/EmtLIsoaTzxJnuMVqwFkEXEBRLxiJIn6Dx3sdurRJBv18Q?e=g8c6h9 | I19: =IF(SUM(Q19:AX19)=0,"-",SUM(Q19:AX19)) -> 6 | J19: =IF(SUMPRODUCT('Sony France - CM'!$Q$3:$AX$3,Q19:AX19)=0,"-",SUMPRODUCT('Sony France - CM'!$Q$3:$AX$3,Q19:AX19)) -> 210 | K19: 45041 | L19: 4200641951 | M19: Avril | R19: 6
A20: Sony | B20: SFR | C20: 26/04/23 | D20: OP summer - Déclinaisons Photo Univers | E20: Alice Mucke | F20: Delivered | G20: DI | H20: https://saranistudio-my.sharepoint.com/:f:/g/personal/team_sarani_studio/ElqnG-FXH_tIjM-5CjehobkBI3iwiykX2wZsbbcXjP2u5Q?e=cTcTX3 | I20: =IF(SUM(Q20:AX20)=0,"-",SUM(Q20:AX20)) -> 3 | J20: =IF(SUMPRODUCT('Sony France - CM'!$Q$3:$AX$3,Q20:AX20)=0,"-",SUMPRODUCT('Sony France - CM'!$Q$3:$AX$3,Q20:AX20)) -> 105 | K20: 45043 | L20: 4200641951 | M20: Mai | N20: sent | R20: 3
A21: Sony | B21: SFR | C21: 45048 | D21: OP FX30 - Photo Univers | E21: Alice Mucke | F21: Delivered | G21: DI | H21: https://saranistudio-my.sharepoint.com/:f:/g/personal/team_sarani_studio/EmGsdIsbJgRJsHn18mqoDSQB5FuBnBna9S_58xG7MtztpQ?e=qp39eM | I21: =IF(SUM(Q21:AX21)=0,"-",SUM(Q21:AX21)) -> 4 | J21: =IF(SUMPRODUCT($Q$3:$AX$3,Q21:AX21)=0,"-",SUMPRODUCT($Q$3:$AX$3,Q21:AX21)) -> 140 | K21: 45047 | L21: 4200641951 | M21: Juin | N21: sent | R21: 4
A22: Sony | B22: SFR | C22: 23/05/23 | D22: CX64800 - Photo Univers | E22: Alice Mucke | F22: Delivered | G22: DI | H22: https://saranistudio-my.sharepoint.com/:f:/g/personal/team_sarani_studio/En4adQAwLLdMpS_-kswH4HYBlTRV8MD-w8jBUwACO_7rVA?e=59Phkd | I22: =IF(SUM(Q22:AX22)=0,"-",SUM(Q22:AX22)) -> 4 | J22: =IF(SUMPRODUCT($Q$3:$AX$3,Q22:AX22)=0,"-",SUMPRODUCT($Q$3:$AX$3,Q22:AX22)) -> 140 | K22: 45082 | L22: 4200641951 | M22: Juin | N22: sent | R22: 4
A23: Sony | B23: SFR | C23: 45033 | D23: Bannières Boulanger promo barres de son | E23: Maureen Masson | F23: Delivered | G23: HAV | H23: https://saranistudio-my.sharepoint.com/:f:/g/personal/team_sarani_studio/EkZE4Y3oDmxOgPwByulkRGQBO22GCn4XXiv8vxBWXU3BOQ?e=QYcm2Z | I23: =IF(SUM(Q23:AX23)=0,"-",SUM(Q23:AX23)) -> 2 | J23: =IF(SUMPRODUCT('Sony France - CM'!$Q$3:$AX$3,Q23:AX23)=0,"-",SUMPRODUCT('Sony France - CM'!$Q$3:$AX$3,Q23:AX23)) -> 155 | K23: 45036 | L23: 4200641959 | M23: Mai | N23: sent | Q23: 1 | R23: 1
A24: Sony | B24: SFR | C24: 45078 | D24: Adaptation Bannières XG300 | E24: Alice Mucke | F24: Delivered | G24: MDR | H24: https://saranistudio-my.sharepoint.com/:f:/g/personal/team_sarani_studio/Ev6IqmHMJZBCphm3dxGsXhYBeFhBvti6G9s1vJiBrYBRdA?e=gI4oeQ | I24: =IF(SUM(Q24:AX24)=0,"-",SUM(Q24:AX24)) -> 4 | J24: =IF(SUMPRODUCT($Q$3:$AX$3,Q24:AX24)=0,"-",SUMPRODUCT($Q$3:$AX$3,Q24:AX24)) -> 140 | K24: 45082 | L24: 4200647984 | M24: Juillet | N24: Sent | R24: 4
A25: Sony | B25: SFR | C25: 45084 | D25: Cross Visuel - Document de formation | E25: Alice Mucke | F25: Delivered | G25: MDR | H25: https://saranistudio-my.sharepoint.com/:f:/g/personal/team_sarani_studio/EmZPb6upSoFLpsVrD7mVPrQBWIvIxUkXO5KuEznQtZpHRA?e=gonNYb | I25: =IF(SUM(Q25:AX25)=0,"-",SUM(Q25:AX25)) -> 1 | J25: =IF(SUMPRODUCT($Q$3:$AX$3,Q25:AX25)=0,"-",SUMPRODUCT($Q$3:$AX$3,Q25:AX25)) -> 120 | L25: 4200647984 | M25: Juillet | N25: Sent | Q25: 1
A26: Sony | B26: SFR | C26: 45091 | D26: Affichages dynamiques - BOULANGER | E26: Alice Mucke | F26: Delivered | G26: MDR | H26: https://saranistudio-my.sharepoint.com/:f:/g/personal/team_sarani_studio/Enx5U2mYTNFMnJc-xIoaRV0B1eOVGObhT3Vm8PYvRQBmQQ?e=buAC3K | I26: =IF(SUM(Q26:AX26)=0,"-",SUM(Q26:AX26)) -> 1 | J26: =IF(SUMPRODUCT($Q$3:$AX$3,Q26:AX26)=0,"-",SUMPRODUCT($Q$3:$AX$3,Q26:AX26)) -> 360 | L26: 4200647984 | M26: Juillet | N26: Sent | AQ26: 1
A27: Sony | B27: SFR | C27: 45104 | D27: Soldes d'été - adaptation | E27: Alice Mucke | F27: Delivered | G27: MDR | H27: https://saranistudio-my.sharepoint.com/:f:/g/personal/team_sarani_studio/EshfpkcRdslJlWo_wRSFdokBKfbGaymAkkISj5Hs0t-4Gg?e=rxI0Dg | I27: =IF(SUM(Q27:AX27)=0,"-",SUM(Q27:AX27)) -> 1 | J27: =IF(SUMPRODUCT($Q$3:$AX$3,Q27:AX27)=0,"-",SUMPRODUCT($Q$3:$AX$3,Q27:AX27)) -> 35 | L27: 4200647984 | M27: Aout | N27: Sent | O27: F2023-0422 | P27: Paid 19/01/2024 | R27: 1
A28: Sony | B28: SFR | C28: 45127 | D28: Bannières de lancement - HT-A7X | E28: Alice Mucke | F28: Delivered | G28: HAV | H28: https://saranistudio.sharepoint.com/:f:/s/SaraniAssets/Eo4fs8B0yVxOnYJDdESxq3IBMQTRyrJaLmIY-WuqR8BCHw?e=CXm0xp | I28: =IF(SUM(Q28:AX28)=0,"-",SUM(Q28:AX28)) -> 6 | J28: =IF(SUMPRODUCT($Q$3:$AX$3,Q28:AX28)=0,"-",SUMPRODUCT($Q$3:$AX$3,Q28:AX28)) -> 295 | L28: 4200647984 | M28: Aout | N28: Sent | O28: F2023-0422 | P28: Paid 19/01/2024 | Q28: 1 | R28: 5
A29: Sony | B29: SFR | C29: 45127 | D29: Bannières teasing E5 Boulanger | E29: Maureen Masson | F29: Delivered | G29: MDR | H29: https://saranistudio.sharepoint.com/:f:/s/SaraniAssets/Et5dFqZmczRMgczFiFOa0GsBBMgBPGHSfouO-Ayz_KXs-g?e=etIRaC | I29: =IF(SUM(Q29:AX29)=0,"-",SUM(Q29:AX29)) -> 2 | J29: =IF(SUMPRODUCT($Q$3:$AX$3,Q29:AX29)=0,"-",SUMPRODUCT($Q$3:$AX$3,Q29:AX29)) -> 70 | L29: 4200647984 | M29: Aout | N29: Sent | O29: F2023-0422 | P29: Paid 19/01/2024 | R29: 2
A30: Sony | B30: SFR | C30: 24/07/2023 | D30: Adaptation bannières Boulanger | E30: Maureen Masson | F30: Delivered | G30: MDR | H30: https://saranistudio.sharepoint.com/:f:/s/SaraniAssets/Ep_e6bGp1cJGnZiPUIoGnmMBOeKbF9oZdsw2Vnw67-ugPA?e=9SpT7N | I30: =IF(SUM(Q30:AX30)=0,"-",SUM(Q30:AX30)) -> 4 | J30: =IF(SUMPRODUCT($Q$3:$AX$3,Q30:AX30)=0,"-",SUMPRODUCT($Q$3:$AX$3,Q30:AX30)) -> 140 | L30: 4200647984 | M30: Aout | N30: Sent | O30: F2023-0422 | P30: Paid 19/01/2024 | R30: 4
A31: Sony | B31: SFR | C31: 27/07/2023 | D31: FNAC DARTY WF1000XM5 | E31: Mylène Pellet | F31: Delivered | G31: MDR | H31: https://saranistudio.sharepoint.com/:f:/s/SaraniAssets/EiknNepsLsBCrpdYsClDYf4BJ3FbQd_CWM1gJFTvYGUW-Q?e=Rq1u9R | I31: =IF(SUM(Q31:AX31)=0,"-",SUM(Q31:AX31)) -> 4 | J31: =IF(SUMPRODUCT($Q$3:$AX$3,Q31:AX31)=0,"-",SUMPRODUCT($Q$3:$AX$3,Q31:AX31)) -> 225 | L31: 4200647984 | M31: Aout | N31: Sent | O31: F2023-0422 | P31: Paid 19/01/2024 | Q31: 1 | R31: 3
A32: Sony | B32: SFR | C32: 27/07/2023 | D32: Bannières Boulanger Try&Buy WF-1000XM5 | E32: Maureen Masson | F32: Delivered | G32: MDR | H32: https://saranistudio.sharepoint.com/:f:/s/SaraniAssets/EooaxtefwdJHkHIXb1uHNp0Bo4oLLxMQXbDoZSqdCMOmdA?e=0dKqff | I32: =IF(SUM(Q32:AX32)=0,"-",SUM(Q32:AX32)) -> 2 | J32: =IF(SUMPRODUCT($Q$3:$AX$3,Q32:AX32)=0,"-",SUMPRODUCT($Q$3:$AX$3,Q32:AX32)) -> 155 | L32: 4200647984 | M32: Aout | N32: Sent | O32: F2023-0422 | P32: Paid 19/01/2024 | Q32: 1 | R32: 1
A33: Sony | B33: SFR | C33: 45159 | D33: Boulanger | Social Ads - WF1000XM5 | E33: Alice Mucke | F33: Delivered | G33: MDR | H33: https://saranistudio.sharepoint.com/:f:/s/SaraniAssets/EtFcNiBU0NdFlh47hWv2DIcB350g2zzLb2TcsdaZ7gu2IA?e=VVwlcH | I33: =IF(SUM(Q33:AX33)=0,"-",SUM(Q33:AX33)) -> 2 | J33: =IF(SUMPRODUCT($Q$3:$AX$3,Q33:AX33)=0,"-",SUMPRODUCT($Q$3:$AX$3,Q33:AX33)) -> 440 | L33: 4200647984 | M33: Septembre | N33: Sent | O33: F2023-0422 | P33: Paid 19/01/2024 | AN33: 1 | AQ33: 1
A34: Sony | B34: SFR | C34: 31/10/2023 | D34: Création Assets - Régie Mégastar | E34: Lucia Alvaro | F34: Delivered | G34: MDR | H34: https://saranistudio.sharepoint.com/:f:/s/SaraniAssets/Eh6KVl3bFE5LhnPwJatp_ZAB-BRSqFvxMpNBm7iwT-IQ2Q?e=HY0ocq | I34: =IF(SUM(Q34:AX34)=0,"-",SUM(Q34:AX34)) -> 2 | J34: =IF(SUMPRODUCT('Sony France - CM'!$Q$3:$AX$3,Q34:AX34)=0,"-",SUMPRODUCT('Sony France - CM'!$Q$3:$AX$3,Q34:AX34)) -> 155 | L34: 4200647984 | M34: Janvier | N34: Sent | O34: F2023-0439 | P34: Paid 23/01/2024 | Q34: 1 | R34: 1
A35: Sony | B35: SFR | C35: 45078 | D35: OP Photo Fnac | E35: Mylène Pellet | F35: Delivered | G35: DI | H35: https://saranistudio-my.sharepoint.com/:f:/g/personal/team_sarani_studio/EmcPifH5zRNCuYQ6gTYnx6sBDvIuTZFuDZPI2FJvUxiAxw?e=XWt4Db | I35: =IF(SUM(Q35:AX35)=0,"-",SUM(Q35:AX35)) -> 6 | J35: =IF(SUMPRODUCT($Q$3:$AX$3,Q35:AX35)=0,"-",SUMPRODUCT($Q$3:$AX$3,Q35:AX35)) -> 465 | K35: 45082 | L35: 4200647987 | M35: Juillet | N35: Sent | Q35: 3 | R35: 3
A36: Sony | B36: SFR | C36: 45083 | D36: OP Photo Fnac adaptations | E36: Mylène Pellet | F36: Delivered | G36: DI | H36: https://saranistudio-my.sharepoint.com/:f:/g/personal/team_sarani_studio/EtIVwt5h1mBGvOR3ExJTZ1gBzwxRkAB45F-wXqyU66HBZg?e=Ck53W4 | I36: =IF(SUM(Q36:AX36)=0,"-",SUM(Q36:AX36)) -> 2 | J36: =IF(SUMPRODUCT($Q$3:$AX$3,Q36:AX36)=0,"-",SUMPRODUCT($Q$3:$AX$3,Q36:AX36)) -> 70 | L36: 4200647987 | M36: Juillet | N36: Sent | R36: 2
A37: Sony | B37: SFR | C37: 45089 | D37: Déclinaisons Packs VLOG / FF | E37: Alice Mucke | F37: Delivered | G37: DI | H37: https://saranistudio-my.sharepoint.com/:f:/g/personal/team_sarani_studio/EnsODutXGZlJka_h6isAGR0BOCwDvdDheBpIbUVmfdjGWQ?e=loMFxG | I37: =IF(SUM(Q37:AX37)=0,"-",SUM(Q37:AX37)) -> 21 | J37: =IF(SUMPRODUCT($Q$3:$AX$3,Q37:AX37)=0,"-",SUMPRODUCT($Q$3:$AX$3,Q37:AX37)) -> 820 | L37: 4200647987 | M37: Juillet | N37: Sent | Q37: 1 | R37: 20
A38: Sony | B38: SFR | C38: 45099 | D38: ZV-E1 - vidéo format court | E38: Mylène Pellet | F38: Delivered | G38: DI | H38: https://saranistudio-my.sharepoint.com/:f:/g/personal/team_sarani_studio/Eq9dY38BCXlJpcBriotIXLwBSlmTZTPUeCHR-CXQ-1YX2g?e=07oE5T | I38: =IF(SUM(Q38:AX38)=0,"-",SUM(Q38:AX38)) -> 1 | J38: =IF(SUMPRODUCT($Q$3:$AX$3,Q38:AX38)=0,"-",SUMPRODUCT($Q$3:$AX$3,Q38:AX38)) -> 150 | L38: 4200647987 | M38: Juillet | N38: Sent | AO38: 1
A39: Sony | B39: SFR | C39: 45103 | D39: Opération Optiques GM garantie | E39: Alice Mucke | F39: Delivered | G39: DI | H39: https://saranistudio-my.sharepoint.com/:f:/g/personal/team_sarani_studio/EjjU1nsll0ZLpfwcqkqDz1ABqwYNoyuQuP2Jpd3qOaYqaw?e=tAAr5m | I39: =IF(SUM(Q39:AX39)=0,"-",SUM(Q39:AX39)) -> 2 | J39: =IF(SUMPRODUCT($Q$3:$AX$3,Q39:AX39)=0,"-",SUMPRODUCT($Q$3:$AX$3,Q39:AX39)) -> 155 | L39: 4200647987 | M39: Aout | N39: Sent | O39: F2023-0423 | P39: Paid 19/01/2024 | Q39: 1 | R39: 1
A40: Sony | B40: SFR | C40: 45110 | D40: Op Optiques | E40: Alice Mucke | F40: Delivered | G40: DI | H40: https://saranistudio.sharepoint.com/:f:/s/SaraniAssets/EsYuFhHQcFRDtLfSjO_6uGMB0GNO5CLhpB3N6Q9GmyqNJQ?e=Y20eDi | I40: =IF(SUM(Q40:AX40)=0,"-",SUM(Q40:AX40)) -> 2 | J40: =IF(SUMPRODUCT($Q$3:$AX$3,Q40:AX40)=0,"-",SUMPRODUCT($Q$3:$AX$3,Q40:AX40)) -> 155 | L40: 4200647987 | M40: Aout | N40: Sent | O40: F2023-0423 | P40: Paid 19/01/2024 | Q40: 1 | R40: 1
...

Sheet Sony France - Hors CM
A1: Price File | P1: Online | W1: Offline | AF1: Presentations | AG1: Web | AM1: Videos | AS1: Virtualization | AU1: Copy
A2: Project | E2: Details | L2: Sony | M2: Sarani Ne pas toucher, svp | P2: Banner creation (static) | Q2: Banner adaptation (static) | R2: Banner creation (animated) | S2: Banner adaptation (animated) | T2: Logo | U2: Lifestyle Picture | V2: Wallpapers | W2: Offline creation (standard) | X2: Offline creation (adaptation) | Y2: Leaflet (1 page) | Z2: Leaflet (2 pages) | AA2: Packaging (box) | AB2: Merchandising Plan | AC2: Roll-up / Wall creation | AD2: Chart | AE2: Brochure (20 pages) | AF2: Slide | AG2: Newsletter (design only) | AH2: Newsletter (complete) | AI2: Landing page (design only) | AJ2: Landing page (complete) | AK2: Website (design only) | AL2: Website (complete) | AM2: Simple Edition | AN2: Social Media Video (up to 30s) | AO2: Social Media Video (up to 1 min) | AP2: Promotional | AQ2: 2D Video (up to 3min) | AR2: 3D Video (up to 3min) | AS2: Virtual space | AT2: Virtual showroom | AU2: Translation (per word) | AV2: Copywrite (per word)
A3: Customer | B3: Division | C3: Date | D3: Project | E3: Contact | F3: Status | G3: Category | H3: Link | I3: Assets | J3: Total Value | K3: Quote | L3: PO | M3: Invoice | N3: N° Invoice | O3: Status | P3: 120 | Q3: 35 | R3: 220 | S3: 60 | T3: 250 | U3: 500 | V3: 100 | W3: 135 | X3: 40 | Y3: 180 | Z3: 250 | AA3: 200 | AB3: 250 | AC3: 180 | AD3: 400 | AE3: 2200 | AF3: 35 | AG3: 500 | AH3: 600 | AI3: 500 | AJ3: 1200 | AK3: 5000 | AL3: 7000 | AM3: 80 | AN3: 260 | AO3: 360 | AP3: 5000 | AQ3: 6500 | AR3: 10000 | AS3: 2500 | AT3: 10000 | AU3: 0.1 | AV3: 0.25
A4: Sony | B4: SFR | C4: 44880 | D4: MDR MEG TW FNAC | E4: Laura Vivient | F4: Delivered | G4: V&S | H4: https://saranistudio-my.sharepoint.com/:f:/g/personal/team_sarani_studio/Etevju8IZKpEjFi3N14QmoUBp7wUTsms6pxhOWBv6e2jlQ?e=poko2y | I4: =IF(SUM(P4:AV4)=0,"-",SUM(P4:AV4)) -> 3 | J4: =IF(SUMPRODUCT($P$3:$AV$3,P4:AV4)=0,"-",SUMPRODUCT($P$3:$AV$3,P4:AV4)) -> 405 | K4: 29/11/2022 | L4: 4200630823 | M4: Sent | W4: 3
A5: Sony | B5: SFR | C5: 44880 | D5: MDR TW Stop Rayon Bluetooth Multipoint | E5: Laura Vivient | F5: Delivered | G5: V&S | H5: https://saranistudio-my.sharepoint.com/:f:/g/personal/team_sarani_studio/EiWYden95S1PhgR70pI8qxEBwY-0nfvYhECdhw2ZQdFqdw?e=oKMO8n | I5: =IF(SUM(P5:AV5)=0,"-",SUM(P5:AV5)) -> 1 | J5: =IF(SUMPRODUCT($P$3:$AV$3,P5:AV5)=0,"-",SUMPRODUCT($P$3:$AV$3,P5:AV5)) -> 135 | K5: 29/11/2022 | L5: 4200630799 | M5: Sent | W5: 1
A6: Sony | B6: SFR | C6: 44882 | D6: Xmas - Creative Assets | E6: Maxime Fenech | F6: Delivered | G6: Cross | H6: https://saranistudio-my.sharepoint.com/:f:/g/personal/team_sarani_studio/EiXLGF1XZ1VNkmFgudaLWcQB0AP6n1T0jNDvvhweNqqJwg?e=vKq0Pw | I6: =IF(SUM(P6:AV6)=0,"-",SUM(P6:AV6)) -> 19 | J6: 590 | K6: 22/11/2022 | L6: 4200632493 | M6: Sent | Q6: 19
A7: Sony | B7: SFR | C7: 44883 | D7: Bulles Boulanger 2 | E7: Laura Vivient | F7: Delivered | G7: V&S | H7: https://saranistudio-my.sharepoint.com/:f:/g/personal/team_sarani_studio/EvZFoSgMoTlGiWeuK20ZrcwBr1BCtYNuR2DptwGgJMpg-A?e=ucRI2s | I7: =IF(SUM(P7:AV7)=0,"-",SUM(P7:AV7)) -> 1 | J7: =IF(SUMPRODUCT($P$3:$AV$3,P7:AV7)=0,"-",SUMPRODUCT($P$3:$AV$3,P7:AV7)) -> 120 | K7: 29/11/2022 | L7: 4200630798 | M7: Sent | P7: 1
A8: Sony | B8: SFR | C8: 44883 | D8: Infographies PSK FR | E8: Laura Vivient | F8: Delivered | G8: V&S | H8: https://saranistudio-my.sharepoint.com/:f:/g/personal/team_sarani_studio/Evtfs8z--DpCs3Qy9Cvq1Y4BMFsqWlLop36Ti2xykheKBA?e=DSnQzV | I8: =IF(SUM(P8:AV8)=0,"-",SUM(P8:AV8)) -> 16 | J8: =IF(SUMPRODUCT($P$3:$AV$3,P8:AV8)=0,"-",SUMPRODUCT($P$3:$AV$3,P8:AV8)) -> 560 | K8: 29/11/2022 | L8: 4200630825 | M8: Sent | Q8: 16
A9: Sony | B9: SFR | C9: 44883 | D9: 1000XM5 Award | E9: Laura Vivient | F9: Delivered | G9: V&S | H9: https://saranistudio-my.sharepoint.com/:f:/g/personal/team_sarani_studio/Eiu73Y88xwJPqQdXyeju6gcBPx5Nk46QboMvzke5SksCEw?e=lK8Qjn | I9: =IF(SUM(P9:AV9)=0,"-",SUM(P9:AV9)) -> 2 | J9: =IF(SUMPRODUCT($P$3:$AV$3,P9:AV9)=0,"-",SUMPRODUCT($P$3:$AV$3,P9:AV9)) -> 70 | K9: 29/11/2022 | L9: 4270024443 | M9: Sent | Q9: 2
A10: Sony | B10: SFR | C10: 44888 | D10: A95K-A83K Topper | E10: Léa Novio | F10: Delivered | G10: TV | H10: https://saranistudio-my.sharepoint.com/:f:/g/personal/team_sarani_studio/Enb5T0uGjd5It7r-yOl8Hw4BRcePMvNEVtlCj65ShnZ1eA?e=oRN2hs | I10: =IF(SUM(P10:AV10)=0,"-",SUM(P10:AV10)) -> 2 | J10: =IF(SUMPRODUCT($P$3:$AV$3,P10:AV10)=0,"-",SUMPRODUCT($P$3:$AV$3,P10:AV10)) -> 175 | K10: 44785 | L10: 4200631414 | M10: Sent | W10: 1 | X10: 1
A11: Sony | B11: SFR | C11: 44888 | D11: Labo Fnac | E11: Léa Novio | F11: Delivered | G11: TV | H11: https://saranistudio-my.sharepoint.com/:f:/g/personal/team_sarani_studio/EmBOVYV-QulImoZen16_XSMBt4gcYjkuDidXF__Uf1-VHw?e=ibhnwE | I11: =IF(SUM(P11:AV11)=0,"-",SUM(P11:AV11)) -> 5 | J11: =IF(SUMPRODUCT($P$3:$AV$3,P11:AV11)=0,"-",SUMPRODUCT($P$3:$AV$3,P11:AV11)) -> 175 | K11: 29/11/2022 | L11: 4200631417 | M11: Sent | Q11: 5
A12: Sony | B12: SFR | C12: 44888 | D12: HAV PLV MEG BDS LEAFLET TV | E12: Laura Vivient | F12: Delivered | G12: HAV | H12: https://saranistudio-my.sharepoint.com/:f:/g/personal/team_sarani_studio/EsKN0KK2wo5EuWcP_12lMhIBc3AUZVWjUaf03MKgHmGTeQ?e=4x7Av8 | I12: =IF(SUM(P12:AV12)=0,"-",SUM(P12:AV12)) -> 2 | J12: =IF(SUMPRODUCT($P$3:$AV$3,P12:AV12)=0,"-",SUMPRODUCT($P$3:$AV$3,P12:AV12)) -> 175 | K12: 30/11/2022 | L12: 4200630829 | M12: Sent | W12: 1 | X12: 1
A13: Sony | B13: SFR | C13: 44896 | D13: LinkBuds S avec SZA | E13: Laura Vivient | F13: Delivered | G13: V&S | H13: https://saranistudio-my.sharepoint.com/:f:/g/personal/team_sarani_studio/Ev2DdJ24TI9DnMYkKwzIkq0BHlTI4PJMje_IlrhSeabtxw?e=g9BnfI | I13: =IF(SUM(P13:AV13)=0,"-",SUM(P13:AV13)) -> 5 | J13: =IF(SUMPRODUCT($P$3:$AV$3,P13:AV13)=0,"-",SUMPRODUCT($P$3:$AV$3,P13:AV13)) -> 175 | K13: 44785 | L13: 4200630821 | M13: Sent | Q13: 5
A14: Sony | B14: SFR | C14: 44896 | D14: Sony Values Poster (5 A4 assets) | E14: Françoise Burgarella | F14: Delivered | G14: Cross | H14: https://saranistudio-my.sharepoint.com/:f:/g/personal/team_sarani_studio/Em0VBaXS7r5GiCtkcsyiCosBToqjoeJ6S1SQLfPqkfkGsQ?e=fEshRi | I14: =IF(SUM(P14:AV14)=0,"-",SUM(P14:AV14)) -> 4 | J14: =IF(SUMPRODUCT($P$3:$AV$3,P14:AV14)=0,"-",SUMPRODUCT($P$3:$AV$3,P14:AV14)) -> 350 | K14: 14/12/2022 | L14: 4200631419 | M14: Sent | W14: 2 | X14: 2
A15: Sony | B15: SFR | C15: 44897 | D15: Infographies Xperia 5M4 | E15: Astrid Jean-Baptiste | F15: Delivered | G15: Xperia | H15: https://saranistudio-my.sharepoint.com/:f:/g/personal/team_sarani_studio/Eu6UoQJssNdAvleXAzibZ1MBJ1RpI-TWGcduRRM37c84hw?e=4VncEj | I15: =IF(SUM(P15:AV15)=0,"-",SUM(P15:AV15)) -> 8 | J15: =IF(SUMPRODUCT($P$3:$AV$3,P15:AV15)=0,"-",SUMPRODUCT($P$3:$AV$3,P15:AV15)) -> 280 | K15: 14/12/2022 | L15: 4200631343 | M15: Sent | O15: ok | Q15: 8
A16: Sony | B16: SFR | C16: 44909 | D16: Newsletter PRT Décembre | E16: Alice Mucke | F16: Delivered | G16: DI | H16: - | I16: =IF(SUM(P16:AV16)=0,"-",SUM(P16:AV16)) -> 1 | J16: =IF(SUMPRODUCT($P$3:$AV$3,P16:AV16)=0,"-",SUMPRODUCT($P$3:$AV$3,P16:AV16)) -> 600 | K16: 15/12/2022 | L16: 4200639267 | M16: Sent | AH16: 1
A17: Sony | B17: SFR | C17: 44914 | D17: OP FAITES VOTRE CINEMA | E17: Astrid Jean-Baptiste | F17: Delivered | G17: DI | H17: https://saranistudio-my.sharepoint.com/:f:/g/personal/team_sarani_studio/EuGwoElxdVxAqUlHd5jwPl0Bd9dIrtw0j4nHaTHU_C0F4Q?e=k1zDEI | I17: =IF(SUM(P17:AV17)=0,"-",SUM(P17:AV17)) -> 7 | J17: =IF(SUMPRODUCT($P$3:$AV$3,P17:AV17)=0,"-",SUMPRODUCT($P$3:$AV$3,P17:AV17)) -> 330 | K17: 44931 | L17: 4200633114 | M17: Sent | O17: ok | P17: 1 | Q17: 6
A18: Sony | B18: SFR | C18: 44914 | D18: VITRO A7RV | E18: Astrid Jean-Baptiste | F18: Delivered | G18: DI | H18: https://saranistudio-my.sharepoint.com/:f:/g/personal/team_sarani_studio/El0REgOxzW1Eiu8AI5a8WPQBuRgA-xuGK77IgcuOUuwGhw?e=jWWT4e | I18: =IF(SUM(P18:AV18)=0,"-",SUM(P18:AV18)) -> 20 | J18: =IF(SUMPRODUCT($P$3:$AV$3,P18:AV18)=0,"-",SUMPRODUCT($P$3:$AV$3,P18:AV18)) -> 895 | K18: 44943 | L18: 4200633341 | M18: Sent | O18: ok | W18: 1 | X18: 19
A19: Sony | B19: SFR | C19: 44914 | D19: PANNEAU PHOTO HAUT VITRINE | E19: Astrid Jean-Baptiste | F19: Delivered | G19: DI | H19: https://saranistudio-my.sharepoint.com/:f:/g/personal/team_sarani_studio/En0xaWGTYWZOtWFNrWlERJYBEkKsluD4U7oLp_2fMTfyPA?e=3dNfLG | I19: =IF(SUM(P19:AV19)=0,"-",SUM(P19:AV19)) -> 11 | J19: =IF(SUMPRODUCT($P$3:$AV$3,P19:AV19)=0,"-",SUMPRODUCT($P$3:$AV$3,P19:AV19)) -> 535 | K19: 44931 | L19: 4200633116 | M19: Sent | O19: ok | W19: 1 | X19: 10
A20: Sony | B20: SFR | C20: 44914 | D20: Winter Sales Banners adaptations | E20: Françoise Burgarella | F20: Delivered | G20: Cross | H20: https://saranistudio-my.sharepoint.com/:f:/g/personal/team_sarani_studio/EitZRBZy2n1Kkw5kaWztE5sBgYKU_BFeDcX25iDrx1Ct5w?e=j19Nkg | I20: =IF(SUM(P20:AV20)=0,"-",SUM(P20:AV20)) -> 18 | J20: 590 | K20: 22/12/2022 | L20: 4200641797 | M20: Sent | P20: 1 | Q20: 17
A21: Sony | B21: SFR | C21: 44916 | D21: Winter Sales Banners adaptations DI | E21: Astrid Jean-Baptiste | F21: Delivered | G21: DI | H21: https://saranistudio-my.sharepoint.com/:f:/g/personal/team_sarani_studio/EitZRBZy2n1Kkw5kaWztE5sBgYKU_BFeDcX25iDrx1Ct5w?e=j19Nkg | I21: =IF(SUM(P21:AV21)=0,"-",SUM(P21:AV21)) -> 9 | J21: =190+4*35 -> 330 | K21: 44931 | L21: 4200632799 | M21: Sent | O21: ok | Q21: 9
A22: Sony | B22: SFR | C22: 44917 | D22: Micromania Boites Factices Update | E22: Alice Mucke | F22: Delivered | G22: Other | H22: https://saranistudio-my.sharepoint.com/:f:/g/personal/team_sarani_studio/Ehi8kv4332BOmhmF0GTdxqcBXMS0bXPqJJq-QzgW5N5jlg?e=BJOqXJ | I22: =IF(SUM(P22:AV22)=0,"-",SUM(P22:AV22)) -> 5 | J22: =IF(SUMPRODUCT($P$3:$AV$3,P22:AV22)=0,"-",SUMPRODUCT($P$3:$AV$3,P22:AV22)) -> 360 | K22: 44931 | L22: 4200635815 | M22: Sent | X22: 4 | AA22: 1
A23: Sony | B23: SFR | C23: 44923 | D23: Invitation Dealers Days | E23: Héloïse Leroy | F23: Delivered | G23: Cross | H23: https://saranistudio-my.sharepoint.com/:f:/g/personal/team_sarani_studio/EqmJWhjv9h9NosYk49rtluQBxvyRtTDdxMXLJdwMK-1B6g?e=mNiTFd | I23: =IF(SUM(P23:AV23)=0,"-",SUM(P23:AV23)) -> 0.5 | J23: =IF(SUMPRODUCT($P$3:$AV$3,P23:AV23)=0,"-",SUMPRODUCT($P$3:$AV$3,P23:AV23)) -> 300 | K23: 44931 | L23: 4200634748 | M23: Sent | AH23: 0.5
A24: Sony | B24: SFR | C24: 44928 | D24: Banners Inzone soldes | E24: Léa Novio | F24: Delivered | G24: TV | H24: https://saranistudio-my.sharepoint.com/:f:/g/personal/team_sarani_studio/EuGDS2OAMPpGu_ldGvZT0DMBpcZ-xeMJpp8v2XzS9CAt0g?e=xhsdm9 | I24: =IF(SUM(P24:AV24)=0,"-",SUM(P24:AV24)) -> 6 | J24: =IF(SUMPRODUCT($P$3:$AV$3,P24:AV24)=0,"-",SUMPRODUCT($P$3:$AV$3,P24:AV24)) -> 380 | K24: 44931 | L24: 4200633093 | M24: Sent | P24: 2 | Q24: 4
A25: Sony | B25: SFR | C25: 44928 | D25: OP FX3 Assets | E25: Astrid Jean-Baptiste | F25: Delivered | G25: DI | H25: https://saranistudio-my.sharepoint.com/:f:/g/personal/team_sarani_studio/EitCbbZcUbZAkfWL7WBLee8BGH7SK4bXE2Dt7jdZHoYz1g?e=PygYN7 | I25: =IF(SUM(P25:AV25)=0,"-",SUM(P25:AV25)) -> 6 | J25: =IF(SUMPRODUCT($P$3:$AV$3,P25:AV25)=0,"-",SUMPRODUCT($P$3:$AV$3,P25:AV25)) -> 295 | K25: 44931 | L25: 4200632673 | M25: Sent | O25: ok | P25: 1 | Q25: 5
A26: Sony | B26: SFR | C26: 44928 | D26: OP Trade In Janvier | E26: Astrid Jean-Baptiste | F26: Delivered | G26: DI | H26: https://saranistudio-my.sharepoint.com/:f:/g/personal/team_sarani_studio/EoitW15aeoVAtVoerfyyJgAB8NtwzeqQjRMP7QJz7L-yow?e=jCYZtF | I26: =IF(SUM(P26:AV26)=0,"-",SUM(P26:AV26)) -> 6 | J26: =IF(SUMPRODUCT($P$3:$AV$3,P26:AV26)=0,"-",SUMPRODUCT($P$3:$AV$3,P26:AV26)) -> 295 | K26: 44931 | L26: 4200632670 | M26: Sent | O26: ok | P26: 1 | Q26: 5
A27: Sony | B27: SFR | C27: 44930 | D27: Infographies NW-A306 | E27: Laura Vivient | F27: Delivered | G27: V&S | H27: https://saranistudio-my.sharepoint.com/:f:/g/personal/team_sarani_studio/Ev8VV5oNGQpDt88C9YGvPJ0BeWvCOnfN80JI8f52rlCkDA?e=svUNka | I27: =IF(SUM(P27:AV27)=0,"-",SUM(P27:AV27)) -> 9 | J27: =IF(SUMPRODUCT($P$3:$AV$3,P27:AV27)=0,"-",SUMPRODUCT($P$3:$AV$3,P27:AV27)) -> 315 | K27: 44943 | L27: 4200634882 | M27: Sent | Q27: 9
A28: Sony | B28: SFR | C28: 44930 | D28: HAV Brief créa ILV A4 accessoires | E28: Léa Novio | F28: Delivered | G28: TV | H28: https://saranistudio-my.sharepoint.com/:f:/g/personal/team_sarani_studio/ErATZuFVVhFNvJLA8_C_5_kBPisr2V-sQmmcvuADdnOrlg?e=Jt6Yhl | I28: =IF(SUM(P28:AV28)=0,"-",SUM(P28:AV28)) -> 4 | J28: =IF(SUMPRODUCT($P$3:$AV$3,P28:AV28)=0,"-",SUMPRODUCT($P$3:$AV$3,P28:AV28)) -> 300 | K28: 44941 | L28: 4200635620 | M28: Sent | X28: 3 | Y28: 1
A29: Sony | B29: SFR | C29: 44931 | D29: CREA SOLDES - XB300 | E29: Françoise Burgarella | F29: Delivered | G29: V&S | H29: https://saranistudio-my.sharepoint.com/:f:/g/personal/team_sarani_studio/EqOyYJkBr71FjjKi8T4TbU8BmZDWzGHq4lIzmPemScoNIg?e=gSGgM9 | I29: =IF(SUM(P29:AV29)=0,"-",SUM(P29:AV29)) -> 4 | J29: =IF(SUMPRODUCT($P$3:$AV$3,P29:AV29)=0,"-",SUMPRODUCT($P$3:$AV$3,P29:AV29)) -> 140 | K29: 44942 | L29: 4200633321 | M29: Sent | Q29: 4
A30: Sony | B30: SFR | C30: 44936 | D30: Update - Plan merch DI | E30: Alice Mucke | F30: Delivered | G30: DI | H30: https://saranistudio-my.sharepoint.com/:f:/g/personal/team_sarani_studio/EgL726Ww1tBPiY3JLeGkgKABHLa4iBWeCZvZMffXcTD0Ow?e=Ev0d8h | I30: =IF(SUM(P30:AV30)=0,"-",SUM(P30:AV30)) -> 2 | J30: 250 | K30: 45006 | L30: 4200639269 | M30: Sent | AB30: 2
A31: Sony | B31: SFR | C31: 44938 | D31: Additional DI assets | E31: Alice Mucke | F31: Delivered | G31: DI | H31: https://saranistudio-my.sharepoint.com/:f:/g/personal/team_sarani_studio/EitZRBZy2n1Kkw5kaWztE5sBgYKU_BFeDcX25iDrx1Ct5w?e=j19Nkg | I31: =IF(SUM(P31:AV31)=0,"-",SUM(P31:AV31)) -> 4 | J31: =IF(SUMPRODUCT($P$3:$AV$3,P31:AV31)=0,"-",SUMPRODUCT($P$3:$AV$3,P31:AV31)) -> 145 | K31: 44941 | L31: 4200639281 | M31: Sent | Q31: 3 | X31: 1
A32: Sony | B32: SFR | C32: 44938 | D32: PSK - Refresh Inlay display PSK HYPERS | E32: Laura Vivient | F32: Delivered | G32: V&S | H32: https://saranistudio-my.sharepoint.com/:f:/g/personal/team_sarani_studio/EtI6MF01VhJDu73LzSQ3CuMBaxqkBPUNcHfWG9NmZXKZGA?e=cAjunF | I32: =IF(SUM(P32:AV32)=0,"-",SUM(P32:AV32)) -> 2 | J32: =IF(SUMPRODUCT($P$3:$AV$3,P32:AV32)=0,"-",SUMPRODUCT($P$3:$AV$3,P32:AV32)) -> 80 | K32: 44941 | L32: 4270024966 | M32: Sent | X32: 2
A33: Sony | B33: SFR | C33: 44942 | D33: Newsletter PRT Janvier | E33: Alice Mucke | F33: Delivered | G33: DI | H33: - | I33: =IF(SUM(P33:AV33)=0,"-",SUM(P33:AV33)) -> 1 | J33: =IF(SUMPRODUCT($P$3:$AV$3,P33:AV33)=0,"-",SUMPRODUCT($P$3:$AV$3,P33:AV33)) -> 600 | K33: 44950 | L33: 4200639268 | M33: Sent | AH33: 1
A34: Sony | B34: SFR | C34: 44943 | D34: Lenses 3D Virtual Showroom | E34: Alice Mucke | F34: Delivered | G34: DI | H34: - | I34: =IF(SUM(P34:AV34)=0,"-",SUM(P34:AV34)) -> 1.2 | J34: =IF(SUMPRODUCT($P$3:$AV$3,P34:AV34)=0,"-",SUMPRODUCT($P$3:$AV$3,P34:AV34)) -> 3000 | K34: 44950 | L34: 4200639270 | M34: Sent | N34: 63659 | O34: Paid | AS34: =3000/2500 -> 1.2
A35: Sony | B35: SFR | C35: 44943 | D35: Bannières New VX8030 | E35: Astrid Jean-Baptiste | F35: Delivered | G35: DI | H35: https://saranistudio-my.sharepoint.com/:f:/g/personal/team_sarani_studio/EksBlAWoBtxAkG5l32B3Di0BbzDMWHG22vO5j0H6ctS9zw?e=RqK3BS | I35: =IF(SUM(P35:AV35)=0,"-",SUM(P35:AV35)) -> 4 | J35: =IF(SUMPRODUCT($P$3:$AV$3,P35:AV35)=0,"-",SUMPRODUCT($P$3:$AV$3,P35:AV35)) -> 140 | K35: 44950 | L35: 4200633858 | M35: Sent | O35: ok | Q35: 4
A36: Sony | B36: SFR | C36: 44944 | D36: HAS - podium High Power Leclerc | E36: Laura Vivient | F36: Delivered | G36: V&S | H36: https://saranistudio-my.sharepoint.com/:f:/g/personal/team_sarani_studio/Euz7AgxtBlxIhnwZ-lXXmF4BeflqaS0GTyKxYGbCz-vMlw?e=IjE9RV | I36: =IF(SUM(P36:AV36)=0,"-",SUM(P36:AV36)) -> 5 | J36: =IF(SUMPRODUCT($P$3:$AV$3,P36:AV36)=0,"-",SUMPRODUCT($P$3:$AV$3,P36:AV36)) -> 485 | K36: 44963 | L36: 4200634883 | M36: Sent | W36: 3 | X36: 2
A37: Sony | B37: SFR | C37: 44951 | D37: Dealer Days 2023 DI | E37: Héloïse Leroy | F37: Delivered | G37: Cross | H37: https://saranistudio-my.sharepoint.com/:f:/g/personal/team_sarani_studio/EmLaqFBj_51MjXZHYWWXnkoBLAa6nzoR1xsPq4BDMu7-cw?e=t3K8Ml | I37: =IF(SUM(P37:AV37)=0,"-",SUM(P37:AV37)) -> 3 | J37: =IF(SUMPRODUCT($P$3:$AV$3,P37:AV37)=0,"-",SUMPRODUCT($P$3:$AV$3,P37:AV37)) -> 310 | K37: 44963 | L37: 4200635109 | M37: Sent | W37: 2 | X37: 1
A38: Sony | B38: SFR | C38: 44951 | D38: HAV ILV4 et Awards | E38: Léa Novio | F38: Delivered | G38: TV | H38: https://saranistudio-my.sharepoint.com/:f:/g/personal/team_sarani_studio/EiFOxcsYWW5HrKMAqEXG268BJdUb73tokZ2aUpOjrqGbMw?e=ZjeN6x | I38: =IF(SUM(P38:AV38)=0,"-",SUM(P38:AV38)) -> 2 | J38: =IF(SUMPRODUCT($P$3:$AV$3,P38:AV38)=0,"-",SUMPRODUCT($P$3:$AV$3,P38:AV38)) -> 215 | K38: 44963 | L38: 4200638979 | M38: Sent | Q38: 1 | Y38: 1
A39: Sony | B39: SFR | C39: 44956 | D39: Glorifier Boulanger ZV 1F | E39: Astrid Jean-Baptiste | F39: Delivered | G39: DI | H39: https://saranistudio-my.sharepoint.com/:f:/g/personal/team_sarani_studio/Et8JT6N3J55Khs36INxlBgQBUbyHbYyC93L5UVW3Wg41vA?e=Q1dlBF | I39: =IF(SUM(P39:AV39)=0,"-",SUM(P39:AV39)) -> 2 | J39: =IF(SUMPRODUCT($P$3:$AV$3,P39:AV39)=0,"-",SUMPRODUCT($P$3:$AV$3,P39:AV39)) -> 270 | K39: 44963 | L39: 4200636045 | M39: Sent | O39: ok | W39: 2
A40: Sony | B40: SFR | C40: 44956 | D40: LANCEMENT CH720 / CH520 | E40: Laura Vivient | F40: Delivered | G40: V&S | H40: https://saranistudio-my.sharepoint.com/:f:/g/personal/team_sarani_studio/EqrCH40AdxVPsCGpjT8TB8wB_B709B2_yzvFX8TAKmXMlg?e=JQ9afM | I40: =IF(SUM(P40:AV40)=0,"-",SUM(P40:AV40)) -> 27 | J40: =IF(SUMPRODUCT($P$3:$AV$3,P40:AV40)=0,"-",SUMPRODUCT($P$3:$AV$3,P40:AV40)) -> 945 | K40: 44963 | L40: 4200637328 | M40: Sent | Q40: 27
...

Sheet Overview
A1: Performance Dashboard — Sony Projects
A3: REVENUS (€) | B3: 2022 | F3: 2023 | J3: 2024 | N3: 2025 | R3: 2026
B4: Q1 | C4: Q2 | D4: Q3 | E4: Q4 | F4: Q1 | G4: Q2 | H4: Q3 | I4: Q4 | J4: Q1 | K4: Q2 | L4: Q3 | M4: Q4 | N4: Q1 | O4: Q2 | P4: Q3 | Q4: Q4 | R4: Q1 | S4: Q2 | T4: Q3 | U4: Q4
A5: Sony France | B5: =SUMIFS('Sony France'!$N$4:$N$5001,'Sony France'!$F$4:$F$5001,">="&DATE(2022,1,1),'Sony France'!$F$4:$F$5001,"<="&DATE(2022,3,31)) -> 0 | C5: =SUMIFS('Sony France'!$N$4:$N$5001,'Sony France'!$F$4:$F$5001,">="&DATE(2022,4,1),'Sony France'!$F$4:$F$5001,"<="&DATE(2022,6,30)) -> 0 | D5: =SUMIFS('Sony France'!$N$4:$N$5001,'Sony France'!$F$4:$F$5001,">="&DATE(2022,7,1),'Sony France'!$F$4:$F$5001,"<="&DATE(2022,9,30)) -> 0 | E5: =SUMIFS('Sony France'!$N$4:$N$5001,'Sony France'!$F$4:$F$5001,">="&DATE(2022,10,1),'Sony France'!$F$4:$F$5001,"<="&DATE(2022,12,31)) -> 7475 | F5: =SUMIFS('Sony France'!$N$4:$N$5001,'Sony France'!$F$4:$F$5001,">="&DATE(2023,1,1),'Sony France'!$F$4:$F$5001,"<="&DATE(2023,3,31)) -> 27760 | G5: =SUMIFS('Sony France'!$N$4:$N$5001,'Sony France'!$F$4:$F$5001,">="&DATE(2023,4,1),'Sony France'!$F$4:$F$5001,"<="&DATE(2023,6,30)) -> 21464.17 | H5: =SUMIFS('Sony France'!$N$4:$N$5001,'Sony France'!$F$4:$F$5001,">="&DATE(2023,7,1),'Sony France'!$F$4:$F$5001,"<="&DATE(2023,9,30)) -> 23035 | I5: =SUMIFS('Sony France'!$N$4:$N$5001,'Sony France'!$F$4:$F$5001,">="&DATE(2023,10,1),'Sony France'!$F$4:$F$5001,"<="&DATE(2023,12,31)) -> 25643 | J5: =SUMIFS('Sony France'!$N$4:$N$5001,'Sony France'!$F$4:$F$5001,">="&DATE(2024,1,1),'Sony France'!$F$4:$F$5001,"<="&DATE(2024,3,31)) -> 18193 | K5: =SUMIFS('Sony France'!$N$4:$N$5001,'Sony France'!$F$4:$F$5001,">="&DATE(2024,4,1),'Sony France'!$F$4:$F$5001,"<="&DATE(2024,6,30)) -> 30285 | L5: =SUMIFS('Sony France'!$N$4:$N$5001,'Sony France'!$F$4:$F$5001,">="&DATE(2024,7,1),'Sony France'!$F$4:$F$5001,"<="&DATE(2024,9,30)) -> 23042 | M5: =SUMIFS('Sony France'!$N$4:$N$5001,'Sony France'!$F$4:$F$5001,">="&DATE(2024,10,1),'Sony France'!$F$4:$F$5001,"<="&DATE(2024,12,31)) -> 26065 | N5: =SUMIFS('Sony France'!$N$4:$N$5001,'Sony France'!$F$4:$F$5001,">="&DATE(2025,1,1),'Sony France'!$F$4:$F$5001,"<="&DATE(2025,3,31)) -> 20260 | O5: =SUMIFS('Sony France'!$N$4:$N$5001,'Sony France'!$F$4:$F$5001,">="&DATE(2025,4,1),'Sony France'!$F$4:$F$5001,"<="&DATE(2025,6,30)) -> 19590 | P5: =SUMIFS('Sony France'!$N$4:$N$5001,'Sony France'!$F$4:$F$5001,">="&DATE(2025,7,1),'Sony France'!$F$4:$F$5001,"<="&DATE(2025,9,30)) -> 21940 | Q5: =SUMIFS('Sony France'!$N$4:$N$5001,'Sony France'!$F$4:$F$5001,">="&DATE(2025,10,1),'Sony France'!$F$4:$F$5001,"<="&DATE(2025,12,31)) -> 22713 | R5: =SUMIFS('Sony France'!$N$4:$N$5001,'Sony France'!$F$4:$F$5001,">="&DATE(2026,1,1),'Sony France'!$F$4:$F$5001,"<="&DATE(2026,3,31)) -> 10105 | S5: =SUMIFS('Sony France'!$N$4:$N$5001,'Sony France'!$F$4:$F$5001,">="&DATE(2026,4,1),'Sony France'!$F$4:$F$5001,"<="&DATE(2026,6,30)) -> 0 | T5: =SUMIFS('Sony France'!$N$4:$N$5001,'Sony France'!$F$4:$F$5001,">="&DATE(2026,7,1),'Sony France'!$F$4:$F$5001,"<="&DATE(2026,9,30)) -> 0 | U5: =SUMIFS('Sony France'!$N$4:$N$5001,'Sony France'!$F$4:$F$5001,">="&DATE(2026,10,1),'Sony France'!$F$4:$F$5001,"<="&DATE(2026,12,31)) -> 0
A6: Sony Europe - Manu | B6: =SUMIFS('Sony Europe - Manu'!$J$6:$J$5000,'Sony Europe - Manu'!$C$6:$C$5000,">="&DATE(2022,1,1),'Sony Europe - Manu'!$C$6:$C$5000,"<="&DATE(2022,3,31)) -> 0 | C6: =SUMIFS('Sony Europe - Manu'!$J$6:$J$5000,'Sony Europe - Manu'!$C$6:$C$5000,">="&DATE(2022,4,1),'Sony Europe - Manu'!$C$6:$C$5000,"<="&DATE(2022,6,30)) -> 0 | D6: =SUMIFS('Sony Europe - Manu'!$J$6:$J$5000,'Sony Europe - Manu'!$C$6:$C$5000,">="&DATE(2022,7,1),'Sony Europe - Manu'!$C$6:$C$5000,"<="&DATE(2022,9,30)) -> 0 | E6: =SUMIFS('Sony Europe - Manu'!$J$6:$J$5000,'Sony Europe - Manu'!$C$6:$C$5000,">="&DATE(2022,10,1),'Sony Europe - Manu'!$C$6:$C$5000,"<="&DATE(2022,12,31)) -> 1995 | F6: =SUMIFS('Sony Europe - Manu'!$J$6:$J$5000,'Sony Europe - Manu'!$C$6:$C$5000,">="&DATE(2023,1,1),'Sony Europe - Manu'!$C$6:$C$5000,"<="&DATE(2023,3,31)) -> 41025 | G6: =SUMIFS('Sony Europe - Manu'!$J$6:$J$5000,'Sony Europe - Manu'!$C$6:$C$5000,">="&DATE(2023,4,1),'Sony Europe - Manu'!$C$6:$C$5000,"<="&DATE(2023,6,30)) -> 6315 | H6: =SUMIFS('Sony Europe - Manu'!$J$6:$J$5000,'Sony Europe - Manu'!$C$6:$C$5000,">="&DATE(2023,7,1),'Sony Europe - Manu'!$C$6:$C$5000,"<="&DATE(2023,9,30)) -> 20620 | I6: =SUMIFS('Sony Europe - Manu'!$J$6:$J$5000,'Sony Europe - Manu'!$C$6:$C$5000,">="&DATE(2023,10,1),'Sony Europe - Manu'!$C$6:$C$5000,"<="&DATE(2023,12,31)) -> 10440 | J6: =SUMIFS('Sony Europe - Manu'!$J$6:$J$5000,'Sony Europe - Manu'!$C$6:$C$5000,">="&DATE(2024,1,1),'Sony Europe - Manu'!$C$6:$C$5000,"<="&DATE(2024,3,31)) -> 18965 | K6: =SUMIFS('Sony Europe - Manu'!$J$6:$J$5000,'Sony Europe - Manu'!$C$6:$C$5000,">="&DATE(2024,4,1),'Sony Europe - Manu'!$C$6:$C$5000,"<="&DATE(2024,6,30)) -> 4925 | L6: =SUMIFS('Sony Europe - Manu'!$J$6:$J$5000,'Sony Europe - Manu'!$C$6:$C$5000,">="&DATE(2024,7,1),'Sony Europe - Manu'!$C$6:$C$5000,"<="&DATE(2024,9,30)) -> 8620 | M6: =SUMIFS('Sony Europe - Manu'!$J$6:$J$5000,'Sony Europe - Manu'!$C$6:$C$5000,">="&DATE(2024,10,1),'Sony Europe - Manu'!$C$6:$C$5000,"<="&DATE(2024,12,31)) -> 10709.25 | N6: =SUMIFS('Sony Europe - Manu'!$J$6:$J$5000,'Sony Europe - Manu'!$C$6:$C$5000,">="&DATE(2025,1,1),'Sony Europe - Manu'!$C$6:$C$5000,"<="&DATE(2025,3,31)) -> 5078 | O6: =SUMIFS('Sony Europe - Manu'!$J$6:$J$5000,'Sony Europe - Manu'!$C$6:$C$5000,">="&DATE(2025,4,1),'Sony Europe - Manu'!$C$6:$C$5000,"<="&DATE(2025,6,30)) -> 0 | P6: =SUMIFS('Sony Europe - Manu'!$J$6:$J$5000,'Sony Europe - Manu'!$C$6:$C$5000,">="&DATE(2025,7,1),'Sony Europe - Manu'!$C$6:$C$5000,"<="&DATE(2025,9,30)) -> 0 | Q6: =SUMIFS('Sony Europe - Manu'!$J$6:$J$5000,'Sony Europe - Manu'!$C$6:$C$5000,">="&DATE(2025,10,1),'Sony Europe - Manu'!$C$6:$C$5000,"<="&DATE(2025,12,31)) -> 0 | R6: =SUMIFS('Sony Europe - Manu'!$J$6:$J$5000,'Sony Europe - Manu'!$C$6:$C$5000,">="&DATE(2026,1,1),'Sony Europe - Manu'!$C$6:$C$5000,"<="&DATE(2026,3,31)) -> 0 | S6: =SUMIFS('Sony Europe - Manu'!$J$6:$J$5000,'Sony Europe - Manu'!$C$6:$C$5000,">="&DATE(2026,4,1),'Sony Europe - Manu'!$C$6:$C$5000,"<="&DATE(2026,6,30)) -> 0 | T6: =SUMIFS('Sony Europe - Manu'!$J$6:$J$5000,'Sony Europe - Manu'!$C$6:$C$5000,">="&DATE(2026,7,1),'Sony Europe - Manu'!$C$6:$C$5000,"<="&DATE(2026,9,30)) -> 0 | U6: =SUMIFS('Sony Europe - Manu'!$J$6:$J$5000,'Sony Europe - Manu'!$C$6:$C$5000,">="&DATE(2026,10,1),'Sony Europe - Manu'!$C$6:$C$5000,"<="&DATE(2026,12,31)) -> 0
A7: Sony Professional | B7: =SUMIFS('Sony Professional'!$J$4:$J$5000,'Sony Professional'!$C$4:$C$5000,">="&DATE(2022,1,1),'Sony Professional'!$C$4:$C$5000,"<="&DATE(2022,3,31)) -> 0 | C7: =SUMIFS('Sony Professional'!$J$4:$J$5000,'Sony Professional'!$C$4:$C$5000,">="&DATE(2022,4,1),'Sony Professional'!$C$4:$C$5000,"<="&DATE(2022,6,30)) -> 0 | D7: =SUMIFS('Sony Professional'!$J$4:$J$5000,'Sony Professional'!$C$4:$C$5000,">="&DATE(2022,7,1),'Sony Professional'!$C$4:$C$5000,"<="&DATE(2022,9,30)) -> 0 | E7: =SUMIFS('Sony Professional'!$J$4:$J$5000,'Sony Professional'!$C$4:$C$5000,">="&DATE(2022,10,1),'Sony Professional'!$C$4:$C$5000,"<="&DATE(2022,12,31)) -> 0 | F7: =SUMIFS('Sony Professional'!$J$4:$J$5000,'Sony Professional'!$C$4:$C$5000,">="&DATE(2023,1,1),'Sony Professional'!$C$4:$C$5000,"<="&DATE(2023,3,31)) -> 10600 | G7: =SUMIFS('Sony Professional'!$J$4:$J$5000,'Sony Professional'!$C$4:$C$5000,">="&DATE(2023,4,1),'Sony Professional'!$C$4:$C$5000,"<="&DATE(2023,6,30)) -> 25219.935 | H7: =SUMIFS('Sony Professional'!$J$4:$J$5000,'Sony Professional'!$C$4:$C$5000,">="&DATE(2023,7,1),'Sony Professional'!$C$4:$C$5000,"<="&DATE(2023,9,30)) -> 14970 | I7: =SUMIFS('Sony Professional'!$J$4:$J$5000,'Sony Professional'!$C$4:$C$5000,">="&DATE(2023,10,1),'Sony Professional'!$C$4:$C$5000,"<="&DATE(2023,12,31)) -> 27151.468 | J7: =SUMIFS('Sony Professional'!$J$4:$J$5000,'Sony Professional'!$C$4:$C$5000,">="&DATE(2024,1,1),'Sony Professional'!$C$4:$C$5000,"<="&DATE(2024,3,31)) -> 33576.4 | K7: =SUMIFS('Sony Professional'!$J$4:$J$5000,'Sony Professional'!$C$4:$C$5000,">="&DATE(2024,4,1),'Sony Professional'!$C$4:$C$5000,"<="&DATE(2024,6,30)) -> 7100 | L7: =SUMIFS('Sony Professional'!$J$4:$J$5000,'Sony Professional'!$C$4:$C$5000,">="&DATE(2024,7,1),'Sony Professional'!$C$4:$C$5000,"<="&DATE(2024,9,30)) -> 5308 | M7: =SUMIFS('Sony Professional'!$J$4:$J$5000,'Sony Professional'!$C$4:$C$5000,">="&DATE(2024,10,1),'Sony Professional'!$C$4:$C$5000,"<="&DATE(2024,12,31)) -> 11327.2 | N7: =SUMIFS('Sony Professional'!$J$4:$J$5000,'Sony Professional'!$C$4:$C$5000,">="&DATE(2025,1,1),'Sony Professional'!$C$4:$C$5000,"<="&DATE(2025,3,31)) -> 9327 | O7: =SUMIFS('Sony Professional'!$J$4:$J$5000,'Sony Professional'!$C$4:$C$5000,">="&DATE(2025,4,1),'Sony Professional'!$C$4:$C$5000,"<="&DATE(2025,6,30)) -> 9853.422 | P7: =SUMIFS('Sony Professional'!$J$4:$J$5000,'Sony Professional'!$C$4:$C$5000,">="&DATE(2025,7,1),'Sony Professional'!$C$4:$C$5000,"<="&DATE(2025,9,30)) -> 2320 | Q7: =SUMIFS('Sony Professional'!$J$4:$J$5000,'Sony Professional'!$C$4:$C$5000,">="&DATE(2025,10,1),'Sony Professional'!$C$4:$C$5000,"<="&DATE(2025,12,31)) -> 9190.25 | R7: =SUMIFS('Sony Professional'!$J$4:$J$5000,'Sony Professional'!$C$4:$C$5000,">="&DATE(2026,1,1),'Sony Professional'!$C$4:$C$5000,"<="&DATE(2026,3,31)) -> 1265 | S7: =SUMIFS('Sony Professional'!$J$4:$J$5000,'Sony Professional'!$C$4:$C$5000,">="&DATE(2026,4,1),'Sony Professional'!$C$4:$C$5000,"<="&DATE(2026,6,30)) -> 0 | T7: =SUMIFS('Sony Professional'!$J$4:$J$5000,'Sony Professional'!$C$4:$C$5000,">="&DATE(2026,7,1),'Sony Professional'!$C$4:$C$5000,"<="&DATE(2026,9,30)) -> 0 | U7: =SUMIFS('Sony Professional'!$J$4:$J$5000,'Sony Professional'!$C$4:$C$5000,">="&DATE(2026,10,1),'Sony Professional'!$C$4:$C$5000,"<="&DATE(2026,12,31)) -> 0
A8: Sony Europe - Other | B8: =SUMIFS('Sony Europe - Other'!$J$4:$J$5000,'Sony Europe - Other'!$C$4:$C$5000,">="&DATE(2022,1,1),'Sony Europe - Other'!$C$4:$C$5000,"<="&DATE(2022,3,31)) -> 0 | C8: =SUMIFS('Sony Europe - Other'!$J$4:$J$5000,'Sony Europe - Other'!$C$4:$C$5000,">="&DATE(2022,4,1),'Sony Europe - Other'!$C$4:$C$5000,"<="&DATE(2022,6,30)) -> 0 | D8: =SUMIFS('Sony Europe - Other'!$J$4:$J$5000,'Sony Europe - Other'!$C$4:$C$5000,">="&DATE(2022,7,1),'Sony Europe - Other'!$C$4:$C$5000,"<="&DATE(2022,9,30)) -> 0 | E8: =SUMIFS('Sony Europe - Other'!$J$4:$J$5000,'Sony Europe - Other'!$C$4:$C$5000,">="&DATE(2022,10,1),'Sony Europe - Other'!$C$4:$C$5000,"<="&DATE(2022,12,31)) -> 0 | F8: =SUMIFS('Sony Europe - Other'!$J$4:$J$5000,'Sony Europe - Other'!$C$4:$C$5000,">="&DATE(2023,1,1),'Sony Europe - Other'!$C$4:$C$5000,"<="&DATE(2023,3,31)) -> 0 | G8: =SUMIFS('Sony Europe - Other'!$J$4:$J$5000,'Sony Europe - Other'!$C$4:$C$5000,">="&DATE(2023,4,1),'Sony Europe - Other'!$C$4:$C$5000,"<="&DATE(2023,6,30)) -> 0 | H8: =SUMIFS('Sony Europe - Other'!$J$4:$J$5000,'Sony Europe - Other'!$C$4:$C$5000,">="&DATE(2023,7,1),'Sony Europe - Other'!$C$4:$C$5000,"<="&DATE(2023,9,30)) -> 0 | I8: =SUMIFS('Sony Europe - Other'!$J$4:$J$5000,'Sony Europe - Other'!$C$4:$C$5000,">="&DATE(2023,10,1),'Sony Europe - Other'!$C$4:$C$5000,"<="&DATE(2023,12,31)) -> 0 | J8: =SUMIFS('Sony Europe - Other'!$J$4:$J$5000,'Sony Europe - Other'!$C$4:$C$5000,">="&DATE(2024,1,1),'Sony Europe - Other'!$C$4:$C$5000,"<="&DATE(2024,3,31)) -> 0 | K8: =SUMIFS('Sony Europe - Other'!$J$4:$J$5000,'Sony Europe - Other'!$C$4:$C$5000,">="&DATE(2024,4,1),'Sony Europe - Other'!$C$4:$C$5000,"<="&DATE(2024,6,30)) -> 6300 | L8: =SUMIFS('Sony Europe - Other'!$J$4:$J$5000,'Sony Europe - Other'!$C$4:$C$5000,">="&DATE(2024,7,1),'Sony Europe - Other'!$C$4:$C$5000,"<="&DATE(2024,9,30)) -> 24955 | M8: =SUMIFS('Sony Europe - Other'!$J$4:$J$5000,'Sony Europe - Other'!$C$4:$C$5000,">="&DATE(2024,10,1),'Sony Europe - Other'!$C$4:$C$5000,"<="&DATE(2024,12,31)) -> 5814.6 | N8: =SUMIFS('Sony Europe - Other'!$J$4:$J$5000,'Sony Europe - Other'!$C$4:$C$5000,">="&DATE(2025,1,1),'Sony Europe - Other'!$C$4:$C$5000,"<="&DATE(2025,3,31)) -> 6615 | O8: =SUMIFS('Sony Europe - Other'!$J$4:$J$5000,'Sony Europe - Other'!$C$4:$C$5000,">="&DATE(2025,4,1),'Sony Europe - Other'!$C$4:$C$5000,"<="&DATE(2025,6,30)) -> 20403.8 | P8: =SUMIFS('Sony Europe - Other'!$J$4:$J$5000,'Sony Europe - Other'!$C$4:$C$5000,">="&DATE(2025,7,1),'Sony Europe - Other'!$C$4:$C$5000,"<="&DATE(2025,9,30)) -> 18978.08 | Q8: =SUMIFS('Sony Europe - Other'!$J$4:$J$5000,'Sony Europe - Other'!$C$4:$C$5000,">="&DATE(2025,10,1),'Sony Europe - Other'!$C$4:$C$5000,"<="&DATE(2025,12,31)) -> 23261.6 | R8: =SUMIFS('Sony Europe - Other'!$J$4:$J$5000,'Sony Europe - Other'!$C$4:$C$5000,">="&DATE(2026,1,1),'Sony Europe - Other'!$C$4:$C$5000,"<="&DATE(2026,3,31)) -> 8382.2 | S8: =SUMIFS('Sony Europe - Other'!$J$4:$J$5000,'Sony Europe - Other'!$C$4:$C$5000,">="&DATE(2026,4,1),'Sony Europe - Other'!$C$4:$C$5000,"<="&DATE(2026,6,30)) -> 0 | T8: =SUMIFS('Sony Europe - Other'!$J$4:$J$5000,'Sony Europe - Other'!$C$4:$C$5000,">="&DATE(2026,7,1),'Sony Europe - Other'!$C$4:$C$5000,"<="&DATE(2026,9,30)) -> 0 | U8: =SUMIFS('Sony Europe - Other'!$J$4:$J$5000,'Sony Europe - Other'!$C$4:$C$5000,">="&DATE(2026,10,1),'Sony Europe - Other'!$C$4:$C$5000,"<="&DATE(2026,12,31)) -> 0
A9: Sony Europe - New | B9: =SUMIFS('Sony Europe - New'!$J$4:$J$5000,'Sony Europe - New'!$C$4:$C$5000,">="&DATE(2022,1,1),'Sony Europe - New'!$C$4:$C$5000,"<="&DATE(2022,3,31)) -> 0 | C9: =SUMIFS('Sony Europe - New'!$J$4:$J$5000,'Sony Europe - New'!$C$4:$C$5000,">="&DATE(2022,4,1),'Sony Europe - New'!$C$4:$C$5000,"<="&DATE(2022,6,30)) -> 0 | D9: =SUMIFS('Sony Europe - New'!$J$4:$J$5000,'Sony Europe - New'!$C$4:$C$5000,">="&DATE(2022,7,1),'Sony Europe - New'!$C$4:$C$5000,"<="&DATE(2022,9,30)) -> 0 | E9: =SUMIFS('Sony Europe - New'!$J$4:$J$5000,'Sony Europe - New'!$C$4:$C$5000,">="&DATE(2022,10,1),'Sony Europe - New'!$C$4:$C$5000,"<="&DATE(2022,12,31)) -> 0 | F9: =SUMIFS('Sony Europe - New'!$J$4:$J$5000,'Sony Europe - New'!$C$4:$C$5000,">="&DATE(2023,1,1),'Sony Europe - New'!$C$4:$C$5000,"<="&DATE(2023,3,31)) -> 0 | G9: =SUMIFS('Sony Europe - New'!$J$4:$J$5000,'Sony Europe - New'!$C$4:$C$5000,">="&DATE(2023,4,1),'Sony Europe - New'!$C$4:$C$5000,"<="&DATE(2023,6,30)) -> 0 | H9: =SUMIFS('Sony Europe - New'!$J$4:$J$5000,'Sony Europe - New'!$C$4:$C$5000,">="&DATE(2023,7,1),'Sony Europe - New'!$C$4:$C$5000,"<="&DATE(2023,9,30)) -> 0 | I9: =SUMIFS('Sony Europe - New'!$J$4:$J$5000,'Sony Europe - New'!$C$4:$C$5000,">="&DATE(2023,10,1),'Sony Europe - New'!$C$4:$C$5000,"<="&DATE(2023,12,31)) -> 0 | J9: =SUMIFS('Sony Europe - New'!$J$4:$J$5000,'Sony Europe - New'!$C$4:$C$5000,">="&DATE(2024,1,1),'Sony Europe - New'!$C$4:$C$5000,"<="&DATE(2024,3,31)) -> 0 | K9: =SUMIFS('Sony Europe - New'!$J$4:$J$5000,'Sony Europe - New'!$C$4:$C$5000,">="&DATE(2024,4,1),'Sony Europe - New'!$C$4:$C$5000,"<="&DATE(2024,6,30)) -> 0 | L9: =SUMIFS('Sony Europe - New'!$J$4:$J$5000,'Sony Europe - New'!$C$4:$C$5000,">="&DATE(2024,7,1),'Sony Europe - New'!$C$4:$C$5000,"<="&DATE(2024,9,30)) -> 0 | M9: =SUMIFS('Sony Europe - New'!$J$4:$J$5000,'Sony Europe - New'!$C$4:$C$5000,">="&DATE(2024,10,1),'Sony Europe - New'!$C$4:$C$5000,"<="&DATE(2024,12,31)) -> 0 | N9: =SUMIFS('Sony Europe - New'!$J$4:$J$5000,'Sony Europe - New'!$C$4:$C$5000,">="&DATE(2025,1,1),'Sony Europe - New'!$C$4:$C$5000,"<="&DATE(2025,3,31)) -> 0 | O9: =SUMIFS('Sony Europe - New'!$J$4:$J$5000,'Sony Europe - New'!$C$4:$C$5000,">="&DATE(2025,4,1),'Sony Europe - New'!$C$4:$C$5000,"<="&DATE(2025,6,30)) -> 6325 | P9: =SUMIFS('Sony Europe - New'!$J$4:$J$5000,'Sony Europe - New'!$C$4:$C$5000,">="&DATE(2025,7,1),'Sony Europe - New'!$C$4:$C$5000,"<="&DATE(2025,9,30)) -> 0 | Q9: =SUMIFS('Sony Europe - New'!$J$4:$J$5000,'Sony Europe - New'!$C$4:$C$5000,">="&DATE(2025,10,1),'Sony Europe - New'!$C$4:$C$5000,"<="&DATE(2025,12,31)) -> 0 | R9: =SUMIFS('Sony Europe - New'!$J$4:$J$5000,'Sony Europe - New'!$C$4:$C$5000,">="&DATE(2026,1,1),'Sony Europe - New'!$C$4:$C$5000,"<="&DATE(2026,3,31)) -> 0 | S9: =SUMIFS('Sony Europe - New'!$J$4:$J$5000,'Sony Europe - New'!$C$4:$C$5000,">="&DATE(2026,4,1),'Sony Europe - New'!$C$4:$C$5000,"<="&DATE(2026,6,30)) -> 0 | T9: =SUMIFS('Sony Europe - New'!$J$4:$J$5000,'Sony Europe - New'!$C$4:$C$5000,">="&DATE(2026,7,1),'Sony Europe - New'!$C$4:$C$5000,"<="&DATE(2026,9,30)) -> 0 | U9: =SUMIFS('Sony Europe - New'!$J$4:$J$5000,'Sony Europe - New'!$C$4:$C$5000,">="&DATE(2026,10,1),'Sony Europe - New'!$C$4:$C$5000,"<="&DATE(2026,12,31)) -> 0
A11: TOTAL | B11: =SUM(B5:B9) -> 0 | C11: =SUM(C5:C9) -> 0 | D11: =SUM(D5:D9) -> 0 | E11: =SUM(E5:E9) -> 9470 | F11: =SUM(F5:F9) -> 79385 | G11: =SUM(G5:G9) -> 52999.105 | H11: =SUM(H5:H9) -> 58625 | I11: =SUM(I5:I9) -> 63234.468 | ... U11: =SUM(U5:U9) -> 0
A13: NOMBRE DE PROJETS | B13: 2022 | F13: 2023 | J13: 2024 | N13: 2025 | R13: 2026
B14: Q1 | C14: Q2 | D14: Q3 | E14: Q4 | F14: Q1 | G14: Q2 | H14: Q3 | I14: Q4 | J14: Q1 | K14: Q2 | L14: Q3 | M14: Q4 | N14: Q1 | O14: Q2 | P14: Q3 | Q14: Q4 | R14: Q1 | S14: Q2 | T14: Q3 | U14: Q4
