Workbook

Sheet Overview
A1: Performance Dashboard — Sarani Studio
A3: REVENUS (€) | B3: 2022 | F3: 2023 | J3: 2024 | N3: 2025 | R3: 2026
B4: Q1 | C4: Q2 | D4: Q3 | E4: Q4 | F4: Q1 | G4: Q2 | H4: Q3 | I4: Q4 | J4: Q1 | K4: Q2 | L4: Q3 | M4: Q4 | N4: Q1 | O4: Q2 | P4: Q3 | Q4: Q4 | R4: Q1 | S4: Q2 | T4: Q3 | U4: Q4
A5: All Projects | B5: =SUMIFS('All projects'!I$2:I$1000,'All projects'!B$2:B$1000,">="&DATE(2022,1,1),'All projects'!B$2:B$1000,"<="&DATE(2022,3+1,0)) -> 0 | C5: =SUMIFS('All projects'!I$2:I$1000,'All projects'!B$2:B$1000,">="&DATE(2022,4,1),'All projects'!B$2:B$1000,"<="&DATE(2022,6+1,0)) -> 0 | D5: =SUMIFS('All projects'!I$2:I$1000,'All projects'!B$2:B$1000,">="&DATE(2022,7,1),'All projects'!B$2:B$1000,"<="&DATE(2022,9+1,0)) -> 5000 | E5: =SUMIFS('All projects'!I$2:I$1000,'All projects'!B$2:B$1000,">="&DATE(2022,10,1),'All projects'!B$2:B$1000,"<="&DATE(2022,12+1,0)) -> 0 | F5: =SUMIFS('All projects'!I$2:I$1000,'All projects'!B$2:B$1000,">="&DATE(2023,1,1),'All projects'!B$2:B$1000,"<="&DATE(2023,3+1,0)) -> 0 | G5: =SUMIFS('All projects'!I$2:I$1000,'All projects'!B$2:B$1000,">="&DATE(2023,4,1),'All projects'!B$2:B$1000,"<="&DATE(2023,6+1,0)) -> 8650 | H5: =SUMIFS('All projects'!I$2:I$1000,'All projects'!B$2:B$1000,">="&DATE(2023,7,1),'All projects'!B$2:B$1000,"<="&DATE(2023,9+1,0)) -> 1950 | I5: =SUMIFS('All projects'!I$2:I$1000,'All projects'!B$2:B$1000,">="&DATE(2023,10,1),'All projects'!B$2:B$1000,"<="&DATE(2023,12+1,0)) -> 3080 | J5: =SUMIFS('All projects'!I$2:I$1000,'All projects'!B$2:B$1000,">="&DATE(2024,1,1),'All projects'!B$2:B$1000,"<="&DATE(2024,3+1,0)) -> 2840 | K5: =SUMIFS('All projects'!I$2:I$1000,'All projects'!B$2:B$1000,">="&DATE(2024,4,1),'All projects'!B$2:B$1000,"<="&DATE(2024,6+1,0)) -> 42371 | L5: =SUMIFS('All projects'!I$2:I$1000,'All projects'!B$2:B$1000,">="&DATE(2024,7,1),'All projects'!B$2:B$1000,"<="&DATE(2024,9+1,0)) -> 122955 | M5: =SUMIFS('All projects'!I$2:I$1000,'All projects'!B$2:B$1000,">="&DATE(2024,10,1),'All projects'!B$2:B$1000,"<="&DATE(2024,12+1,0)) -> 3490 | N5: =SUMIFS('All projects'!I$2:I$1000,'All projects'!B$2:B$1000,">="&DATE(2025,1,1),'All projects'!B$2:B$1000,"<="&DATE(2025,3+1,0)) -> 11105 | O5: =SUMIFS('All projects'!I$2:I$1000,'All projects'!B$2:B$1000,">="&DATE(2025,4,1),'All projects'!B$2:B$1000,"<="&DATE(2025,6+1,0)) -> 63830 | P5: =SUMIFS('All projects'!I$2:I$1000,'All projects'!B$2:B$1000,">="&DATE(2025,7,1),'All projects'!B$2:B$1000,"<="&DATE(2025,9+1,0)) -> 29620 | Q5: =SUMIFS('All projects'!I$2:I$1000,'All projects'!B$2:B$1000,">="&DATE(2025,10,1),'All projects'!B$2:B$1000,"<="&DATE(2025,12+1,0)) -> 19506.17 | R5: =SUMIFS('All projects'!I$2:I$1000,'All projects'!B$2:B$1000,">="&DATE(2026,1,1),'All projects'!B$2:B$1000,"<="&DATE(2026,3+1,0)) -> 19630 | S5: =SUMIFS('All projects'!I$2:I$1000,'All projects'!B$2:B$1000,">="&DATE(2026,4,1),'All projects'!B$2:B$1000,"<="&DATE(2026,6+1,0)) -> 0 | T5: =SUMIFS('All projects'!I$2:I$1000,'All projects'!B$2:B$1000,">="&DATE(2026,7,1),'All projects'!B$2:B$1000,"<="&DATE(2026,9+1,0)) -> 0 | U5: =SUMIFS('All projects'!I$2:I$1000,'All projects'!B$2:B$1000,">="&DATE(2026,10,1),'All projects'!B$2:B$1000,"<="&DATE(2026,12+1,0)) -> 3428
A6: ProcessOut | B6: =SUMIFS(ProcessOut!J$4:J$1000,ProcessOut!C$4:C$1000,">="&DATE(2022,1,1),ProcessOut!C$4:C$1000,"<="&DATE(2022,3+1,0)) -> 0 | C6: =SUMIFS(ProcessOut!J$4:J$1000,ProcessOut!C$4:C$1000,">="&DATE(2022,4,1),ProcessOut!C$4:C$1000,"<="&DATE(2022,6+1,0)) -> 0 | D6: =SUMIFS(ProcessOut!J$4:J$1000,ProcessOut!C$4:C$1000,">="&DATE(2022,7,1),ProcessOut!C$4:C$1000,"<="&DATE(2022,9+1,0)) -> 0 | E6: =SUMIFS(ProcessOut!J$4:J$1000,ProcessOut!C$4:C$1000,">="&DATE(2022,10,1),ProcessOut!C$4:C$1000,"<="&DATE(2022,12+1,0)) -> 0 | F6: =SUMIFS(ProcessOut!J$4:J$1000,ProcessOut!C$4:C$1000,">="&DATE(2023,1,1),ProcessOut!C$4:C$1000,"<="&DATE(2023,3+1,0)) -> 0 | G6: =SUMIFS(ProcessOut!J$4:J$1000,ProcessOut!C$4:C$1000,">="&DATE(2023,4,1),ProcessOut!C$4:C$1000,"<="&DATE(2023,6+1,0)) -> 0 | H6: =SUMIFS(ProcessOut!J$4:J$1000,ProcessOut!C$4:C$1000,">="&DATE(2023,7,1),ProcessOut!C$4:C$1000,"<="&DATE(2023,9+1,0)) -> 0 | I6: =SUMIFS(ProcessOut!J$4:J$1000,ProcessOut!C$4:C$1000,">="&DATE(2023,10,1),ProcessOut!C$4:C$1000,"<="&DATE(2023,12+1,0)) -> 0 | J6: =SUMIFS(ProcessOut!J$4:J$1000,ProcessOut!C$4:C$1000,">="&DATE(2024,1,1),ProcessOut!C$4:C$1000,"<="&DATE(2024,3+1,0)) -> 0 | K6: =SUMIFS(ProcessOut!J$4:J$1000,ProcessOut!C$4:C$1000,">="&DATE(2024,4,1),ProcessOut!C$4:C$1000,"<="&DATE(2024,6+1,0)) -> 900 | L6: =SUMIFS(ProcessOut!J$4:J$1000,ProcessOut!C$4:C$1000,">="&DATE(2024,7,1),ProcessOut!C$4:C$1000,"<="&DATE(2024,9+1,0)) -> 3600 | M6: =SUMIFS(ProcessOut!J$4:J$1000,ProcessOut!C$4:C$1000,">="&DATE(2024,10,1),ProcessOut!C$4:C$1000,"<="&DATE(2024,12+1,0)) -> 5400 | N6: =SUMIFS(ProcessOut!J$4:J$1000,ProcessOut!C$4:C$1000,">="&DATE(2025,1,1),ProcessOut!C$4:C$1000,"<="&DATE(2025,3+1,0)) -> 10600 | O6: =SUMIFS(ProcessOut!J$4:J$1000,ProcessOut!C$4:C$1000,">="&DATE(2025,4,1),ProcessOut!C$4:C$1000,"<="&DATE(2025,6+1,0)) -> 21000 | P6: =SUMIFS(ProcessOut!J$4:J$1000,ProcessOut!C$4:C$1000,">="&DATE(2025,7,1),ProcessOut!C$4:C$1000,"<="&DATE(2025,9+1,0)) -> 42900 | Q6: =SUMIFS(ProcessOut!J$4:J$1000,ProcessOut!C$4:C$1000,">="&DATE(2025,10,1),ProcessOut!C$4:C$1000,"<="&DATE(2025,12+1,0)) -> 0 | R6: =SUMIFS(ProcessOut!J$4:J$1000,ProcessOut!C$4:C$1000,">="&DATE(2026,1,1),ProcessOut!C$4:C$1000,"<="&DATE(2026,3+1,0)) -> 22350 | S6: =SUMIFS(ProcessOut!J$4:J$1000,ProcessOut!C$4:C$1000,">="&DATE(2026,4,1),ProcessOut!C$4:C$1000,"<="&DATE(2026,6+1,0)) -> 22350 | T6: =SUMIFS(ProcessOut!J$4:J$1000,ProcessOut!C$4:C$1000,">="&DATE(2026,7,1),ProcessOut!C$4:C$1000,"<="&DATE(2026,9+1,0)) -> 22350 | U6: =SUMIFS(ProcessOut!J$4:J$1000,ProcessOut!C$4:C$1000,">="&DATE(2026,10,1),ProcessOut!C$4:C$1000,"<="&DATE(2026,12+1,0)) -> 22350
A7: Connect | B7: =SUMIFS(Connect!J$4:J$1000,Connect!C$4:C$1000,">="&DATE(2022,1,1),Connect!C$4:C$1000,"<="&DATE(2022,3+1,0))/$B$25 -> 0 | C7: =SUMIFS(Connect!J$4:J$1000,Connect!C$4:C$1000,">="&DATE(2022,4,1),Connect!C$4:C$1000,"<="&DATE(2022,6+1,0))/$B$25 -> 0 | D7: =SUMIFS(Connect!J$4:J$1000,Connect!C$4:C$1000,">="&DATE(2022,7,1),Connect!C$4:C$1000,"<="&DATE(2022,9+1,0))/$B$25 -> 0 | E7: =SUMIFS(Connect!J$4:J$1000,Connect!C$4:C$1000,">="&DATE(2022,10,1),Connect!C$4:C$1000,"<="&DATE(2022,12+1,0))/$B$25 -> 0 | F7: =SUMIFS(Connect!J$4:J$1000,Connect!C$4:C$1000,">="&DATE(2023,1,1),Connect!C$4:C$1000,"<="&DATE(2023,3+1,0))/$B$25 -> 0 | G7: =SUMIFS(Connect!J$4:J$1000,Connect!C$4:C$1000,">="&DATE(2023,4,1),Connect!C$4:C$1000,"<="&DATE(2023,6+1,0))/$B$25 -> 0 | H7: =SUMIFS(Connect!J$4:J$1000,Connect!C$4:C$1000,">="&DATE(2023,7,1),Connect!C$4:C$1000,"<="&DATE(2023,9+1,0))/$B$25 -> 0 | I7: =SUMIFS(Connect!J$4:J$1000,Connect!C$4:C$1000,">="&DATE(2023,10,1),Connect!C$4:C$1000,"<="&DATE(2023,12+1,0))/$B$25 -> 0 | J7: =SUMIFS(Connect!J$4:J$1000,Connect!C$4:C$1000,">="&DATE(2024,1,1),Connect!C$4:C$1000,"<="&DATE(2024,3+1,0))/$B$25 -> 0 | K7: =SUMIFS(Connect!J$4:J$1000,Connect!C$4:C$1000,">="&DATE(2024,4,1),Connect!C$4:C$1000,"<="&DATE(2024,6+1,0))/$B$25 -> 0 | L7: =SUMIFS(Connect!J$4:J$1000,Connect!C$4:C$1000,">="&DATE(2024,7,1),Connect!C$4:C$1000,"<="&DATE(2024,9+1,0))/$B$25 -> 3913.0435 | M7: =SUMIFS(Connect!J$4:J$1000,Connect!C$4:C$1000,">="&DATE(2024,10,1),Connect!C$4:C$1000,"<="&DATE(2024,12+1,0))/$B$25 -> 1304.3478 | N7: =SUMIFS(Connect!J$4:J$1000,Connect!C$4:C$1000,">="&DATE(2025,1,1),Connect!C$4:C$1000,"<="&DATE(2025,3+1,0))/$B$25 -> 739.13043 | O7: =SUMIFS(Connect!J$4:J$1000,Connect!C$4:C$1000,">="&DATE(2025,4,1),Connect!C$4:C$1000,"<="&DATE(2025,6+1,0))/$B$25 -> 478.26087 | P7: =SUMIFS(Connect!J$4:J$1000,Connect!C$4:C$1000,">="&DATE(2025,7,1),Connect!C$4:C$1000,"<="&DATE(2025,9+1,0))/$B$25 -> 1630.4348 | Q7: =SUMIFS(Connect!J$4:J$1000,Connect!C$4:C$1000,">="&DATE(2025,10,1),Connect!C$4:C$1000,"<="&DATE(2025,12+1,0))/$B$25 -> 0 | R7: =SUMIFS(Connect!J$4:J$1000,Connect!C$4:C$1000,">="&DATE(2026,1,1),Connect!C$4:C$1000,"<="&DATE(2026,3+1,0))/$B$25 -> 0 | S7: =SUMIFS(Connect!J$4:J$1000,Connect!C$4:C$1000,">="&DATE(2026,4,1),Connect!C$4:C$1000,"<="&DATE(2026,6+1,0))/$B$25 -> 0 | T7: =SUMIFS(Connect!J$4:J$1000,Connect!C$4:C$1000,">="&DATE(2026,7,1),Connect!C$4:C$1000,"<="&DATE(2026,9+1,0))/$B$25 -> 0 | U7: =SUMIFS(Connect!J$4:J$1000,Connect!C$4:C$1000,">="&DATE(2026,10,1),Connect!C$4:C$1000,"<="&DATE(2026,12+1,0))/$B$25 -> 0
A8: Oneov | B8: =SUMIFS(Oneov!H$4:H$1000,Oneov!A$4:A$1000,">="&DATE(2022,1,1),Oneov!A$4:A$1000,"<="&DATE(2022,3+1,0)) -> 0 | C8: =SUMIFS(Oneov!H$4:H$1000,Oneov!A$4:A$1000,">="&DATE(2022,4,1),Oneov!A$4:A$1000,"<="&DATE(2022,6+1,0)) -> 0 | D8: =SUMIFS(Oneov!H$4:H$1000,Oneov!A$4:A$1000,">="&DATE(2022,7,1),Oneov!A$4:A$1000,"<="&DATE(2022,9+1,0)) -> 0 | E8: =SUMIFS(Oneov!H$4:H$1000,Oneov!A$4:A$1000,">="&DATE(2022,10,1),Oneov!A$4:A$1000,"<="&DATE(2022,12+1,0)) -> 0 | F8: =SUMIFS(Oneov!H$4:H$1000,Oneov!A$4:A$1000,">="&DATE(2023,1,1),Oneov!A$4:A$1000,"<="&DATE(2023,3+1,0)) -> 0 | G8: =SUMIFS(Oneov!H$4:H$1000,Oneov!A$4:A$1000,">="&DATE(2023,4,1),Oneov!A$4:A$1000,"<="&DATE(2023,6+1,0)) -> 0 | H8: =SUMIFS(Oneov!H$4:H$1000,Oneov!A$4:A$1000,">="&DATE(2023,7,1),Oneov!A$4:A$1000,"<="&DATE(2023,9+1,0)) -> 0 | I8: =SUMIFS(Oneov!H$4:H$1000,Oneov!A$4:A$1000,">="&DATE(2023,10,1),Oneov!A$4:A$1000,"<="&DATE(2023,12+1,0)) -> 0 | J8: =SUMIFS(Oneov!H$4:H$1000,Oneov!A$4:A$1000,">="&DATE(2024,1,1),Oneov!A$4:A$1000,"<="&DATE(2024,3+1,0)) -> 13150 | K8: =SUMIFS(Oneov!H$4:H$1000,Oneov!A$4:A$1000,">="&DATE(2024,4,1),Oneov!A$4:A$1000,"<="&DATE(2024,6+1,0)) -> 0 | L8: =SUMIFS(Oneov!H$4:H$1000,Oneov!A$4:A$1000,">="&DATE(2024,7,1),Oneov!A$4:A$1000,"<="&DATE(2024,9+1,0)) -> 0 | M8: =SUMIFS(Oneov!H$4:H$1000,Oneov!A$4:A$1000,">="&DATE(2024,10,1),Oneov!A$4:A$1000,"<="&DATE(2024,12+1,0)) -> 0 | N8: =SUMIFS(Oneov!H$4:H$1000,Oneov!A$4:A$1000,">="&DATE(2025,1,1),Oneov!A$4:A$1000,"<="&DATE(2025,3+1,0)) -> 0 | O8: =SUMIFS(Oneov!H$4:H$1000,Oneov!A$4:A$1000,">="&DATE(2025,4,1),Oneov!A$4:A$1000,"<="&DATE(2025,6+1,0)) -> 0 | P8: =SUMIFS(Oneov!H$4:H$1000,Oneov!A$4:A$1000,">="&DATE(2025,7,1),Oneov!A$4:A$1000,"<="&DATE(2025,9+1,0)) -> 0 | Q8: =SUMIFS(Oneov!H$4:H$1000,Oneov!A$4:A$1000,">="&DATE(2025,10,1),Oneov!A$4:A$1000,"<="&DATE(2025,12+1,0)) -> 0 | R8: =SUMIFS(Oneov!H$4:H$1000,Oneov!A$4:A$1000,">="&DATE(2026,1,1),Oneov!A$4:A$1000,"<="&DATE(2026,3+1,0)) -> 0 | S8: =SUMIFS(Oneov!H$4:H$1000,Oneov!A$4:A$1000,">="&DATE(2026,4,1),Oneov!A$4:A$1000,"<="&DATE(2026,6+1,0)) -> 0 | T8: =SUMIFS(Oneov!H$4:H$1000,Oneov!A$4:A$1000,">="&DATE(2026,7,1),Oneov!A$4:A$1000,"<="&DATE(2026,9+1,0)) -> 0 | U8: =SUMIFS(Oneov!H$4:H$1000,Oneov!A$4:A$1000,">="&DATE(2026,10,1),Oneov!A$4:A$1000,"<="&DATE(2026,12+1,0)) -> 0
A9: TOTAL | B9: =SUM(B5:B8) -> 0 | C9: =SUM(C5:C8) -> 0 | D9: =SUM(D5:D8) -> 5000 | E9: =SUM(E5:E8) -> 0 | F9: =SUM(F5:F8) -> 0 | G9: =SUM(G5:G8) -> 8650 | H9: =SUM(H5:H8) -> 1950 | I9: =SUM(I5:I8) -> 3080 | ... U9: =SUM(U5:U8) -> 25778
A11: NOMBRE DE PROJETS | B11: 2022 | F11: 2023 | J11: 2024 | N11: 2025 | R11: 2026
B12: Q1 | C12: Q2 | D12: Q3 | E12: Q4 | F12: Q1 | G12: Q2 | H12: Q3 | I12: Q4 | J12: Q1 | K12: Q2 | L12: Q3 | M12: Q4 | N12: Q1 | O12: Q2 | P12: Q3 | Q12: Q4 | R12: Q1 | S12: Q2 | T12: Q3 | U12: Q4
A13: All Projects | B13: =COUNTIFS('All projects'!B$2:B$1000,">="&DATE(2022,1,1),'All projects'!B$2:B$1000,"<="&DATE(2022,3+1,0)) -> 0 | C13: =COUNTIFS('All projects'!B$2:B$1000,">="&DATE(2022,4,1),'All projects'!B$2:B$1000,"<="&DATE(2022,6+1,0)) -> 0 | D13: =COUNTIFS('All projects'!B$2:B$1000,">="&DATE(2022,7,1),'All projects'!B$2:B$1000,"<="&DATE(2022,9+1,0)) -> 1 | E13: =COUNTIFS('All projects'!B$2:B$1000,">="&DATE(2022,10,1),'All projects'!B$2:B$1000,"<="&DATE(2022,12+1,0)) -> 0 | F13: =COUNTIFS('All projects'!B$2:B$1000,">="&DATE(2023,1,1),'All projects'!B$2:B$1000,"<="&DATE(2023,3+1,0)) -> 0 | G13: =COUNTIFS('All projects'!B$2:B$1000,">="&DATE(2023,4,1),'All projects'!B$2:B$1000,"<="&DATE(2023,6+1,0)) -> 4 | H13: =COUNTIFS('All projects'!B$2:B$1000,">="&DATE(2023,7,1),'All projects'!B$2:B$1000,"<="&DATE(2023,9+1,0)) -> 2 | I13: =COUNTIFS('All projects'!B$2:B$1000,">="&DATE(2023,10,1),'All projects'!B$2:B$1000,"<="&DATE(2023,12+1,0)) -> 4 | J13: =COUNTIFS('All projects'!B$2:B$1000,">="&DATE(2024,1,1),'All projects'!B$2:B$1000,"<="&DATE(2024,3+1,0)) -> 7 | K13: =COUNTIFS('All projects'!B$2:B$1000,">="&DATE(2024,4,1),'All projects'!B$2:B$1000,"<="&DATE(2024,6+1,0)) -> 15 | L13: =COUNTIFS('All projects'!B$2:B$1000,">="&DATE(2024,7,1),'All projects'!B$2:B$1000,"<="&DATE(2024,9+1,0)) -> 28 | M13: =COUNTIFS('All projects'!B$2:B$1000,">="&DATE(2024,10,1),'All projects'!B$2:B$1000,"<="&DATE(2024,12+1,0)) -> 8 | N13: =COUNTIFS('All projects'!B$2:B$1000,">="&DATE(2025,1,1),'All projects'!B$2:B$1000,"<="&DATE(2025,3+1,0)) -> 16 | O13: =COUNTIFS('All projects'!B$2:B$1000,">="&DATE(2025,4,1),'All projects'!B$2:B$1000,"<="&DATE(2025,6+1,0)) -> 16 | P13: =COUNTIFS('All projects'!B$2:B$1000,">="&DATE(2025,7,1),'All projects'!B$2:B$1000,"<="&DATE(2025,9+1,0)) -> 13 | Q13: =COUNTIFS('All projects'!B$2:B$1000,">="&DATE(2025,10,1),'All projects'!B$2:B$1000,"<="&DATE(2025,12+1,0)) -> 12 | R13: =COUNTIFS('All projects'!B$2:B$1000,">="&DATE(2026,1,1),'All projects'!B$2:B$1000,"<="&DATE(2026,3+1,0)) -> 11 | S13: =COUNTIFS('All projects'!B$2:B$1000,">="&DATE(2026,4,1),'All projects'!B$2:B$1000,"<="&DATE(2026,6+1,0)) -> 0 | T13: =COUNTIFS('All projects'!B$2:B$1000,">="&DATE(2026,7,1),'All projects'!B$2:B$1000,"<="&DATE(2026,9+1,0)) -> 0 | U13: =COUNTIFS('All projects'!B$2:B$1000,">="&DATE(2026,10,1),'All projects'!B$2:B$1000,"<="&DATE(2026,12+1,0)) -> 2
A14: ProcessOut | B14: =COUNTIFS(ProcessOut!C$4:C$1000,">="&DATE(2022,1,1),ProcessOut!C$4:C$1000,"<="&DATE(2022,3+1,0)) -> 0 | C14: =COUNTIFS(ProcessOut!C$4:C$1000,">="&DATE(2022,4,1),ProcessOut!C$4:C$1000,"<="&DATE(2022,6+1,0)) -> 0 | D14: =COUNTIFS(ProcessOut!C$4:C$1000,">="&DATE(2022,7,1),ProcessOut!C$4:C$1000,"<="&DATE(2022,9+1,0)) -> 0 | E14: =COUNTIFS(ProcessOut!C$4:C$1000,">="&DATE(2022,10,1),ProcessOut!C$4:C$1000,"<="&DATE(2022,12+1,0)) -> 0 | F14: =COUNTIFS(ProcessOut!C$4:C$1000,">="&DATE(2023,1,1),ProcessOut!C$4:C$1000,"<="&DATE(2023,3+1,0)) -> 0 | G14: =COUNTIFS(ProcessOut!C$4:C$1000,">="&DATE(2023,4,1),ProcessOut!C$4:C$1000,"<="&DATE(2023,6+1,0)) -> 0 | H14: =COUNTIFS(ProcessOut!C$4:C$1000,">="&DATE(2023,7,1),ProcessOut!C$4:C$1000,"<="&DATE(2023,9+1,0)) -> 0 | I14: =COUNTIFS(ProcessOut!C$4:C$1000,">="&DATE(2023,10,1),ProcessOut!C$4:C$1000,"<="&DATE(2023,12+1,0)) -> 0 | J14: =COUNTIFS(ProcessOut!C$4:C$1000,">="&DATE(2024,1,1),ProcessOut!C$4:C$1000,"<="&DATE(2024,3+1,0)) -> 0 | K14: =COUNTIFS(ProcessOut!C$4:C$1000,">="&DATE(2024,4,1),ProcessOut!C$4:C$1000,"<="&DATE(2024,6+1,0)) -> 3 | L14: =COUNTIFS(ProcessOut!C$4:C$1000,">="&DATE(2024,7,1),ProcessOut!C$4:C$1000,"<="&DATE(2024,9+1,0)) -> 3 | M14: =COUNTIFS(ProcessOut!C$4:C$1000,">="&DATE(2024,10,1),ProcessOut!C$4:C$1000,"<="&DATE(2024,12+1,0)) -> 3 | N14: =COUNTIFS(ProcessOut!C$4:C$1000,">="&DATE(2025,1,1),ProcessOut!C$4:C$1000,"<="&DATE(2025,3+1,0)) -> 3 | O14: =COUNTIFS(ProcessOut!C$4:C$1000,">="&DATE(2025,4,1),ProcessOut!C$4:C$1000,"<="&DATE(2025,6+1,0)) -> 3 | P14: =COUNTIFS(ProcessOut!C$4:C$1000,">="&DATE(2025,7,1),ProcessOut!C$4:C$1000,"<="&DATE(2025,9+1,0)) -> 8 | Q14: =COUNTIFS(ProcessOut!C$4:C$1000,">="&DATE(2025,10,1),ProcessOut!C$4:C$1000,"<="&DATE(2025,12+1,0)) -> 0 | R14: =COUNTIFS(ProcessOut!C$4:C$1000,">="&DATE(2026,1,1),ProcessOut!C$4:C$1000,"<="&DATE(2026,3+1,0)) -> 6 | S14: =COUNTIFS(ProcessOut!C$4:C$1000,">="&DATE(2026,4,1),ProcessOut!C$4:C$1000,"<="&DATE(2026,6+1,0)) -> 6 | T14: =COUNTIFS(ProcessOut!C$4:C$1000,">="&DATE(2026,7,1),ProcessOut!C$4:C$1000,"<="&DATE(2026,9+1,0)) -> 6 | U14: =COUNTIFS(ProcessOut!C$4:C$1000,">="&DATE(2026,10,1),ProcessOut!C$4:C$1000,"<="&DATE(2026,12+1,0)) -> 6
A15: Connect | B15: =COUNTIFS(Connect!C$4:C$1000,">="&DATE(2022,1,1),Connect!C$4:C$1000,"<="&DATE(2022,3+1,0)) -> 0 | C15: =COUNTIFS(Connect!C$4:C$1000,">="&DATE(2022,4,1),Connect!C$4:C$1000,"<="&DATE(2022,6+1,0)) -> 0 | D15: =COUNTIFS(Connect!C$4:C$1000,">="&DATE(2022,7,1),Connect!C$4:C$1000,"<="&DATE(2022,9+1,0)) -> 0 | E15: =COUNTIFS(Connect!C$4:C$1000,">="&DATE(2022,10,1),Connect!C$4:C$1000,"<="&DATE(2022,12+1,0)) -> 0 | F15: =COUNTIFS(Connect!C$4:C$1000,">="&DATE(2023,1,1),Connect!C$4:C$1000,"<="&DATE(2023,3+1,0)) -> 0 | G15: =COUNTIFS(Connect!C$4:C$1000,">="&DATE(2023,4,1),Connect!C$4:C$1000,"<="&DATE(2023,6+1,0)) -> 0 | H15: =COUNTIFS(Connect!C$4:C$1000,">="&DATE(2023,7,1),Connect!C$4:C$1000,"<="&DATE(2023,9+1,0)) -> 0 | I15: =COUNTIFS(Connect!C$4:C$1000,">="&DATE(2023,10,1),Connect!C$4:C$1000,"<="&DATE(2023,12+1,0)) -> 0 | J15: =COUNTIFS(Connect!C$4:C$1000,">="&DATE(2024,1,1),Connect!C$4:C$1000,"<="&DATE(2024,3+1,0)) -> 0 | K15: =COUNTIFS(Connect!C$4:C$1000,">="&DATE(2024,4,1),Connect!C$4:C$1000,"<="&DATE(2024,6+1,0)) -> 0 | L15: =COUNTIFS(Connect!C$4:C$1000,">="&DATE(2024,7,1),Connect!C$4:C$1000,"<="&DATE(2024,9+1,0)) -> 3 | M15: =COUNTIFS(Connect!C$4:C$1000,">="&DATE(2024,10,1),Connect!C$4:C$1000,"<="&DATE(2024,12+1,0)) -> 1 | N15: =COUNTIFS(Connect!C$4:C$1000,">="&DATE(2025,1,1),Connect!C$4:C$1000,"<="&DATE(2025,3+1,0)) -> 2 | O15: =COUNTIFS(Connect!C$4:C$1000,">="&DATE(2025,4,1),Connect!C$4:C$1000,"<="&DATE(2025,6+1,0)) -> 1 | P15: =COUNTIFS(Connect!C$4:C$1000,">="&DATE(2025,7,1),Connect!C$4:C$1000,"<="&DATE(2025,9+1,0)) -> 1 | Q15: =COUNTIFS(Connect!C$4:C$1000,">="&DATE(2025,10,1),Connect!C$4:C$1000,"<="&DATE(2025,12+1,0)) -> 0 | R15: =COUNTIFS(Connect!C$4:C$1000,">="&DATE(2026,1,1),Connect!C$4:C$1000,"<="&DATE(2026,3+1,0)) -> 0 | S15: =COUNTIFS(Connect!C$4:C$1000,">="&DATE(2026,4,1),Connect!C$4:C$1000,"<="&DATE(2026,6+1,0)) -> 0 | T15: =COUNTIFS(Connect!C$4:C$1000,">="&DATE(2026,7,1),Connect!C$4:C$1000,"<="&DATE(2026,9+1,0)) -> 0 | U15: =COUNTIFS(Connect!C$4:C$1000,">="&DATE(2026,10,1),Connect!C$4:C$1000,"<="&DATE(2026,12+1,0)) -> 0
A16: Oneov | B16: =COUNTIFS(Oneov!A$4:A$1000,">="&DATE(2022,1,1),Oneov!A$4:A$1000,"<="&DATE(2022,3+1,0)) -> 0 | C16: =COUNTIFS(Oneov!A$4:A$1000,">="&DATE(2022,4,1),Oneov!A$4:A$1000,"<="&DATE(2022,6+1,0)) -> 0 | D16: =COUNTIFS(Oneov!A$4:A$1000,">="&DATE(2022,7,1),Oneov!A$4:A$1000,"<="&DATE(2022,9+1,0)) -> 0 | E16: =COUNTIFS(Oneov!A$4:A$1000,">="&DATE(2022,10,1),Oneov!A$4:A$1000,"<="&DATE(2022,12+1,0)) -> 0 | F16: =COUNTIFS(Oneov!A$4:A$1000,">="&DATE(2023,1,1),Oneov!A$4:A$1000,"<="&DATE(2023,3+1,0)) -> 0 | G16: =COUNTIFS(Oneov!A$4:A$1000,">="&DATE(2023,4,1),Oneov!A$4:A$1000,"<="&DATE(2023,6+1,0)) -> 0 | H16: =COUNTIFS(Oneov!A$4:A$1000,">="&DATE(2023,7,1),Oneov!A$4:A$1000,"<="&DATE(2023,9+1,0)) -> 0 | I16: =COUNTIFS(Oneov!A$4:A$1000,">="&DATE(2023,10,1),Oneov!A$4:A$1000,"<="&DATE(2023,12+1,0)) -> 0 | J16: =COUNTIFS(Oneov!A$4:A$1000,">="&DATE(2024,1,1),Oneov!A$4:A$1000,"<="&DATE(2024,3+1,0)) -> 7 | K16: =COUNTIFS(Oneov!A$4:A$1000,">="&DATE(2024,4,1),Oneov!A$4:A$1000,"<="&DATE(2024,6+1,0)) -> 0 | L16: =COUNTIFS(Oneov!A$4:A$1000,">="&DATE(2024,7,1),Oneov!A$4:A$1000,"<="&DATE(2024,9+1,0)) -> 0 | M16: =COUNTIFS(Oneov!A$4:A$1000,">="&DATE(2024,10,1),Oneov!A$4:A$1000,"<="&DATE(2024,12+1,0)) -> 0 | N16: =COUNTIFS(Oneov!A$4:A$1000,">="&DATE(2025,1,1),Oneov!A$4:A$1000,"<="&DATE(2025,3+1,0)) -> 0 | O16: =COUNTIFS(Oneov!A$4:A$1000,">="&DATE(2025,4,1),Oneov!A$4:A$1000,"<="&DATE(2025,6+1,0)) -> 0 | P16: =COUNTIFS(Oneov!A$4:A$1000,">="&DATE(2025,7,1),Oneov!A$4:A$1000,"<="&DATE(2025,9+1,0)) -> 0 | Q16: =COUNTIFS(Oneov!A$4:A$1000,">="&DATE(2025,10,1),Oneov!A$4:A$1000,"<="&DATE(2025,12+1,0)) -> 0 | R16: =COUNTIFS(Oneov!A$4:A$1000,">="&DATE(2026,1,1),Oneov!A$4:A$1000,"<="&DATE(2026,3+1,0)) -> 0 | S16: =COUNTIFS(Oneov!A$4:A$1000,">="&DATE(2026,4,1),Oneov!A$4:A$1000,"<="&DATE(2026,6+1,0)) -> 0 | T16: =COUNTIFS(Oneov!A$4:A$1000,">="&DATE(2026,7,1),Oneov!A$4:A$1000,"<="&DATE(2026,9+1,0)) -> 0 | U16: =COUNTIFS(Oneov!A$4:A$1000,">="&DATE(2026,10,1),Oneov!A$4:A$1000,"<="&DATE(2026,12+1,0)) -> 0
A17: TOTAL | B17: =SUM(B13:B16) -> 0 | C17: =SUM(C13:C16) -> 0 | D17: =SUM(D13:D16) -> 1 | E17: =SUM(E13:E16) -> 0 | F17: =SUM(F13:F16) -> 0 | G17: =SUM(G13:G16) -> 4 | H17: =SUM(H13:H16) -> 2 | I17: =SUM(I13:I16) -> 4 | ... U17: =SUM(U13:U16) -> 8
A19: SYNTHÈSE ANNUELLE | B19: 2022 | C19: 2023 | D19: 2024 | E19: 2025 | F19: 2026
A20: Revenus (€) | B20: =SUM(B9:E9) -> 5000 | C20: =SUM(F9:I9) -> 13680 | D20: =SUM(J9:M9) -> 199923.39 | E20: =SUM(N9:Q9) -> 201409 | F20: =SUM(R9:U9) -> 112458
A21: Projets | B21: =SUM(B17:E17) -> 1 | C21: =SUM(F17:I17) -> 10 | D21: =SUM(J17:M17) -> 78 | E21: =SUM(N17:Q17) -> 75 | F21: =SUM(R17:U17) -> 37
A22: Rev. / Projet (€) | B22: =IFERROR(B20/B21,"—") -> 5000 | C22: =IFERROR(C20/C21,"—") -> 1368 | D22: =IFERROR(D20/D21,"—") -> 2563.1204 | E22: =IFERROR(E20/E21,"—") -> 2685.4533 | F22: =IFERROR(F20/F21,"—") -> 3039.4054
A24: Hypothèses
A25: Taux EUR/USD | B25: 1.15

Sheet All
A1: Project | E1: Details | R1: Banner creation (static) | S1: Banner adaptation (static) | T1: Banner creation (animated) | U1: Banner adaptation (animated) | V1: Branding pack | W1: Logo | X1: Lifestyle Picture | Y1: Wallpapers | Z1: Offline creation (standard) | AA1: Offline creation (adaptation) | AB1: Leaflet (1 page) | AC1: Leaflet (2 pages) | AD1: Roll-up / Wall creation | AE1: Chart | AF1: Brochure (20 pages) | AG1: Slide | AH1: Landing page (design only) | AI1: Landing page (complete) | AJ1: Website (design only) | AK1: Website (complete) | AL1: Video Edition | AM1: Video Subtitles | AN1: Social Media Video (up to 30s) | AO1: Social Media Video (up to 1 min) | AP1: Promotional Video (up to 1 min) | AQ1: 2D Video (up to 3mn) | AR1: 3D Video (up to 3min) | AS1: Virtual space | AT1: Virtual showroom | AU1: Translation (per word) | AV1: Copywrite (per word)
A2: Customer | B2: Division | C2: Date | D2: Project | E2: Contact | F2: Status | G2: Category | H2: Link | I2: Assets | J2: Total Value | K2: Quote | L2: PO | M2: Invoice | N2: N° invoice | O2: Status2 | P2: Echéance | Q2: Colonne3 | R2: 135 | S2: 30 | T2: 220 | U2: 50 | V2: 2000 | W2: 250 | X2: 400 | Y2: 85 | Z2: 135 | AA2: 30 | AB2: 180 | AC2: 260 | AD2: 180 | AE2: 400 | AF2: 2200 | AG2: 40 | AH2: 300 | AI2: 700 | AJ2: 5000 | AK2: 7000 | AL2: 80 | AM2: 150 | AN2: 260 | AO2: 560 | AP2: 4000 | AQ2: 5000 | AR2: 10000 | AS2: 2500 | AT2: 10000 | AU2: 0.1 | AV2: 0.25
A3: Son-video.com | B3: - | C3: 44743 | D3: Virtual Showroom | E3: Hugo Lahutte | F3: Delivered | G3: France | H3: - | I3: =IF(SUM(R3:AV3)=0,"-",SUM(R3:AV3)) -> 2 | J3: =IF(SUMPRODUCT($R$2:$AV$2,R3:AV3)=0,"-",SUMPRODUCT($R$2:$AV$2,R3:AV3)) -> 5000 | K3: 45084 | L3: - | M3: Sent | N3: F2023-0523 | O3: Payé le 11/08/2023 | AS3: 2
A4: La Maison des Bienheureux | B4: - | C4: 45083 | D4: New website | E4: Romain Petit | F4: Delivered | G4: France | H4: https://b2b.sarani.studio | I4: 1 | J4: =IF(SUMPRODUCT($R$2:$AV$2,R4:AV4)=0,"-",SUMPRODUCT($R$2:$AV$2,R4:AV4)) -> 4000 | K4: 45084 | L4: - | M4: Sent | N4: F2024-0045 | O4: Payé le 29/05/2024 | AK4: =4000/7000 -> 0.57142857
A5: Pippacorner | B5: - | C5: 45083 | D5: Pippacorner Branding | E5: Stéphane Rambaud | F5: Delivered | G5: France | H5: https://saranistudio.sharepoint.com/:f:/s/SaraniAssets/EnbyF5acw11EjdYGvMP5nx0B0d70LzvZ1gHbTGcqlFjbGA?e=zcD1fD | I5: =IF(SUM(R5:AV5)=0,"-",SUM(R5:AV5)) -> 4.376 | J5: 2000 | K5: 45084 | L5: - | M5: Sent | N5: F2023-0515 | O5: Payé le 28/07/2023 | V5: 1 | AJ5: =1500/AJ2 -> 0.3 | AO5: 2 | AQ5: =5380/AQ2 -> 1.076
A6: Pippacorner | B6: - | C6: 45083 | D6: Pippacorner Website Design | E6: Stéphane Rambaud | F6: Delivered | G6: France | H6: https://saranistudio.sharepoint.com/:f:/s/SaraniAssets/ErmhsGB8kgRAuBYr4yIhwroBiQEACi2aakOTS93vHVWT1A?e=Xu2JTN | I6: 1 | J6: 1800 | L6: - | M6: Sent | N6: F2023-0514 | O6: Payée le 26/09/2023 | V6: 1 | AJ6: =1500/AJ4 -> #DIV/0! | AO6: 2 | AQ6: =5380/AQ4 -> #DIV/0!
A7: Pippacorner | B7: - | C7: 45083 | D7: Pippacorner Catalogue | E7: Stéphane Rambaud | F7: Delivered | G7: France | H7: https://saranistudio.sharepoint.com/:f:/s/SaraniAssets/EmRcIT6D4cxGl8o_DjWi9wcB_aDUY7-whHxFK_E3rlYFFw?e=aG6faZ | I7: 1 | J7: 850 | L7: - | M7: Sent | N7: F2023-0513 | O7: Payée le 26/092023
A8: Pippacorner | B8: - | C8: 45184 | D8: Pippacorner maquettes | E8: Stéphane Rambaud | F8: Delivered | G8: France | H8: https://saranistudio.sharepoint.com/:f:/s/SaraniAssets/ErmhsGB8kgRAuBYr4yIhwroBiQEACi2aakOTS93vHVWT1A?e=Xu2JTN | I8: 10 | J8: 1500 | M8: Sent | N8: F2023-0512 | O8: Payée le 07/11/2032
A9: Pippacorner | B9: - | C9: 45185 | D9: Pippacorner Flyer | E9: Stéphane Rambaud | F9: Delivered | G9: France | H9: https://saranistudio.sharepoint.com/:f:/s/SaraniAssets/EkTN4p5LGHFGhELydt5HB-oB0aFtmnCCp7LOSYR9hymHGw?e=QPJaAL | I9: 1 | J9: 450 | M9: Sent | N9: F2023-0511 | O9: Payée le 07/11/2023
A10: Pernod-Ricard | C10: 45211 | D10: Perrier-Jouet - CP - Menu d'hiver | E10: Laura Marie through Marie Caroline Selmer | F10: Delivered | G10: France | H10: https://saranistudio.sharepoint.com/sites/SaraniAssets/Shared%20Documents/Forms/AllItems.aspx?ga=1&id=%2Fsites%2FSaraniAssets%2FShared%20Documents%2F03%2E%20Customers%2F09%2E%20Pernod%20Ricard%2F01%2E%20Press%20Release&viewid=2c2e4824%2D3cb1%2D4619%2Db7c6%2D219dce795204 | I10: 1 | J10: 40 | M10: Sent | N10: F2024-0038 | O10: Payé
A11: Pippacorner | B11: - | C11: 45214 | D11: Pippacorner Final website assets | E11: Stéphane Rambaud | F11: Delivered | G11: France | H11: https://saranistudio.sharepoint.com/:f:/s/SaraniAssets/ElcfhiK7aLhJhiN2ZjA7EwYB_oX3cVCbpCW7693MDQnjtA?e=wHOvMb | I11: 5 | J11: 250 | M11: Sent | N11: F2023-0236 | O11: Payée le 7/11/2023
A12: Pernod-Ricard | C12: 45274 | D12: Château Sainte Marguerite - CP | E12: Laura Marie through Marie Caroline Selmer | F12: Delivered | G12: France | H12: https://saranistudio.sharepoint.com/sites/SaraniAssets/Shared%20Documents/Forms/AllItems.aspx?ga=1&id=%2Fsites%2FSaraniAssets%2FShared%20Documents%2F03%2E%20Customers%2F09%2E%20Pernod%20Ricard%2F01%2E%20Press%20Release&viewid=2c2e4824%2D3cb1%2D4619%2Db7c6%2D219dce795204 | I12: 1 | J12: 40 | M12: Sent | N12: F2024-0039 | O12: Payé
A13: Pomme de Pin | C13: 45290 | D13: Site web 50% | F13: Delivered | G13: France | H13: https://saranistudio.sharepoint.com/:f:/s/SaraniAssets/EpLFm-Ryfg5LirKpuYZqX6IBW6BRaDZWa7vLEWJstShnIg?e=XkPfBa | I13: =IF(SUM(R13:AV13)=0,"-",SUM(R13:AV13)) -> - | J13: 2750 | M13: Sent | N13: F2024-0029 | O13: Payé le 30/01/2024
A14: PADOC | C14: 45292 | D14: Identité graphique | F14: Delivered | G14: France | H14: https://saranistudio.sharepoint.com/:f:/s/SaraniAssets/EtLDGZ7rZQRCnBF0YE1t2a4B2RhNm2OEYoiy6eidCd4hAw?e=JRicjA | I14: 1 | J14: 600 | K14: - | L14: - | M14: Sent | N14: F2024-0216 | O14: Payé le 17/06/2024
A15: Tour & taxi | C15: 45314 | D15: Création originale – Visuel pour impression | E15: Soraya Nouiyer | F15: Delivered | G15: France | H15: - | I15: =IF(SUM(R15:AV15)=0,"-",SUM(R15:AV15)) -> - | J15: 135 | K15: 23/01/2024 | L15: - | M15: Sent | N15: F2024-0064 | O15: Payé le 05/06/2024
A16: Tour & taxi | C16: 45314 | D16: Création originale – Visuel pour publication | E16: Soraya Nouiyer | F16: Delivered | G16: France | H16: - | I16: =IF(SUM(R16:AV16)=0,"-",SUM(R16:AV16)) -> - | J16: 135 | K16: 23/01/2024 | L16: - | M16: - | N16: - | O16: - | P16: -
A17: Dragon Rouge | C17: 45331 | D17: Vidéo roullier - V2 | E17: Cécile Mercadier | F17: Delivered | G17: France | H17: 20240902_Vidéo roullier-V2 | I17: 1 | J17: =150*5 -> 750 | L17: P022318 | M17: Sent to Thomas | N17: F2024-0508 | O17: Payée le 16/01/2025
A18: Eqiom | C18: 45331 | D18: Création originale – Visuel pour impression | E18: Cédric Lechoux, Marine Savary | F18: Delivered | G18: France | H18: - | I18: =IF(SUM(R18:AV18)=0,"-",SUM(R18:AV18)) -> - | J18: 180 | L18: - | M18: Sent | N18: F2024-0091 | O18: Payée le 26/07/2024
A19: GIE | C19: 45331 | D19: Flyers x 500 units 300g print | E19: Gabrielle Lelievre | F19: Delivered | G19: Belgium | H19: - | I19: 1 | J19: 550 | L19: - | M19: Sent | N19: F2024-0419 | O19: Payé le 05/09/2024
A20: France Chimie | C20: 45343 | D20: Kakémono (Design + Impression) + Vignettes | E20: Aurélia | F20: Delivered | G20: France | H20: - | J20: 490 | K20: - | L20: - | M20: sent | N20: F2024-0214 | O20: Payé le 10/06/2024
A21: Pernod-Ricard | C21: 45400 | D21: Facture 2024-11 (CP n°1 de PJ) | E21: Laura Marie through Marie Caroline Selmer | F21: Delivered | G21: France | H21: - | I21: 1 | J21: 40 | M21: Sent | N21: F2024-0169 | O21: Payé
A22: Pernod-Ricard | C22: 45400 | D22: Facture 2024-20 (CP n°5 de SMEP) | E22: Laura Marie through Marie Caroline Selmer | F22: Delivered | G22: France | H22: - | I22: 1 | J22: 40 | M22: Sent | N22: F2024-0170 | O22: Payé | AG22: 14
A23: Eqiom | C23: 45405 | D23: Livret d'accueil A4 Alternants | E23: Cédric Lechoux, Marine Savary | F23: Delivered | G23: France | H23: https://saranistudio.sharepoint.com/:f:/s/SaraniAssets/Eqwntg4GF4xHs_lcP9At1-0BUwZloYyi4fg05MClpbZ17w?e=DtySqI | I23: =IF(SUM(R23:AV23)=0,"-",SUM(R23:AV23)) -> - | J23: =IF(SUMPRODUCT($R$2:$AV$2,R23:AV23)=0,"-",SUMPRODUCT($R$2:$AV$2,R23:AV23)) -> - | M23: Sent | N23: F2024-0187 | O23: Payée le 10/01/2025
A24: Pernod-Ricard | C24: 45405 | D24: Facture 2024-13 (CP n°4 de SMEP) Perrier-Jouët | E24: Laura Marie through Marie Caroline Selmer | F24: Delivered | G24: France | H24: - | I24: 1 | J24: 40 | M24: Sent | N24: F2024-0195 | O24: Payé le 29/05/2024
A25: Pippacorner | C25: 45405 | D25: Pippacorner website improvements | E25: Stéphane Rambaud | F25: Delivered | G25: France | H25: - | I25: 1 | J25: 500 | M25: Sent | N25: F2024-0186 | O25: Payée le 27/05/2024
A26: SpaceProjects | C26: 45405 | D26: Pack Présentations | E26: Hassib Mounzer | F26: Delivered | G26: France | H26: - | I26: 3 | J26: 1500 | K26: - | L26: - | M26: Sent via Whatsapp | N26: F2024-0679 | O26: Payée le 17/12/2024
A27: SpaceProjects | C27: 45405 | D27: Site Web | E27: Hassib Mounzer | F27: In progress | G27: France | H27: - | I27: 1 | J27: 3000
A28: Air Corsica | C28: 45413 | D28: Influencers campaign | E28: Jean-Paul | F28: Delivered | G28: France | H28: - | J28: 500 | K28: - | L28: - | M28: - | N28: - | O28: - | P28: - | Q28: - | AD28: 9
A29: Eqiom | B29: 45405 | C29: 45415 | D29: Création Panneaux - EQIOM A1 | F29: Delivered | G29: France | H29: 20240509_Création Panneaux - EQIOM | I29: 9 | J29: =220*9 -> 1980 | K29: - | L29: C000150109 | M29: Sent | N29: F2024-0428 | O29: Payée le 25/10/2024
A30: France Chimie | C30: 45415 | D30: Kakémono classique + Tendu (Design + Impression) | E30: Clayton / Juliette | F30: Delivered | G30: France | H30: - | J30: 891 | K30: - | L30: - | M30: sent | N30: F2024-0215 | O30: Payé le 10/06/2024
A31: GIE | C31: 45444 | D31: Service proposal: GIE Munich Conference assets v2 | E31: Gabrielle Lelievre | F31: Delivered | G31: Belgium | H31: - | I31: 15 | J31: 1080 | L31: - | M31: Sent | N31: F2024-0389 | O31: Payée le 04/09/2024
A32: Aventim - Howel | C32: 45453 | D32: AXONOGRAPHIE | E32: Clément Robillard - crobillard@aventim.com | F32: Delivered | G32: France | H32: - | I32: 1 | J32: 950 | K32: - | L32: - | M32: Sent | N32: F2024-0361 | O32: Payée le 16/10/2024
A33: Air Corsica | C33: 45454 | D33: Campagne Italie Belgique | E33: Jean-Franois Colonna | F33: Delivered | G33: France | H33: - | J33: 30500 | L33: CDF00019891 | M33: Sent | N33: F2024-0282 | O33: Payé le 26/07/2024
A34: Pomme de Pin | C34: 45458 | D34: PLAN + MENU + PLANNING JUILLET AOUT + SIGNATURES | E34: Julien Bauchart | F34: Delivered | G34: France | H34: - | J34: 900 | K34: Offrir cette prestation afin de compenser les problèmes de livraison du site web Pomme de Pin. Possible de réaliser une facture de 900€ avec remise de 900€ pour que le client se rende compte du geste commercial effectué? | M34: Sent | N34: F2024-0352 | O34: Facture à 0€, pas de paiement attendu
A35: Pomme de Pin | C35: 45463 | D35: Shooting Photos | E35: Julien Bauchart | F35: Delivered | G35: France | H35: - | J35: 450 | M35: Sent | N35: F2024-0414 | O35: Payée le 04/09/2024
A36: Dialogue | C36: 45477 | D36: Campagne Influence Dialogues 2410067 | E36: Charlotte | F36: Delivered | G36: France | H36: - | I36: 1 | J36: 12500 | L36: 2410067 | M36: Sent | N36: F2024-0636 | O36: Payée le 16/12/2024
A37: Dialogue | C37: 45477 | D37: Campagne Influence Dialogues 2410066 | E37: Charlotte | F37: Delivered | G37: France | H37: - | I37: 1 | J37: 7500 | L37: 2410066 | M37: Sent | N37: F2024-0635 | O37: Payée le 16/12/2024
A38: Pernod-Ricard | C38: 45483 | D38: SMEP corporate (CP6) | E38: Laura Marie through Marie Caroline Selmer | F38: Delivered | G38: France | H38: - | I38: 1 | J38: 40 | M38: Sent | N38: F2024-0327 | O38: Payé le 22/07/2024
A39: Pernod-Ricard | C39: 45483 | D39: PERRIER-JOUET CP 7 - Réouverture Cellier | E39: Laura Marie through Marie Caroline Selmer | F39: Delivered | G39: France | H39: - | I39: 1 | J39: 40 | M39: Sent | N39: F2024-0328 | O39: Payé le 22/07/2024
A40: Quentin Carnaille | C40: 45488 | D40: STATUE - C. DE GAULLE | E40: Quentin Carnaille quentincarnaille@gmail.com | F40: Delivered | G40: France | H40: https://saranistudio.sharepoint.com/sites/SaraniAssets/Shared%20Documents/Forms/AllItems.aspx?ga=1&id=%2Fsites%2FSaraniAssets%2FShared%20Documents%2F03%2E%20Customers%2F01%2E%20Single%20Projects%2FQuentin%20Carnaille&viewid=2c2e4824%2D3cb1%2D4619%2Db7c6%2D219dce795204 | I40: 1 | J40: 3500€ | K40: - | L40: - | M40: Sent | N40: F2024-0489 | O40: Payé 13/11/2024
...

Sheet All projects
A1: Customer | B1: Date | C1: Project | D1: Contact | E1: Status | F1: Category | G1: Link | H1: Assets | I1: Total Value | J1: Quote | K1: PO | L1: Invoice | M1: N° invoice | N1: Status inv. | O1: Echéance | P1: Commentaire | Q1: Banner creation (static) 135 | R1: Banner adaptation (static) 30 | S1: Banner creation (animated) 220 | T1: Banner adaptation (animated) 50 | U1: Branding pack 2000 | V1: Logo 250 | W1: Lifestyle Picture 400 | X1: Wallpapers 85 | Y1: Offline creation (standard) 135 | Z1: Offline creation (adaptation) 30 | AA1: Leaflet (1 page) 180 | AB1: Leaflet (2 pages) 260 | AC1: Roll-up / Wall creation 180 | AD1: Chart 400 | AE1: Brochure (20 pages) 2200 | AF1: Slide 40 | AG1: Landing page (design only) 300 | AH1: Landing page (complete) 700 | AI1: Website (design only) 5000 | AJ1: Website (complete) 7000 | AK1: Video Edition 80 | AL1: Video Subtitles 150 | AM1: Social Media Video (up to 30s) 260 | AN1: Social Media Video (up to 1 min) 560 | AO1: Promotional Video (up to 1 min) 4000 | AP1: 2D Video (up to 3mn) 5000 | AQ1: 3D Video (up to 3min) 10000 | AR1: Virtual space 2500 | AS1: Virtual showroom 10000 | AT1: Translation (per word) 0.1 | AU1: Copywrite (per word) 0.25
A2: Son-video.com | B2: 44743 | C2: Virtual Showroom | D2: Hugo Lahutte | E2: Delivered | F2: France | G2: - | H2: 2 | I2: 5000 | J2: 45084 | K2: - | L2: Sent | M2: F2023-0523 | N2: Payé le 11/08/2023 | AR2: 2
A3: Pippacorner | B3: 45083 | C3: Pippacorner Branding | D3: Stéphane Rambaud | E3: Delivered | F3: France | G3: https://saranistudio.sharepoint.com/:f:/s/SaraniAssets/EnbyF5acw11EjdYGvMP5nx0B0d70LzvZ1gHbTGcqlFjbGA?e=zcD1fD | H3: 4.376 | I3: 2000 | J3: 45084 | K3: - | L3: Sent | M3: F2023-0515 | N3: Payé le 28/07/2023 | U3: 1 | AI3: 0.3 | AN3: 2 | AP3: 1.076
A4: Pippacorner | B4: 45083 | C4: Pippacorner Website Design | D4: Stéphane Rambaud | E4: Delivered | F4: France | G4: https://saranistudio.sharepoint.com/:f:/s/SaraniAssets/ErmhsGB8kgRAuBYr4yIhwroBiQEACi2aakOTS93vHVWT1A?e=Xu2JTN | H4: 1 | I4: 1800 | J4: - | K4: - | L4: Sent | M4: F2023-0514 | N4: Payée le 26/09/2023 | U4: 1 | AI4: #DIV/0! | AN4: 2 | AP4: #DIV/0!
A5: La Maison des Bienheureux | B5: 45083 | C5: New website | D5: Romain Petit | E5: Delivered | F5: France | G5: https://b2b.sarani.studio | H5: 1 | I5: 4000 | J5: 45084 | K5: - | L5: Sent | M5: F2024-0045 | N5: Payé le 29/05/2024 | AJ5: 0.57142857
A6: Pippacorner | B6: 45083 | C6: Pippacorner Catalogue | D6: Stéphane Rambaud | E6: Delivered | F6: France | G6: https://saranistudio.sharepoint.com/:f:/s/SaraniAssets/EmRcIT6D4cxGl8o_DjWi9wcB_aDUY7-whHxFK_E3rlYFFw?e=aG6faZ | H6: 1 | I6: 850 | J6: - | K6: - | L6: Sent | M6: F2023-0513 | N6: Payée le 26/092023
A7: Pippacorner | B7: 45184 | C7: Pippacorner maquettes | D7: Stéphane Rambaud | E7: Delivered | F7: France | G7: https://saranistudio.sharepoint.com/:f:/s/SaraniAssets/ErmhsGB8kgRAuBYr4yIhwroBiQEACi2aakOTS93vHVWT1A?e=Xu2JTN | H7: 10 | I7: 1500 | J7: - | K7: - | L7: Sent | M7: F2023-0512 | N7: Payée le 07/11/2032
A8: Pippacorner | B8: 45185 | C8: Pippacorner Flyer | D8: Stéphane Rambaud | E8: Delivered | F8: France | G8: https://saranistudio.sharepoint.com/:f:/s/SaraniAssets/EkTN4p5LGHFGhELydt5HB-oB0aFtmnCCp7LOSYR9hymHGw?e=QPJaAL | H8: 1 | I8: 450 | J8: - | K8: - | L8: Sent | M8: F2023-0511 | N8: Payée le 07/11/2023
A9: Pernod-Ricard | B9: 45211 | C9: Perrier-Jouet - CP - Menu d'hiver | D9: Laura Marie through Marie Caroline Selmer | E9: Delivered | F9: France | G9: https://saranistudio.sharepoint.com/sites/SaraniAssets/Shared%20Documents/Forms/AllItems.aspx?ga=1&id=%2Fsites%2FSaraniAssets%2FShared%20Documents%2F03%2E%20Customers%2F09%2E%20Pernod%20Ricard%2F01%2E%20Press%20Release&viewid=2c2e4824%2D3cb1%2D4619%2Db7c6%2D219dce795204 | H9: 1 | I9: 40 | J9: - | K9: - | L9: Sent | M9: F2024-0038 | N9: Payé
A10: Pippacorner | B10: 45214 | C10: Pippacorner Final website assets | D10: Stéphane Rambaud | E10: Delivered | F10: France | G10: https://saranistudio.sharepoint.com/:f:/s/SaraniAssets/ElcfhiK7aLhJhiN2ZjA7EwYB_oX3cVCbpCW7693MDQnjtA?e=wHOvMb | H10: 5 | I10: 250 | J10: - | K10: - | L10: Sent | M10: F2023-0236 | N10: Payée le 7/11/2023
A11: Pernod-Ricard | B11: 45274 | C11: Château Sainte Marguerite - CP | D11: Laura Marie through Marie Caroline Selmer | E11: Delivered | F11: France | G11: https://saranistudio.sharepoint.com/sites/SaraniAssets/Shared%20Documents/Forms/AllItems.aspx?ga=1&id=%2Fsites%2FSaraniAssets%2FShared%20Documents%2F03%2E%20Customers%2F09%2E%20Pernod%20Ricard%2F01%2E%20Press%20Release&viewid=2c2e4824%2D3cb1%2D4619%2Db7c6%2D219dce795204 | H11: 1 | I11: 40 | J11: - | K11: - | L11: Sent | M11: F2024-0039 | N11: Payé
A12: Pomme de Pin | B12: 45290 | C12: Site web 50% | E12: Delivered | F12: France | G12: https://saranistudio.sharepoint.com/:f:/s/SaraniAssets/EpLFm-Ryfg5LirKpuYZqX6IBW6BRaDZWa7vLEWJstShnIg?e=XkPfBa | H12: - | I12: 2750 | J12: - | K12: - | L12: Sent | M12: F2024-0029 | N12: Payé le 30/01/2024
A13: PADOC | B13: 45292 | C13: Identité graphique | E13: Delivered | F13: France | G13: https://saranistudio.sharepoint.com/:f:/s/SaraniAssets/EtLDGZ7rZQRCnBF0YE1t2a4B2RhNm2OEYoiy6eidCd4hAw?e=JRicjA | H13: 1 | I13: 600 | J13: - | K13: - | L13: Sent | M13: F2024-0216 | N13: Payé le 17/06/2024
A14: Tour & taxi | B14: 45314 | C14: Création originale – Visuel pour impression | D14: Soraya Nouiyer | E14: Delivered | F14: France | G14: - | H14: - | I14: 135 | J14: 23/01/2024 | K14: - | L14: Sent | M14: F2024-0064 | N14: Payé le 05/06/2024
A15: Tour & taxi | B15: 45314 | C15: Création originale – Visuel pour publication | D15: Soraya Nouiyer | E15: Delivered | F15: France | G15: - | H15: - | I15: 135 | J15: 23/01/2024 | K15: - | L15: - | M15: - | N15: - | O15: -
A16: Dragon Rouge | B16: 45331 | C16: Vidéo roullier - V2 | D16: Cécile Mercadier | E16: Delivered | F16: France | G16: 20240902_Vidéo roullier-V2 | H16: 1 | I16: 750 | J16: - | K16: P022318 | L16: Sent to Thomas | M16: F2024-0508 | N16: Payée le 16/01/2025
A17: Eqiom | B17: 45331 | C17: Création originale – Visuel pour impression | D17: Cédric Lechoux, Marine Savary | E17: Delivered | F17: France | G17: - | H17: - | I17: 180 | J17: - | K17: - | L17: Sent | M17: F2024-0091 | N17: Payée le 26/07/2024
A18: GIE | B18: 45331 | C18: Flyers x 500 units 300g print | D18: Gabrielle Lelievre | E18: Delivered | F18: Belgium | G18: - | H18: 1 | I18: 550 | J18: - | K18: - | L18: Sent | M18: F2024-0419 | N18: Payé le 05/09/2024
A19: France Chimie | B19: 45343 | C19: Kakémono (Design + Impression) + Vignettes | D19: Aurélia | E19: Delivered | F19: France | G19: - | I19: 490 | J19: - | K19: - | L19: sent | M19: F2024-0214 | N19: Payé le 10/06/2024
A20: Pernod-Ricard | B20: 45400 | C20: Facture 2024-11 (CP n°1 de PJ) | D20: Laura Marie through Marie Caroline Selmer | E20: Delivered | F20: France | G20: - | H20: 1 | I20: 40 | J20: - | K20: - | L20: Sent | M20: F2024-0169 | N20: Payé
A21: Pernod-Ricard | B21: 45400 | C21: Facture 2024-20 (CP n°5 de SMEP) | D21: Laura Marie through Marie Caroline Selmer | E21: Delivered | F21: France | G21: - | H21: 1 | I21: 40 | J21: - | K21: - | L21: Sent | M21: F2024-0170 | N21: Payé | AF21: 14
A22: Eqiom | B22: 45405 | C22: Livret d'accueil A4 Alternants | D22: Cédric Lechoux, Marine Savary | E22: Delivered | F22: France | G22: https://saranistudio.sharepoint.com/:f:/s/SaraniAssets/Eqwntg4GF4xHs_lcP9At1-0BUwZloYyi4fg05MClpbZ17w?e=DtySqI | H22: - | I22: - | J22: - | K22: - | L22: Sent | M22: F2024-0187 | N22: Payée le 10/01/2025
A23: Pernod-Ricard | B23: 45405 | C23: Facture 2024-13 (CP n°4 de SMEP) Perrier-Jouët | D23: Laura Marie through Marie Caroline Selmer | E23: Delivered | F23: France | G23: - | H23: 1 | I23: 40 | J23: - | K23: - | L23: Sent | M23: F2024-0195 | N23: Payé le 29/05/2024
A24: Pippacorner | B24: 45405 | C24: Pippacorner website improvements | D24: Stéphane Rambaud | E24: Delivered | F24: France | G24: - | H24: 1 | I24: 500 | J24: - | K24: - | L24: Sent | M24: F2024-0186 | N24: Payée le 27/05/2024
A25: SpaceProjects | B25: 45405 | C25: Pack Présentations | D25: Hassib Mounzer | E25: Delivered | F25: France | G25: - | H25: 3 | I25: 1500 | J25: - | K25: - | L25: Sent via Whatsapp | M25: F2024-0679 | N25: Payée le 17/12/2024
A26: Air Corsica | B26: 45882 | C26: Projet Influence - Vienne et Munich | D26: Mélanie Tolédano | E26: In progress | F26: France | I26: 20000 | J26: - | K26: -
A27: Air Corsica | B27: 45413 | C27: Influencers campaign | D27: Jean-Paul | E27: Delivered | F27: France | G27: - | I27: 500 | J27: - | K27: - | L27: - | M27: - | N27: - | O27: - | P27: - | AC27: 9
A28: Eqiom | B28: 45415 | C28: Création Panneaux - EQIOM A1 | E28: Delivered | F28: France | G28: 20240509_Création Panneaux - EQIOM | H28: 9 | I28: 1980 | J28: - | K28: C000150109 | L28: Sent | M28: F2024-0428 | N28: Payée le 25/10/2024
A29: France Chimie | B29: 45415 | C29: Kakémono classique + Tendu (Design + Impression) | D29: Clayton / Juliette | E29: Delivered | F29: France | G29: - | I29: 891 | J29: - | K29: - | L29: sent | M29: F2024-0215 | N29: Payé le 10/06/2024
A30: GIE | B30: 45444 | C30: Service proposal: GIE Munich Conference assets v2 | D30: Gabrielle Lelievre | E30: Delivered | F30: Belgium | G30: - | H30: 15 | I30: 1080 | J30: - | K30: - | L30: Sent | M30: F2024-0389 | N30: Payée le 04/09/2024
A31: Aventim - Howel | B31: 45453 | C31: AXONOGRAPHIE | D31: Clément Robillard - crobillard@aventim.com | E31: Delivered | F31: France | G31: - | H31: 1 | I31: 950 | J31: - | K31: - | L31: Sent | M31: F2024-0361 | N31: Payée le 16/10/2024
A32: Air Corsica | B32: 45454 | C32: Campagne Italie Belgique | D32: Jean-Franois Colonna | E32: Delivered | F32: France | G32: - | I32: 30500 | J32: - | K32: CDF00019891 | L32: Sent | M32: F2024-0282 | N32: Payé le 26/07/2024
A33: Pomme de Pin | B33: 45458 | C33: PLAN + MENU + PLANNING JUILLET AOUT + SIGNATURES | D33: Julien Bauchart | E33: Delivered | F33: France | G33: - | I33: 900 | J33: - | K33: - | L33: Sent | M33: F2024-0352 | N33: Facture à 0€, pas de paiement attendu | P33: Offrir cette prestation afin de compenser les problèmes de livraison du site web Pomme de Pin. Possible de réaliser une facture de 900€ avec remise de 900€ pour que le client se rende compte du geste commercial effectué?
A34: Pomme de Pin | B34: 45463 | C34: Shooting Photos | D34: Julien Bauchart | E34: Delivered | F34: France | G34: - | I34: 450 | J34: - | K34: - | L34: Sent | M34: F2024-0414 | N34: Payée le 04/09/2024
A35: Dialogue | B35: 45477 | C35: Campagne Influence Dialogues 2410067 | D35: Charlotte | E35: Delivered | F35: France | G35: - | H35: 1 | I35: 12500 | J35: - | K35: 2410067 | L35: Sent | M35: F2024-0636 | N35: Payée le 16/12/2024
A36: Dialogue | B36: 45477 | C36: Campagne Influence Dialogues 2410066 | D36: Charlotte | E36: Delivered | F36: France | G36: - | H36: 1 | I36: 7500 | J36: - | K36: 2410066 | L36: Sent | M36: F2024-0635 | N36: Payée le 16/12/2024
A37: Pernod-Ricard | B37: 45483 | C37: SMEP corporate (CP6) | D37: Laura Marie through Marie Caroline Selmer | E37: Delivered | F37: France | G37: - | H37: 1 | I37: 40 | J37: - | K37: - | L37: Sent | M37: F2024-0327 | N37: Payé le 22/07/2024
A38: Pernod-Ricard | B38: 45483 | C38: PERRIER-JOUET CP 7 - Réouverture Cellier | D38: Laura Marie through Marie Caroline Selmer | E38: Delivered | F38: France | G38: - | H38: 1 | I38: 40 | J38: - | K38: - | L38: Sent | M38: F2024-0328 | N38: Payé le 22/07/2024
A39: Quentin Carnaille | B39: 45488 | C39: STATUE - C. DE GAULLE | D39: Quentin Carnaille quentincarnaille@gmail.com | E39: Delivered | F39: France | G39: https://saranistudio.sharepoint.com/sites/SaraniAssets/Shared%20Documents/Forms/AllItems.aspx?ga=1&id=%2Fsites%2FSaraniAssets%2FShared%20Documents%2F03%2E%20Customers%2F01%2E%20Single%20Projects%2FQuentin%20Carnaille&viewid=2c2e4824%2D3cb1%2D4619%2Db7c6%2D219dce795204 | H39: 1 | I39: 3500€ | J39: - | K39: - | L39: Sent | M39: F2024-0489 | N39: Payé 13/11/2024
A40: Velux | B40: 45498 | C40: DESIRE September burst - assets digitaux | D40: Pamela Ankrah | E40: Delivered | F40: France | G40: https://saranistudio.sharepoint.com/:f:/s/SaraniAssets/EoNIo5JGichNm6_RXrv8dEQBilHwAUZF81WudIE4jMTUlQ?e=h5OWme | H40: 16 | I40: 560 | J40: - | K40: - | L40: Sent | M40: F2024-0362 | N40: Payée le 09/09/2024 | R40: 16
...

Sheet ESPI
A1: Customer | B1: Project | C1: Status | D1: Facturé client | E1: Cost Sébastien | F1: Cost Chloé | G1: Other | H1: Profit | I1: Quote | J1: PO | K1: Invoice | L1: N° invoice | M1: Status
A2: ESPI | B2: Refonte site web | C2: In progress | D2: 34000 | E2: 12000 | F2: 6000 | G2: 8000 | H2: =D2-E2-F2-G2 -> 8000 | I2: Acompte de 20% à facturer .Notre compte client a bien été créé chez le client ESPI. Prestataire Sébastien Gras 12000€HT | J2: - | K2: Acompte 20% sent | L2: F2024-0407 | M2: Payée le 30/09/2024
A3: ESPI | B3: MotionDesign | C3: In progress | D3: 5000 | I3: Pas initié pour le moment
A4: ESPI | B4: Shooting photo / Vidéo | C4: Delivered | D4: 16680 | E4: 15000 | H4: =D4-E4-F4-G4 -> 1680 | I4: Acompte de 20% à facturer.Prestataire: Sébastien Gras (13344€HT, acompte de 3336€HT) | J4: - | K4: Acompte 20% sent | L4: F2024-0408 | M4: Payée le 30/09/2024
A5: ESPI | B5: Site web temporaire | C5: Delivered | D5: 8000 | E5: 4000 | F5: 0 | G5: 0 | H5: =D5-E5-F5-G5 -> 4000 | I5: Acompte de 20% à facturer. Prestataire: Sébastien Gras (4000€HT, acompte de 2000€HT à régler) | J5: BdC5411 | K5: Envoyée 03/09/2024 | L5: F2024-0406 | M5: Payée le 30/09/2024
A6: ESPI | B6: Traduction web | C6: Delivered | D6: 1600 | E6: 700 | F6: 0 | G6: 310 | H6: =D6-E6-F6-G6 -> 590 | I6: 700€ à régler au prestataire Sébastien Gras. Facture à recevoir. | J6: - | K6: Envoyée le 11/12/2024 | L6: F2024-0681 | M6: Payée le 31/01/2025
A7: ESPI | B7: Maintenance
A8: ESPI | B8: Tracking
A9: ESPI | B9: TOTAL | D9: =SUM(D2:D6) -> 65280 | E9: =SUM(E2:E6) -> 31700 | F9: =SUM(F2:F6) -> 6000 | G9: =SUM(G2:G6) -> 8310 | H9: =SUM(H2:H6) -> 14270

Sheet Oneov
R1: Online | Z1: Offline | AG1: Presentations | AH1: Web | AL1: Videos | AS1: Virtualization | AU1: Copy
C2: Details : Maxime mailto:Samcommerce.r360@gmail.com | R2: Banner creation (static) | S2: Banner adaptation (static) | T2: Banner creation (animated) | U2: Banner adaptation (animated) | V2: Branding pack | W2: Logo | X2: Lifestyle Picture | Y2: Wallpapers | Z2: Offline creation (standard) | AA2: Offline creation (adaptation) | AB2: Leaflet (1 page) | AC2: Leaflet (2 pages) | AD2: Roll-up / Wall creation | AE2: Chart | AF2: Brochure (20 pages) | AG2: Slide | AH2: Landing page (design only) | AI2: Landing page (complete) | AJ2: Website (design only) | AK2: Website (complete) | AL2: Video Edition | AM2: Video Subtitles | AN2: Social Media Video (up to 30s) | AO2: Social Media Video (up to 1 min) | AP2: Promotional Video (up to 1 min) | AQ2: 2D Video (up to 3mn) | AR2: 3D Video (up to 3min) | AS2: Virtual space | AT2: Virtual showroom | AU2: Translation (per word) | AV2: Copywrite (per word)
A3: Date | B3: Project | C3: Contact | D3: Status | E3: Category | F3: Link | G3: Assets | H3: Total Value | I3: Quote | J3: PO | K3: Invoice | L3: N° invoice | M3: Status | N3: Echéance | P3: Jours de retards | Q3: Commentaire | R3: 135 | S3: 35 | T3: 220 | U3: 50 | V3: 2000 | W3: 250 | X3: 400 | Y3: 85 | Z3: 135 | AA3: 40 | AB3: 180 | AC3: 260 | AD3: 180 | AE3: 400 | AF3: 2200 | AG3: 30 | AH3: 300 | AI3: 700 | AJ3: 5000 | AK3: 7000 | AL3: 80 | AM3: 150 | AN3: 260 | AO3: 560 | AP3: 4000 | AQ3: 5000 | AR3: 10000 | AS3: 2500 | AT3: 10000 | AU3: 0.1 | AV3: 0.25
A4: - | B4: Identification de la marque | C4: Sam | D4: Delivered | E4: France | F4: - | G4: 1 | H4: 500 | I4: - | J4: - | K4: Sent | L4: F2024-0171 | M4: Waiting for payment | N4: 45435 | O4: =TODAY() -> 46106 | P4: =_xlfn.DAYS(O4,N4) -> 671 | Q4: 27/02: Procédure d'injonction de payer lancée
A5: - | B5: Création d'un logo et des déclinisations | C5: Sam | D5: Delivered | E5: France | F5: - | G5: 1 | H5: 500 | I5: - | J5: - | K5: Sent | L5: F2024-0171 | M5: Waiting for payment | N5: 45435 | O5: =TODAY() -> 46106 | P5: =_xlfn.DAYS(O5,N5) -> 671 | Q5: 27/02: Procédure d'injonction de payer lancée
A6: - | B6: Création d'une charte graphique | C6: Sam | D6: Delivered | E6: France | F6: - | G6: 1 | H6: 1000 | I6: - | J6: - | K6: Sent | L6: F2024-0171 | M6: Waiting for payment | N6: 45435 | O6: =TODAY() -> 46106 | P6: =_xlfn.DAYS(O6,N6) -> 671 | Q6: 27/02: Procédure d'injonction de payer lancée
A7: - | B7: Dépôt de la marque par un avocat en PI auprès de l'INPI | C7: Sam | D7: Delivered | E7: France | F7: - | G7: 1 | H7: 2000 | I7: - | J7: - | K7: Sent | L7: F2024-0171 | M7: Waiting for payment | N7: 45435 | O7: =TODAY() -> 46106 | P7: =_xlfn.DAYS(O7,N7) -> 671 | Q7: 27/02: Procédure d'injonction de payer lancée
A8: - | B8: Facture Print BPRIVES PARIS LAFAYETTE | C8: Sam | D8: Delivered | E8: France | F8: - | G8: 1 | H8: 750 | I8: - | J8: - | K8: Sent | L8: F2024-0172 | M8: Waiting for payment | N8: 45435 | O8: =TODAY() -> 46106 | P8: =_xlfn.DAYS(O8,N8) -> 671 | Q8: 27/02: Procédure d'injonction de payer lancée
A9: - | B9: Création de 3 Visuels pour print extérieur - Les Lillas | C9: Sam | D9: Delivered | E9: France | F9: - | G9: =IF(SUM(R9:AV9)=0,"-",SUM(R9:AV9)) -> 3 | H9: =IF(SUMPRODUCT($R$3:$AV$3,R9:AV9)=0,"-",SUMPRODUCT($R$3:$AV$3,R9:AV9)) -> 120 | I9: - | J9: - | K9: Sent | L9: F2024-0498 | M9: Waiting for payment | N9: 45602 | O9: =TODAY() -> 46106 | P9: =_xlfn.DAYS(O9,N9) -> 504 | Q9: 27/02: Procédure d'injonction de payer lancée | AA9: 3
A10: - | B10: Merchandising - Les Lillas | C10: Sam | D10: Delivered | E10: France | G10: 2900 | H10: 2900 | I10: - | J10: - | K10: Sent | L10: F2024-0499 | M10: Waiting for payment | N10: 45602 | O10: =TODAY() -> 46106 | P10: =_xlfn.DAYS(O10,N10) -> 504 | Q10: 27/02: Procédure d'injonction de payer lancée
A11: - | B11: Création d'un site web vitrine avec Optimisation SEO | C11: Sam | D11: Waiting for first payment to start | F11: - | G11: 1 | H11: 6000 | Q11: Jamais facturé
A12: - | B12: Configuration initiale des réseaux Sociaux | C12: Sam | D12: Waiting for first payment to start | F12: - | G12: 1 | H12: 500 | Q12: Jamais facturé
A13: 45355 | B13: Accompagnement Social Media / Shooting Photos Vidéos / Landing Page / SEO | C13: Lailla | E13: France | F13: - | H13: 8200 | I13: - | J13: -
B14: Facture solde | H14: 7380 | L14: F2024-0644
B15: 10% acompte | H15: 820 | L15: F2024-0255
A16: 45355 | B16: Accompagnement Instagram sur 2 mois + création d'un pack de 15 visuels | C16: Lailla | D16: Delivered | E16: France | F16: - | G16: - | H16: 2500 | J16: - | L16: F2024-0497 | M16: En attente de paiement | N16: 45602 | O16: =_xlfn.DAYS(N16,M16) -> #VALUE!
A17: 45355 | B17: Shooting photos + interviews videos présentant le concept | C17: Lailla | D17: In progress | E17: France | F17: - | G17: - | H17: 1700 | J17: - | L17: F2024-0497 | M17: En attente de paiement | N17: 45602 | O17: =_xlfn.DAYS(N17,M17) -> #VALUE!
A18: 45355 | B18: Création d'une marque et de sa charte | C18: Lailla | D18: Delivered | E18: France | F18: - | G18: - | H18: 750 | J18: - | L18: F2024-0497 | M18: En attente de paiement | N18: 45602 | O18: =_xlfn.DAYS(N18,M18) -> #VALUE!
A19: 45355 | B19: Création d'une landing page | C19: Lailla | D19: In progress | E19: France | F19: - | G19: -
A20: 45355 | B20: Optimisation SEO de la landing page | C20: Lailla | D20: In progress | E20: France | F20: - | G20: -
A21: 45355 | B21: Optimisation SEA (publicité payante) | C21: Lailla | D21: In progress | E21: France | F21: - | G21: -

Sheet Connect
A1: Price File | C1: Last update project | D1: ? | J1: LAST UPDATE FINANCE | L1: 45489 | P1: Online | X1: Offline | AE1: Presentations | AF1: Web | AJ1: Videos | AQ1: Virtualization | AS1: Copy
A2: Project | E2: We invoice : Connect Communication Advertising LLC (Bassel Kassas) 3 invoices | P2: Banner creation (static) | Q2: Banner adaptation (static) | R2: Banner creation (animated) | S2: Banner adaptation (animated) | T2: Branding pack | U2: Logo | V2: Lifestyle Picture | W2: Wallpapers | X2: Offline creation (standard) | Y2: Offline creation (adaptation) | Z2: Leaflet (1 page) | AA2: Leaflet (2 pages) | AB2: Roll-up / Wall creation | AC2: Chart | AD2: Brochure (20 pages) | AE2: Slide | AF2: Landing page (design only) | AG2: Landing page (complete) | AH2: Website (design only) | AI2: Website (complete) | AJ2: Video Edition | AK2: Video Subtitles | AL2: Social Media Video (up to 30s) | AM2: Social Media Video (up to 1 min) | AN2: Promotional Video (up to 1 min) | AO2: 2D Video (up to 3mn) | AP2: 3D Video (up to 3min) | AQ2: Virtual space | AR2: Virtual showroom | AS2: Translation (per word) | AT2: Copywrite (per word)
A3: Customer | B3: Division | C3: Date | D3: Project | E3: Contact | F3: Status | G3: Category | H3: Link | I3: Assets | J3: Total Value | K3: Quote | L3: PO | M3: Invoice | N3: N° invoice | O3: Status | P3: 135 | Q3: 30 | R3: 220 | S3: 50 | T3: 2000 | U3: 250 | V3: 400 | W3: 85 | X3: 135 | Y3: 30 | Z3: 180 | AA3: 260 | AB3: 180 | AC3: 400 | AD3: 2200 | AE3: 40 | AF3: 300 | AG3: 700 | AH3: 5000 | AI3: 7000 | AJ3: 80 | AK3: 150 | AL3: 260 | AM3: 560 | AN3: 4000 | AO3: 5000 | AP3: 10000 | AQ3: 2500 | AR3: 10000 | AS3: 0.1 | AT3: 0.25
A4: Connect | C4: 45536 | D4: CPC Branding Deck | E4: Bassel Kassas | F4: Delivered | G4: CPC | I4: 1 | J4: 1500 | K4: - | L4: - | M4: Sent | N4: F2024-0433 | O4: Paid 16/10/2024
A5: Connect | C5: 45536 | D5: IBD Profile deck | E5: Bassel Kassas | F5: Delivered | G5: CPC | H5: https://saranistudio.sharepoint.com/:f:/s/SaraniAssets/EpyzWx2RoxlDk2mb6W9Ul8MBg1Ms8d2tY2OQ8wXNLUA4ZA?e=3jQi7b | I5: 1 | J5: 1500 | K5: - | L5: - | M5: Sent | N5: F2024-0434 | O5: Paid 16/10/2024
A6: Connect | C6: 45545 | D6: IBU - Pre-Qualification Brochure | E6: Bassel Kassas | F6: Delivered | G6: CPC | H6: https://saranistudio.sharepoint.com/:f:/s/SaraniAssets/ErjOFrbH7FVHjPw1NvubUJgBfYN8x0t0vXyReRCLIlouZA?e=tNdaWa | I6: 1 | J6: 1500 | K6: - | L6: - | M6: Sent | N6: F2024-0435 | O6: Paid 16/10/2024
A7: Connect | C7: 45567 | D7: UCC Profile deck | E7: Bassel Kassas | F7: Delivered | G7: CPC | H7: 20241002_UCC Profile deck | I7: 1 | J7: 1500 | K7: - | L7: - | M7: Sent | N7: F2024-0568 | O7: Paid 09/03/2025
A8: Connect | C8: 45667 | D8: Transimed Brand Identity | E8: Bassel Kassas | F8: Delivered | G8: Transimed | I8: 1 | J8: 850 | K8: - | L8: - | M8: Sent via Whatsapp | N8: F2025-0029 | O8: Paid 28/02/2025
A9: Connect | C9: 45667 | D9: Waw packaging | E9: Wissam | F9: Delivered | G9: Waw | J9: OFFERED | K9: - | L9: - | M9: - | N9: - | O9: - | Z9: 3
A10: Connect | C10: 45818 | D10: The Body Shop Packaging | E10: Bassel Kassas | F10: Delivered | G10: TBS | I10: 3 | J10: 550 | K10: - | L10: - | M10: Sent via Whatsapp | N10: F2025-0386 | O10: Paid 10/11/2025
A11: Connect | C11: 45852 | D11: The Body Shop - 3 New Range | E11: Bassel Kassas | F11: Delivered | G11: TBS | H11: https://saranistudio.sharepoint.com/:f:/s/SaraniAssets/EuHNcWVhPKFImvd2XDHEUtwBtNbHSJEFRnTZoXyuk68DKw?e=gwaCz7 | I11: 3 | J11: =1250*I11*50% -> 1875 | K11: - | L11: - | M11: Sent via Whatsapp | N11: F2025-0628 | O11: Paid 10/11/2025

Sheet ProcessOut
A1: Price File | C1: Last update project | D1: ? | J1: LAST UPDATE FINANCE | L1: 45467 | S1: Online | AA1: Offline | AH1: Presentations | AI1: Web | AM1: Videos | AT1: Virtualization | AV1: Copy
A2: Project | E2: Details #POFR019659 | S2: Banner creation (static) | T2: Banner adaptation (static) | U2: Banner creation (animated) | V2: Banner adaptation (animated) | W2: Branding pack | X2: Logo | Y2: Lifestyle Picture | Z2: Wallpapers | AA2: Offline creation (standard) | AB2: Offline creation (adaptation) | AC2: Leaflet (1 page) | AD2: Leaflet (2 pages) | AE2: Roll-up / Wall creation | AF2: Chart | AG2: Brochure (20 pages) | AH2: Slide | AI2: Landing page (design only) | AJ2: Landing page (complete) | AK2: Website (design only) | AL2: Website (complete) | AM2: Video Edition | AN2: Video Subtitles | AO2: Social Media Video (up to 30s) | AP2: Social Media Video (up to 1 min) | AQ2: Promotional Video (up to 1 min) | AR2: 2D Video (up to 3mn) | AS2: 3D Video (up to 3min) | AT2: Virtual space | AU2: Virtual showroom | AV2: Translation (per word) | AW2: Copywrite (per word)
A3: Customer | B3: Division | C3: Date | D3: Project | E3: Contact | F3: Status | G3: Category | H3: Link | I3: Assets | J3: Total Value | K3: Quote | L3: PO | M3: Invoice | N3: N° invoice | O3: Status | P3: Echéance | S3: 135 | T3: 30 | U3: 220 | V3: 50 | W3: 2000 | X3: 250 | Y3: 400 | Z3: 85 | AA3: 135 | AB3: 30 | AC3: 180 | AD3: 260 | AE3: 180 | AF3: 400 | AG3: 2200 | AH3: 40 | AI3: 300 | AJ3: 700 | AK3: 5000 | AL3: 7000 | AM3: 80 | AN3: 150 | AO3: 260 | AP3: 560 | AQ3: 4000 | AR3: 5000 | AS3: 10000 | AT3: 2500 | AU3: 10000 | AV3: 0.1 | AW3: 0.25
A4: ProcessOut | C4: 45463 | D4: ProcessOut Kakemono 1 | E4: Alizé Amrani | F4: Delivered | G4: France | H4: https://saranistudio.sharepoint.com/:f:/s/SaraniAssets/EiEq_tcCAl5KpCw6Csa44nIBnD3l21MpG9vmZPK0gR_UoA?e=nwN5Xt | I4: 1 | J4: 250 | M4: Sent | N4: F2024-0375 | O4: Payé | P4: 45561 | Q4: =TODAY() -> 46106
A5: ProcessOut | C5: 45463 | D5: ProcessOut Kakemono 2 | E5: Alizé Amrani | F5: Delivered | G5: France | H5: https://saranistudio.sharepoint.com/:f:/s/SaraniAssets/EiEq_tcCAl5KpCw6Csa44nIBnD3l21MpG9vmZPK0gR_UoA?e=nwN5Xt | I5: 1 | J5: 250 | M5: Sent | N5: F2024-0409 | O5: Payé | P5: 45568 | Q5: =TODAY() -> 46106
A6: ProcessOut | C6: 45504 | D6: July LinkedIn Management | E6: Alizé Amrani | F6: Delivered | G6: France | I6: 1 | J6: 1800 | M6: Sent | N6: F2024-0410 | O6: Payé | P6: 45568 | Q6: =TODAY() -> 46106
A7: ProcessOut | C7: 45535 | D7: August LinkedIn Management | E7: Alizé Amrani | F7: Delivered | G7: France | I7: 1 | J7: 1800 | M7: Sent | N7: F2024-0411 | O7: Payé | P7: 45568 | Q7: =TODAY() -> 46106
A8: ProcessOut | C8: 45463 | D8: ProcessOut Brochure (thank you card) | E8: Alizé Amrani | F8: Delivered | G8: France | H8: 20240820_ProcessOut Thank You Card Design - 4 pages | I8: 1 | J8: 400 | M8: Sent | N8: F2024-0412 | O8: Payé | P8: 45568 | Q8: =TODAY() -> 46106
A9: ProcessOut | C9: 45565 | D9: September LinkedIn Management | E9: Alizé Amrani | F9: Delivered | G9: France | I9: 1 | J9: FREE | K9: - | L9: - | M9: - | N9: - | O9: - | P9: - | Q9: -
A10: ProcessOut | C10: 45597 | D10: October LinkedIn Management | E10: Alizé Amrani | F10: Delivered | G10: France | H10: 20240927_ProcessOut - Linkedin Testimonial Graphic - Ankama | I10: 1 | J10: 1800 | M10: Sent | N10: F2024-0566 | O10: Payé | P10: 45639 | Q10: =TODAY() -> 46106
