Workbook

Sheet Overview
A1: Performance Dashboard — Sarani — Aristocrat
A3: REVENUS (€) | B3: 2022 | F3: 2023 | J3: 2024 | N3: 2025 | R3: 2026
B4: Q1 | C4: Q2 | D4: Q3 | E4: Q4 | F4: Q1 | G4: Q2 | H4: Q3 | I4: Q4 | J4: Q1 | K4: Q2 | L4: Q3 | M4: Q4 | N4: Q1 | O4: Q2 | P4: Q3 | Q4: Q4 | R4: Q1 | S4: Q2 | T4: Q3 | U4: Q4
A5: Aristocrat (US-EMEA) | B5: =SUMIFS('Aristocrat (US-EMEA)'!J$6:J$500,'Aristocrat (US-EMEA)'!C$6:C$500,">="&DATE(2022,1,1),'Aristocrat (US-EMEA)'!C$6:C$500,"<="&DATE(2022,3+1,1)-1) -> 0 | C5: =SUMIFS('Aristocrat (US-EMEA)'!J$6:J$500,'Aristocrat (US-EMEA)'!C$6:C$500,">="&DATE(2022,4,1),'Aristocrat (US-EMEA)'!C$6:C$500,"<="&DATE(2022,6+1,1)-1) -> 0 | D5: =SUMIFS('Aristocrat (US-EMEA)'!J$6:J$500,'Aristocrat (US-EMEA)'!C$6:C$500,">="&DATE(2022,7,1),'Aristocrat (US-EMEA)'!C$6:C$500,"<="&DATE(2022,9+1,1)-1) -> 0 | E5: =SUMIFS('Aristocrat (US-EMEA)'!J$6:J$500,'Aristocrat (US-EMEA)'!C$6:C$500,">="&DATE(2022,10,1),'Aristocrat (US-EMEA)'!C$6:C$500,"<="&DATE(2022,12+1,1)-1) -> 0 | F5: =SUMIFS('Aristocrat (US-EMEA)'!J$6:J$500,'Aristocrat (US-EMEA)'!C$6:C$500,">="&DATE(2023,1,1),'Aristocrat (US-EMEA)'!C$6:C$500,"<="&DATE(2023,3+1,1)-1) -> 0 | G5: =SUMIFS('Aristocrat (US-EMEA)'!J$6:J$500,'Aristocrat (US-EMEA)'!C$6:C$500,">="&DATE(2023,4,1),'Aristocrat (US-EMEA)'!C$6:C$500,"<="&DATE(2023,6+1,1)-1) -> 0 | H5: =SUMIFS('Aristocrat (US-EMEA)'!J$6:J$500,'Aristocrat (US-EMEA)'!C$6:C$500,">="&DATE(2023,7,1),'Aristocrat (US-EMEA)'!C$6:C$500,"<="&DATE(2023,9+1,1)-1) -> 0 | I5: =SUMIFS('Aristocrat (US-EMEA)'!J$6:J$500,'Aristocrat (US-EMEA)'!C$6:C$500,">="&DATE(2023,10,1),'Aristocrat (US-EMEA)'!C$6:C$500,"<="&DATE(2023,12+1,1)-1) -> 0 | J5: =SUMIFS('Aristocrat (US-EMEA)'!J$6:J$500,'Aristocrat (US-EMEA)'!C$6:C$500,">="&DATE(2024,1,1),'Aristocrat (US-EMEA)'!C$6:C$500,"<="&DATE(2024,3+1,1)-1) -> 244.88 | K5: =SUMIFS('Aristocrat (US-EMEA)'!J$6:J$500,'Aristocrat (US-EMEA)'!C$6:C$500,">="&DATE(2024,4,1),'Aristocrat (US-EMEA)'!C$6:C$500,"<="&DATE(2024,6+1,1)-1) -> 5558.1 | L5: =SUMIFS('Aristocrat (US-EMEA)'!J$6:J$500,'Aristocrat (US-EMEA)'!C$6:C$500,">="&DATE(2024,7,1),'Aristocrat (US-EMEA)'!C$6:C$500,"<="&DATE(2024,9+1,1)-1) -> 2740.32 | M5: =SUMIFS('Aristocrat (US-EMEA)'!J$6:J$500,'Aristocrat (US-EMEA)'!C$6:C$500,">="&DATE(2024,10,1),'Aristocrat (US-EMEA)'!C$6:C$500,"<="&DATE(2024,12+1,1)-1) -> 4504.52 | N5: =SUMIFS('Aristocrat (US-EMEA)'!J$6:J$500,'Aristocrat (US-EMEA)'!C$6:C$500,">="&DATE(2025,1,1),'Aristocrat (US-EMEA)'!C$6:C$500,"<="&DATE(2025,3+1,1)-1) -> 7910.4 | O5: =SUMIFS('Aristocrat (US-EMEA)'!J$6:J$500,'Aristocrat (US-EMEA)'!C$6:C$500,">="&DATE(2025,4,1),'Aristocrat (US-EMEA)'!C$6:C$500,"<="&DATE(2025,6+1,1)-1) -> 4827.5 | P5: =SUMIFS('Aristocrat (US-EMEA)'!J$6:J$500,'Aristocrat (US-EMEA)'!C$6:C$500,">="&DATE(2025,7,1),'Aristocrat (US-EMEA)'!C$6:C$500,"<="&DATE(2025,9+1,1)-1) -> 91323.6 | Q5: =SUMIFS('Aristocrat (US-EMEA)'!J$6:J$500,'Aristocrat (US-EMEA)'!C$6:C$500,">="&DATE(2025,10,1),'Aristocrat (US-EMEA)'!C$6:C$500,"<="&DATE(2025,12+1,1)-1) -> 31029.84 | R5: =SUMIFS('Aristocrat (US-EMEA)'!J$6:J$500,'Aristocrat (US-EMEA)'!C$6:C$500,">="&DATE(2026,1,1),'Aristocrat (US-EMEA)'!C$6:C$500,"<="&DATE(2026,3+1,1)-1) -> 13652.28 | S5: =SUMIFS('Aristocrat (US-EMEA)'!J$6:J$500,'Aristocrat (US-EMEA)'!C$6:C$500,">="&DATE(2026,4,1),'Aristocrat (US-EMEA)'!C$6:C$500,"<="&DATE(2026,6+1,1)-1) -> 0 | T5: =SUMIFS('Aristocrat (US-EMEA)'!J$6:J$500,'Aristocrat (US-EMEA)'!C$6:C$500,">="&DATE(2026,7,1),'Aristocrat (US-EMEA)'!C$6:C$500,"<="&DATE(2026,9+1,1)-1) -> 0 | U5: =SUMIFS('Aristocrat (US-EMEA)'!J$6:J$500,'Aristocrat (US-EMEA)'!C$6:C$500,">="&DATE(2026,10,1),'Aristocrat (US-EMEA)'!C$6:C$500,"<="&DATE(2026,12+1,1)-1) -> 0
A6: Aristocrat (Asia) — conv. € | B6: =SUMIFS('Aristocrat (Asia)'!J$6:J$500,'Aristocrat (Asia)'!C$6:C$500,">="&DATE(2022,1,1),'Aristocrat (Asia)'!C$6:C$500,"<="&DATE(2022,3+1,1)-1)/$B$20 -> 0 | C6: =SUMIFS('Aristocrat (Asia)'!J$6:J$500,'Aristocrat (Asia)'!C$6:C$500,">="&DATE(2022,4,1),'Aristocrat (Asia)'!C$6:C$500,"<="&DATE(2022,6+1,1)-1)/$B$20 -> 0 | D6: =SUMIFS('Aristocrat (Asia)'!J$6:J$500,'Aristocrat (Asia)'!C$6:C$500,">="&DATE(2022,7,1),'Aristocrat (Asia)'!C$6:C$500,"<="&DATE(2022,9+1,1)-1)/$B$20 -> 0 | E6: =SUMIFS('Aristocrat (Asia)'!J$6:J$500,'Aristocrat (Asia)'!C$6:C$500,">="&DATE(2022,10,1),'Aristocrat (Asia)'!C$6:C$500,"<="&DATE(2022,12+1,1)-1)/$B$20 -> 0 | F6: =SUMIFS('Aristocrat (Asia)'!J$6:J$500,'Aristocrat (Asia)'!C$6:C$500,">="&DATE(2023,1,1),'Aristocrat (Asia)'!C$6:C$500,"<="&DATE(2023,3+1,1)-1)/$B$20 -> 0 | G6: =SUMIFS('Aristocrat (Asia)'!J$6:J$500,'Aristocrat (Asia)'!C$6:C$500,">="&DATE(2023,4,1),'Aristocrat (Asia)'!C$6:C$500,"<="&DATE(2023,6+1,1)-1)/$B$20 -> 0 | H6: =SUMIFS('Aristocrat (Asia)'!J$6:J$500,'Aristocrat (Asia)'!C$6:C$500,">="&DATE(2023,7,1),'Aristocrat (Asia)'!C$6:C$500,"<="&DATE(2023,9+1,1)-1)/$B$20 -> 0 | I6: =SUMIFS('Aristocrat (Asia)'!J$6:J$500,'Aristocrat (Asia)'!C$6:C$500,">="&DATE(2023,10,1),'Aristocrat (Asia)'!C$6:C$500,"<="&DATE(2023,12+1,1)-1)/$B$20 -> 0 | J6: =SUMIFS('Aristocrat (Asia)'!J$6:J$500,'Aristocrat (Asia)'!C$6:C$500,">="&DATE(2024,1,1),'Aristocrat (Asia)'!C$6:C$500,"<="&DATE(2024,3+1,1)-1)/$B$20 -> 0 | K6: =SUMIFS('Aristocrat (Asia)'!J$6:J$500,'Aristocrat (Asia)'!C$6:C$500,">="&DATE(2024,4,1),'Aristocrat (Asia)'!C$6:C$500,"<="&DATE(2024,6+1,1)-1)/$B$20 -> 0 | L6: =SUMIFS('Aristocrat (Asia)'!J$6:J$500,'Aristocrat (Asia)'!C$6:C$500,">="&DATE(2024,7,1),'Aristocrat (Asia)'!C$6:C$500,"<="&DATE(2024,9+1,1)-1)/$B$20 -> 0 | M6: =SUMIFS('Aristocrat (Asia)'!J$6:J$500,'Aristocrat (Asia)'!C$6:C$500,">="&DATE(2024,10,1),'Aristocrat (Asia)'!C$6:C$500,"<="&DATE(2024,12+1,1)-1)/$B$20 -> 0 | N6: =SUMIFS('Aristocrat (Asia)'!J$6:J$500,'Aristocrat (Asia)'!C$6:C$500,">="&DATE(2025,1,1),'Aristocrat (Asia)'!C$6:C$500,"<="&DATE(2025,3+1,1)-1)/$B$20 -> 0 | O6: =SUMIFS('Aristocrat (Asia)'!J$6:J$500,'Aristocrat (Asia)'!C$6:C$500,">="&DATE(2025,4,1),'Aristocrat (Asia)'!C$6:C$500,"<="&DATE(2025,6+1,1)-1)/$B$20 -> 0 | P6: =SUMIFS('Aristocrat (Asia)'!J$6:J$500,'Aristocrat (Asia)'!C$6:C$500,">="&DATE(2025,7,1),'Aristocrat (Asia)'!C$6:C$500,"<="&DATE(2025,9+1,1)-1)/$B$20 -> 0 | Q6: =SUMIFS('Aristocrat (Asia)'!J$6:J$500,'Aristocrat (Asia)'!C$6:C$500,">="&DATE(2025,10,1),'Aristocrat (Asia)'!C$6:C$500,"<="&DATE(2025,12+1,1)-1)/$B$20 -> 1408.6957 | R6: =SUMIFS('Aristocrat (Asia)'!J$6:J$500,'Aristocrat (Asia)'!C$6:C$500,">="&DATE(2026,1,1),'Aristocrat (Asia)'!C$6:C$500,"<="&DATE(2026,3+1,1)-1)/$B$20 -> 8986.9565 | S6: =SUMIFS('Aristocrat (Asia)'!J$6:J$500,'Aristocrat (Asia)'!C$6:C$500,">="&DATE(2026,4,1),'Aristocrat (Asia)'!C$6:C$500,"<="&DATE(2026,6+1,1)-1)/$B$20 -> 0 | T6: =SUMIFS('Aristocrat (Asia)'!J$6:J$500,'Aristocrat (Asia)'!C$6:C$500,">="&DATE(2026,7,1),'Aristocrat (Asia)'!C$6:C$500,"<="&DATE(2026,9+1,1)-1)/$B$20 -> 0 | U6: =SUMIFS('Aristocrat (Asia)'!J$6:J$500,'Aristocrat (Asia)'!C$6:C$500,">="&DATE(2026,10,1),'Aristocrat (Asia)'!C$6:C$500,"<="&DATE(2026,12+1,1)-1)/$B$20 -> 0
A7: TOTAL | B7: =SUM(B5:B6) -> 0 | C7: =SUM(C5:C6) -> 0 | D7: =SUM(D5:D6) -> 0 | E7: =SUM(E5:E6) -> 0 | F7: =SUM(F5:F6) -> 0 | G7: =SUM(G5:G6) -> 0 | H7: =SUM(H5:H6) -> 0 | I7: =SUM(I5:I6) -> 0 | ... U7: =SUM(U5:U6) -> 0
A9: NOMBRE DE PROJETS | B9: 2022 | F9: 2023 | J9: 2024 | N9: 2025 | R9: 2026
B10: Q1 | C10: Q2 | D10: Q3 | E10: Q4 | F10: Q1 | G10: Q2 | H10: Q3 | I10: Q4 | J10: Q1 | K10: Q2 | L10: Q3 | M10: Q4 | N10: Q1 | O10: Q2 | P10: Q3 | Q10: Q4 | R10: Q1 | S10: Q2 | T10: Q3 | U10: Q4
A11: Aristocrat (US-EMEA) | B11: =COUNTIFS('Aristocrat (US-EMEA)'!C$6:C$500,">="&DATE(2022,1,1),'Aristocrat (US-EMEA)'!C$6:C$500,"<="&DATE(2022,3+1,1)-1) -> 0 | C11: =COUNTIFS('Aristocrat (US-EMEA)'!C$6:C$500,">="&DATE(2022,4,1),'Aristocrat (US-EMEA)'!C$6:C$500,"<="&DATE(2022,6+1,1)-1) -> 0 | D11: =COUNTIFS('Aristocrat (US-EMEA)'!C$6:C$500,">="&DATE(2022,7,1),'Aristocrat (US-EMEA)'!C$6:C$500,"<="&DATE(2022,9+1,1)-1) -> 0 | E11: =COUNTIFS('Aristocrat (US-EMEA)'!C$6:C$500,">="&DATE(2022,10,1),'Aristocrat (US-EMEA)'!C$6:C$500,"<="&DATE(2022,12+1,1)-1) -> 0 | F11: =COUNTIFS('Aristocrat (US-EMEA)'!C$6:C$500,">="&DATE(2023,1,1),'Aristocrat (US-EMEA)'!C$6:C$500,"<="&DATE(2023,3+1,1)-1) -> 0 | G11: =COUNTIFS('Aristocrat (US-EMEA)'!C$6:C$500,">="&DATE(2023,4,1),'Aristocrat (US-EMEA)'!C$6:C$500,"<="&DATE(2023,6+1,1)-1) -> 0 | H11: =COUNTIFS('Aristocrat (US-EMEA)'!C$6:C$500,">="&DATE(2023,7,1),'Aristocrat (US-EMEA)'!C$6:C$500,"<="&DATE(2023,9+1,1)-1) -> 0 | I11: =COUNTIFS('Aristocrat (US-EMEA)'!C$6:C$500,">="&DATE(2023,10,1),'Aristocrat (US-EMEA)'!C$6:C$500,"<="&DATE(2023,12+1,1)-1) -> 0 | J11: =COUNTIFS('Aristocrat (US-EMEA)'!C$6:C$500,">="&DATE(2024,1,1),'Aristocrat (US-EMEA)'!C$6:C$500,"<="&DATE(2024,3+1,1)-1) -> 5 | K11: =COUNTIFS('Aristocrat (US-EMEA)'!C$6:C$500,">="&DATE(2024,4,1),'Aristocrat (US-EMEA)'!C$6:C$500,"<="&DATE(2024,6+1,1)-1) -> 13 | L11: =COUNTIFS('Aristocrat (US-EMEA)'!C$6:C$500,">="&DATE(2024,7,1),'Aristocrat (US-EMEA)'!C$6:C$500,"<="&DATE(2024,9+1,1)-1) -> 15 | M11: =COUNTIFS('Aristocrat (US-EMEA)'!C$6:C$500,">="&DATE(2024,10,1),'Aristocrat (US-EMEA)'!C$6:C$500,"<="&DATE(2024,12+1,1)-1) -> 12 | N11: =COUNTIFS('Aristocrat (US-EMEA)'!C$6:C$500,">="&DATE(2025,1,1),'Aristocrat (US-EMEA)'!C$6:C$500,"<="&DATE(2025,3+1,1)-1) -> 6 | O11: =COUNTIFS('Aristocrat (US-EMEA)'!C$6:C$500,">="&DATE(2025,4,1),'Aristocrat (US-EMEA)'!C$6:C$500,"<="&DATE(2025,6+1,1)-1) -> 7 | P11: =COUNTIFS('Aristocrat (US-EMEA)'!C$6:C$500,">="&DATE(2025,7,1),'Aristocrat (US-EMEA)'!C$6:C$500,"<="&DATE(2025,9+1,1)-1) -> 20 | Q11: =COUNTIFS('Aristocrat (US-EMEA)'!C$6:C$500,">="&DATE(2025,10,1),'Aristocrat (US-EMEA)'!C$6:C$500,"<="&DATE(2025,12+1,1)-1) -> 30 | R11: =COUNTIFS('Aristocrat (US-EMEA)'!C$6:C$500,">="&DATE(2026,1,1),'Aristocrat (US-EMEA)'!C$6:C$500,"<="&DATE(2026,3+1,1)-1) -> 16 | S11: =COUNTIFS('Aristocrat (US-EMEA)'!C$6:C$500,">="&DATE(2026,4,1),'Aristocrat (US-EMEA)'!C$6:C$500,"<="&DATE(2026,6+1,1)-1) -> 0 | T11: =COUNTIFS('Aristocrat (US-EMEA)'!C$6:C$500,">="&DATE(2026,7,1),'Aristocrat (US-EMEA)'!C$6:C$500,"<="&DATE(2026,9+1,1)-1) -> 0 | U11: =COUNTIFS('Aristocrat (US-EMEA)'!C$6:C$500,">="&DATE(2026,10,1),'Aristocrat (US-EMEA)'!C$6:C$500,"<="&DATE(2026,12+1,1)-1) -> 0
A12: Aristocrat (Asia) | B12: =COUNTIFS('Aristocrat (Asia)'!C$6:C$500,">="&DATE(2022,1,1),'Aristocrat (Asia)'!C$6:C$500,"<="&DATE(2022,3+1,1)-1) -> 0 | C12: =COUNTIFS('Aristocrat (Asia)'!C$6:C$500,">="&DATE(2022,4,1),'Aristocrat (Asia)'!C$6:C$500,"<="&DATE(2022,6+1,1)-1) -> 0 | D12: =COUNTIFS('Aristocrat (Asia)'!C$6:C$500,">="&DATE(2022,7,1),'Aristocrat (Asia)'!C$6:C$500,"<="&DATE(2022,9+1,1)-1) -> 0 | E12: =COUNTIFS('Aristocrat (Asia)'!C$6:C$500,">="&DATE(2022,10,1),'Aristocrat (Asia)'!C$6:C$500,"<="&DATE(2022,12+1,1)-1) -> 0 | F12: =COUNTIFS('Aristocrat (Asia)'!C$6:C$500,">="&DATE(2023,1,1),'Aristocrat (Asia)'!C$6:C$500,"<="&DATE(2023,3+1,1)-1) -> 0 | G12: =COUNTIFS('Aristocrat (Asia)'!C$6:C$500,">="&DATE(2023,4,1),'Aristocrat (Asia)'!C$6:C$500,"<="&DATE(2023,6+1,1)-1) -> 0 | H12: =COUNTIFS('Aristocrat (Asia)'!C$6:C$500,">="&DATE(2023,7,1),'Aristocrat (Asia)'!C$6:C$500,"<="&DATE(2023,9+1,1)-1) -> 0 | I12: =COUNTIFS('Aristocrat (Asia)'!C$6:C$500,">="&DATE(2023,10,1),'Aristocrat (Asia)'!C$6:C$500,"<="&DATE(2023,12+1,1)-1) -> 0 | J12: =COUNTIFS('Aristocrat (Asia)'!C$6:C$500,">="&DATE(2024,1,1),'Aristocrat (Asia)'!C$6:C$500,"<="&DATE(2024,3+1,1)-1) -> 0 | K12: =COUNTIFS('Aristocrat (Asia)'!C$6:C$500,">="&DATE(2024,4,1),'Aristocrat (Asia)'!C$6:C$500,"<="&DATE(2024,6+1,1)-1) -> 0 | L12: =COUNTIFS('Aristocrat (Asia)'!C$6:C$500,">="&DATE(2024,7,1),'Aristocrat (Asia)'!C$6:C$500,"<="&DATE(2024,9+1,1)-1) -> 0 | M12: =COUNTIFS('Aristocrat (Asia)'!C$6:C$500,">="&DATE(2024,10,1),'Aristocrat (Asia)'!C$6:C$500,"<="&DATE(2024,12+1,1)-1) -> 0 | N12: =COUNTIFS('Aristocrat (Asia)'!C$6:C$500,">="&DATE(2025,1,1),'Aristocrat (Asia)'!C$6:C$500,"<="&DATE(2025,3+1,1)-1) -> 0 | O12: =COUNTIFS('Aristocrat (Asia)'!C$6:C$500,">="&DATE(2025,4,1),'Aristocrat (Asia)'!C$6:C$500,"<="&DATE(2025,6+1,1)-1) -> 0 | P12: =COUNTIFS('Aristocrat (Asia)'!C$6:C$500,">="&DATE(2025,7,1),'Aristocrat (Asia)'!C$6:C$500,"<="&DATE(2025,9+1,1)-1) -> 0 | Q12: =COUNTIFS('Aristocrat (Asia)'!C$6:C$500,">="&DATE(2025,10,1),'Aristocrat (Asia)'!C$6:C$500,"<="&DATE(2025,12+1,1)-1) -> 3 | R12: =COUNTIFS('Aristocrat (Asia)'!C$6:C$500,">="&DATE(2026,1,1),'Aristocrat (Asia)'!C$6:C$500,"<="&DATE(2026,3+1,1)-1) -> 4 | S12: =COUNTIFS('Aristocrat (Asia)'!C$6:C$500,">="&DATE(2026,4,1),'Aristocrat (Asia)'!C$6:C$500,"<="&DATE(2026,6+1,1)-1) -> 0 | T12: =COUNTIFS('Aristocrat (Asia)'!C$6:C$500,">="&DATE(2026,7,1),'Aristocrat (Asia)'!C$6:C$500,"<="&DATE(2026,9+1,1)-1) -> 0 | U12: =COUNTIFS('Aristocrat (Asia)'!C$6:C$500,">="&DATE(2026,10,1),'Aristocrat (Asia)'!C$6:C$500,"<="&DATE(2026,12+1,1)-1) -> 0
A13: TOTAL | B13: =SUM(B11:B12) -> 0 | C13: =SUM(C11:C12) -> 0 | D13: =SUM(D11:D12) -> 0 | E13: =SUM(E11:E12) -> 0 | F13: =SUM(F11:F12) -> 0 | G13: =SUM(G11:G12) -> 0 | H13: =SUM(H11:H12) -> 0 | I13: =SUM(I11:I12) -> 0 | ... U13: =SUM(U11:U12) -> 0
A15: SYNTHÈSE ANNUELLE | B15: 2022 | C15: 2023 | D15: 2024 | E15: 2025 | F15: 2026
A16: Revenus (€) | B16: =SUM(B7:E7) -> 0 | C16: =SUM(F7:I7) -> 0 | D16: =SUM(J7:M7) -> 13047.82 | E16: =SUM(N7:Q7) -> 136500.04 | F16: =SUM(R7:U7) -> 22639.237
A17: Projets | B17: =SUM(B13:E13) -> 0 | C17: =SUM(F13:I13) -> 0 | D17: =SUM(J13:M13) -> 45 | E17: =SUM(N13:Q13) -> 66 | F17: =SUM(R13:U13) -> 20
A18: Rev. / Projet (€) | B18: =IFERROR(B16/B17,"—") -> — | C18: =IFERROR(C16/C17,"—") -> — | D18: =IFERROR(D16/D17,"—") -> 289.95156 | E18: =IFERROR(E16/E17,"—") -> 2068.1824 | F18: =IFERROR(F16/F17,"—") -> 1131.9618
A20: Taux de change (1€ = x $) | B20: 1.15

Sheet Aristocrat (US-EMEA)
J1: =SUBTOTAL(2,J6:J20065) -> 124 | P1: =SUBTOTAL(2,P6:P20065) -> 7 | Q1: =SUBTOTAL(2,Q6:Q20065) -> 35 | R1: =SUBTOTAL(2,R6:R20065) -> 0 | S1: =SUBTOTAL(2,S6:S20065) -> 0 | T1: =SUBTOTAL(2,T6:T20065) -> 0 | U1: =SUBTOTAL(2,U6:U20065) -> 0 | V1: =SUBTOTAL(2,V6:V20065) -> 0 | W1: =SUBTOTAL(2,W6:W20065) -> 0 | ... AT1: =SUBTOTAL(2,AT6:AT20065) -> 17
I2: =SUBTOTAL(9,I6:I20066) -> 116261 | J2: =SUBTOTAL(9,J6:J20066) -> 214352.76 | P2: =SUBTOTAL(9,P6:P20066)*P5 -> 1755 | Q2: =SUBTOTAL(9,Q6:Q20066)*Q5 -> 3090 | R2: =SUBTOTAL(9,R6:R20066)*R5 -> 0 | S2: =SUBTOTAL(9,S6:S20066)*S5 -> 0 | T2: =SUBTOTAL(9,T6:T20066)*T5 -> 0 | U2: =SUBTOTAL(9,U6:U20066)*U5 -> 0 | V2: =SUBTOTAL(9,V6:V20066)*V5 -> 0 | W2: =SUBTOTAL(9,W6:W20066)*W5 -> 0 | ... AT2: =SUBTOTAL(9,AT6:AT20066)*AT5 -> 1283
A3: Price File | P3: Online | X3: Offline | AE3: Presentations | AF3: Web | AJ3: Videos | AQ3: Virtualization | AS3: Copy
A4: Project | E4: Details | P4: Banner creation (static) | Q4: Banner adaptation (static) | R4: Banner creation (animated) | S4: Banner adaptation (animated) | T4: Buttons | U4: Logo | V4: Lifestyle Picture | W4: Wallpapers | X4: Offline creation (standard) | Y4: Offline creation (adaptation) | Z4: Leaflet (1 page) | AA4: Leaflet (2 pages) | AB4: Roll-up / Wall creation | AC4: Chart | AD4: Brochure (20 pages) | AE4: Slide | AF4: Landing page (design only) | AG4: Landing page (complete) | AH4: Website (design only) | AI4: Website (complete) | AJ4: Video Edition | AK4: Video Subtitles / Adaptations | AL4: Social Media Video (up to 30s) | AM4: Social Media Video (up to 1 min) | AN4: Promotional Video (up to 1 min) | AO4: 2D Video (up to 3mn) | AP4: 3D Video (up to 3min) | AQ4: Virtual space | AR4: Virtual showroom | AS4: Translation (per word) | AT4: Transcription (per word)
A5: Customer | B5: Division | C5: Date | D5: Project | E5: Contact | F5: Status | G5: Category | H5: Link | I5: Assets | J5: Total Value | K5: Quote | L5: PO | M5: Invoice | N5: n° Invoice | O5: Statut | P5: 135 | Q5: 30 | R5: 220 | S5: 50 | T5: 15 | U5: 250 | V5: 400 | W5: 85 | X5: 135 | Y5: 30 | Z5: 180 | AA5: 260 | AB5: 180 | AC5: 400 | AD5: 2200 | AE5: 35 | AF5: 300 | AG5: 700 | AH5: 5000 | AI5: 7000 | AJ5: 80 | AK5: 150 | AL5: 260 | AM5: 360 | AN5: 4000 | AO5: 5000 | AP5: 10000 | AQ5: 2500 | AR5: 10000 | AS5: 0.12 | AT5: 0.25
A6: Aristocrat | B6: EMEA | C6: 45302 | D6: Pilot Test Translations | E6: Daniel Browne | F6: Delivered | G6: EMEA | H6: https://saranistudio.sharepoint.com/:f:/s/SaraniAssets/EicHqBO9GotOltf9BORHCJIBc712FqijUq_259gQluFAoA?e=Jiivi4 | I6: 3 | J6: - | K6: NO INVOICE | AS6: 235 | AT6: 80
A7: Aristocrat | B7: EMEA | C7: 45303 | D7: Communiqué de presse ICE 2024 | E7: Daniel Browne | F7: Delivered | G7: EMEA | H7: https://saranistudio.sharepoint.com/:f:/s/SaraniAssets/EjVCi8Y81g5PsgKtjsrg0DIBy6kA-oKjBf_SGQZ9FG3gIQ?e=9wYSQo | I7: 1 | J7: =IF(SUMPRODUCT($P$5:$AU$5,P7:AU7)=0,"-",SUMPRODUCT($P$5:$AU$5,P7:AU7)) -> 120 | K7: - | L7: - | M7: Sent to Thomas | N7: F2024-0176 | O7: Paid 28/05/2024 | AS7: 1000
A8: Aristocrat | B8: EMEA | C8: 45317 | D8: Présentation Carnival Jackpot | E8: Daniel Browne | F8: Delivered | G8: EMEA | H8: https://saranistudio.sharepoint.com/:f:/s/SaraniAssets/ElFltiSBIpREjdA77uLJRYYBlz8fUYn92zg2K6e1A4XqqQ?e=lt6xeh | I8: 1 | J8: =IF(SUMPRODUCT($P$5:$AU$5,P8:AU8)=0,"-",SUMPRODUCT($P$5:$AU$5,P8:AU8)) -> 92 | K8: - | L8: - | M8: Sent to Thomas | N8: F2024-0176 | O8: Paid 28/05/2024 | AT8: 368
A9: Aristocrat | B9: USA | C9: 45327 | D9: 12.23 E-Blast V1_FR | E9: Megan Nimsgern | F9: Delivered | G9: USA | H9: https://saranistudio.sharepoint.com/:f:/s/SaraniAssets/ElyIX3Mo7jBAu6K49clJcLkB3uYPq9Ekqat5KsoijNSwEQ?e=Dgbppz | I9: 1 | J9: =IF(SUMPRODUCT($P$5:$AU$5,P9:AU9)=0,"-",SUMPRODUCT($P$5:$AU$5,P9:AU9)) -> 27.6 | K9: - | L9: - | M9: Sent to Thomas | N9: F2024-0176 | O9: Paid 28/05/2024 | AS9: 230
A10: Aristocrat | B10: USA | C10: 45364 | D10: Know Your Max - Welcome to Max HQ | E10: Megan Nimsgern | F10: Delivered | G10: USA | H10: https://saranistudio.sharepoint.com/:w:/s/SaraniAssets/Eck7LNoSSKRJhKCa-vUyWZMBWUpF6UToorC9K1p-89QEkw?e=641Qfg | I10: =IF(SUM(P10:AU10)=0,"-",SUM(P10:AU10)) -> 44 | J10: =IF(SUMPRODUCT($P$5:$AU$5,P10:AU10)=0,"-",SUMPRODUCT($P$5:$AU$5,P10:AU10)) -> 5.28 | K10: - | L10: - | M10: Sent to Thomas | N10: F2024-0176 | O10: Paid 28/05/2024 | AS10: 44
A11: Aristocrat | B11: EMEA | C11: 45387 | D11: Hungarian translations | E11: Lauen Feiner | F11: Delivered | G11: EMEA | H11: https://saranistudio.sharepoint.com/:f:/s/SaraniAssets/EsjQHFLgoTRJhu_jtLNpEHcBr5y8GcgOaH8eq1tt8JljCw?e=iqr6dx | I11: 12 | J11: 2750 | K11: - | L11: - | M11: Sent to Thomas | N11: F2024-0175 | O11: Paid 28/05/2024 | AS11: =7767+1951+1951+4739+4697+7754+2428+3121 -> 34408
A12: Aristocrat | B12: USA | C12: 45400 | D12: Dragon Link Page Advertising | E12: Megan Nimsgern | F12: Delivered | G12: USA | H12: https://saranistudio.sharepoint.com/:f:/s/SaraniAssets/EgV4wqclurVAjk8QfT1zRi4BWj5py5IHEgtvzYHjmD5wug?e=qHNSPI | I12: =IF(SUM(P12:AU12)=0,"-",SUM(P12:AU12)) -> 155 | J12: =IF(SUMPRODUCT($P$5:$AU$5,P12:AU12)=0,"-",SUMPRODUCT($P$5:$AU$5,P12:AU12)) -> 38.75 | K12: - | L12: - | M12: Sent to Thomas | N12: F2024-0176 | O12: Paid 28/05/2024 | AT12: 155
A13: Aristocrat | B13: USA | C13: 45400 | D13: Joy Presentation | E13: Megan Nimsgern | F13: Delivered | G13: USA | H13: 20240418_Dragon Link Page Advertising | I13: =IF(SUM(P13:AU13)=0,"-",SUM(P13:AU13)) -> 700 | J13: =IF(SUMPRODUCT($P$5:$AU$5,P13:AU13)=0,"-",SUMPRODUCT($P$5:$AU$5,P13:AU13)) -> 84 | K13: - | L13: - | M13: Sent to Thomas | N13: F2024-0176 | O13: Paid 28/05/2024 | AS13: 700
A14: Aristocrat | B14: USA | C14: 45400 | D14: Updating Dragon Link Photos | E14: Megan Nimsgern | F14: Delivered | G14: USA | H14: https://saranistudio.sharepoint.com/:f:/s/SaraniAssets/Eqha9ofIjoZPr1TIu2A69sMB4vKH3PjJO7zUgKsc2yJ0Ow?e=RWbeeV | I14: =IF(SUM(P14:AU14)=0,"-",SUM(P14:AU14)) -> 3 | J14: =IF(SUMPRODUCT($P$5:$AU$5,P14:AU14)=0,"-",SUMPRODUCT($P$5:$AU$5,P14:AU14)) -> 90 | K14: - | L14: - | M14: Sent to Thomas | N14: F2024-0176 | O14: Paid 28/05/2024 | Q14: 3
A15: Aristocrat | B15: EMEA | C15: 45405 | D15: Dragon Link Ads | E15: Daniel Browne | F15: Delivered | G15: EMEA | H15: https://saranistudio.sharepoint.com/:f:/s/SaraniAssets/ErUH4AT3xKZIiF2P4aB6THEB3fERlJB2gaIl9dYmZrPU0A?e=YqoR1K | I15: =IF(SUM(P15:AU15)=0,"-",SUM(P15:AU15)) -> 1 | J15: =IF(SUMPRODUCT($P$5:$AU$5,P15:AU15)=0,"-",SUMPRODUCT($P$5:$AU$5,P15:AU15)) -> 30 | K15: - | L15: - | M15: Sent to Thomas | N15: F2024-0257 | O15: Paid 05/07/2024 | Q15: 1
A16: Aristocrat | B16: EMEA | C16: 45411 | D16: Cashman Double Bingo Sun & Moon | E16: Gustavo Vessani | F16: Delivered | G16: EMEA | H16: https://saranistudio.sharepoint.com/:f:/s/SaraniAssets/El6ehHV_24RBn9ZgNxvKNSoBtEqrSmA3EEm-Zb8LYcWBPA?e=DeQugO | I16: =IF(SUM(P16:AU16)=0,"-",SUM(P16:AU16)) -> 1017 | J16: 122 | K16: - | L16: - | M16: Sent to Thomas | N16: F2024-0196 | O16: Paid 28/05/2024 | AS16: 1017
A17: Aristocrat | B17: USA | C17: 45433 | D17: French Game Rules - Translations | E17: Megan Nimsgern | F17: Delivered | G17: USA | H17: https://saranistudio.sharepoint.com/:f:/s/SaraniAssets/EnroNK7W9i5Mivv8g4hJkS4BD2zqxvkMcEhH6ksZ0EQJRQ?e=1SKKur | I17: =IF(SUM(P17:AU17)=0,"-",SUM(P17:AU17)) -> 17330 | J17: =IF(SUMPRODUCT($P$5:$AU$5,P17:AU17)=0,"-",SUMPRODUCT($P$5:$AU$5,P17:AU17)) -> 2079.6 | K17: - | L17: - | M17: Sent to Thomas | N17: F2024-0257 | O17: Paid 05/07/2024 | AS17: =2575+2811+664+665+745+747+2113+2115+1232+1229+1217+1217 -> 17330
A18: Aristocrat | B18: USA | C18: 45443 | D18: Peru Gaming Show | E18: Megan Nimsgern | F18: Delivered | G18: USA | H18: https://saranistudio.sharepoint.com/:f:/s/SaraniAssets/EowvOfwr33BMj-fQq9knBvcBnaujdRAc2b1WcprDqcBzhg?e=fwvcPN | I18: =IF(SUM(P18:AU18)=0,"-",SUM(P18:AU18)) -> 430 | J18: =IF(SUMPRODUCT($P$5:$AU$5,P18:AU18)=0,"-",SUMPRODUCT($P$5:$AU$5,P18:AU18)) -> 107.5 | K18: - | L18: - | M18: Sent to Thomas | N18: F2024-0257 | O18: Paid 05/07/2024 | AT18: 430
A19: Aristocrat | B19: USA | C19: 45456 | D19: Trilenium SP | E19: Megan Nimsgern | F19: Delivered | G19: USA | H19: https://saranistudio.sharepoint.com/:f:/s/SaraniAssets/EnIC2ND_-IhLtuOmQ0ywYuEB6r7gGkvOeKFO_yCblpWXuA?e=dFypTO | I19: =IF(SUM(P19:AU19)=0,"-",SUM(P19:AU19)) -> 265 | J19: =IF(SUMPRODUCT($P$5:$AU$5,P19:AU19)=0,"-",SUMPRODUCT($P$5:$AU$5,P19:AU19)) -> 66.25 | K19: - | L19: - | M19: Sent to Thomas | N19: F2024-0326 | O19: Paid 14/08/2024 | AT19: 265
A20: Aristocrat | B20: USA | C20: 45463 | D20: SP registration form | E20: Megan Nimsgern | F20: Delivered | G20: USA | H20: https://saranistudio.sharepoint.com/:f:/s/SaraniAssets/Evl07W9WGGhEtehSc2_yr28BZJ3M38Rqn6iRc7qPrpL8uQ?e=pivuZd | I20: =IF(SUM(P20:AU20)=0,"-",SUM(P20:AU20)) -> 250 | J20: =IF(SUMPRODUCT($P$5:$AU$5,P20:AU20)=0,"-",SUMPRODUCT($P$5:$AU$5,P20:AU20)) -> 30 | K20: - | L20: - | M20: Sent to Thomas | N20: F2024-0326 | O20: Paid 14/08/2024 | AS20: 250
A21: Aristocrat | B21: USA | C21: 45463 | D21: French ad | E21: Megan Nimsgern | F21: Delivered | G21: USA | H21: - Email | I21: =IF(SUM(P21:AU21)=0,"-",SUM(P21:AU21)) -> 40 | J21: =IF(SUMPRODUCT($P$5:$AU$5,P21:AU21)=0,"-",SUMPRODUCT($P$5:$AU$5,P21:AU21)) -> 10 | K21: - | L21: - | M21: Sent to Thomas | N21: F2024-0326 | O21: Paid 14/08/2024 | AT21: 40
A22: Aristocrat | B22: USA | C22: 45470 | D22: Monaco Casino Deck Translation | E22: Megan Nimsgern | F22: Delivered | G22: USA | H22: https://saranistudio.sharepoint.com/:f:/s/SaraniAssets/Eu1DdecbiRlFjp4_UiiV1aEBGaf_h3dwocON-LWLu6u8Dg?e=7fkaek | I22: =IF(SUM(P22:AU22)=0,"-",SUM(P22:AU22)) -> 400 | J22: =IF(SUMPRODUCT($P$5:$AU$5,P22:AU22)=0,"-",SUMPRODUCT($P$5:$AU$5,P22:AU22)) -> 48 | K22: - | L22: - | M22: Sent to Thomas | N22: F2024-0326 | O22: Paid 14/08/2024 | AS22: 400
A23: Aristocrat | B23: USA | C23: 45470 | D23: Bonus Highlights Translations | E23: Megan Nimsgern | F23: Delivered | G23: USA | H23: https://saranistudio.sharepoint.com/:f:/s/SaraniAssets/EjoYoNRokUJCob2AkQes1eoBOP4MJuo3Zc-1qw_-HiSnuQ?e=tABvP0 | I23: =IF(SUM(P23:AU23)=0,"-",SUM(P23:AU23)) -> 850 | J23: =IF(SUMPRODUCT($P$5:$AU$5,P23:AU23)=0,"-",SUMPRODUCT($P$5:$AU$5,P23:AU23)) -> 102 | K23: - | L23: - | M23: Sent to Thomas | N23: F2024-0326 | O23: Paid 14/08/2024 | AS23: 850
A24: Aristocrat | B24: USA | C24: 45485 | D24: EMEA Product Script Translations | E24: Megan Nimsgern | F24: Delivered | G24: USA | H24: https://saranistudio.sharepoint.com/:f:/s/SaraniAssets/Es9QBoBjb9VJvGDL3Zf9-voBWmaA_rAbTzthkJYXQAA1Mw?e=PkwSHS | I24: =IF(SUM(P24:AU24)=0,"-",SUM(P24:AU24)) -> 4140 | J24: =IF(SUMPRODUCT($P$5:$AU$5,P24:AU24)=0,"-",SUMPRODUCT($P$5:$AU$5,P24:AU24)) -> 496.8 | K24: - | L24: - | M24: Sent to Thomas | N24: F2024-0326 | O24: Paid 14/08/2024 | AS24: =690*6 -> 4140
A25: Aristocrat | B25: USA | C25: 45485 | D25: Games rules translations | E25: Megan Nimsgern | F25: Delivered | G25: USA | H25: https://saranistudio.sharepoint.com/:f:/s/SaraniAssets/EgSpS7bq8c9ClzPajLlGKnIBdqYULi6RzKofIZubAtNmwg?e=MsRkUu | I25: =IF(SUM(P25:AU25)=0,"-",SUM(P25:AU25)) -> 7100 | J25: =IF(SUMPRODUCT($P$5:$AU$5,P25:AU25)=0,"-",SUMPRODUCT($P$5:$AU$5,P25:AU25)) -> 852 | K25: - | L25: - | M25: Sent to Thomas | N25: F2024-0326 | O25: Paid 14/08/2024 | AS25: =3500+1800+1800 -> 7100
A26: Aristocrat | B26: USA | C26: 45485 | D26: Form Export | E26: Megan Nimsgern | F26: Delivered | G26: USA | H26: https://saranistudio.sharepoint.com/:f:/s/SaraniAssets/EpuE4RXdO8hAr4qLP_U7DQ0BZkLhBXgxJfYor_Z0-CduXg?e=E8bQ44 | I26: =IF(SUM(P26:AU26)=0,"-",SUM(P26:AU26)) -> 2674 | J26: =IF(SUMPRODUCT($P$5:$AU$5,P26:AU26)=0,"-",SUMPRODUCT($P$5:$AU$5,P26:AU26)) -> 320.88 | K26: - | L26: - | M26: Sent to Thomas | N26: F2024-0326 | O26: Paid 14/08/2024 | AS26: 2674
A27: Aristocrat | B27: USA | C27: 45499 | D27: G2E Invite Translation | E27: Megan Nimsgern | F27: Delivered | G27: USA | H27: - Email | I27: =IF(SUM(P27:AU27)=0,"-",SUM(P27:AU27)) -> 150 | J27: =IF(SUMPRODUCT($P$5:$AU$5,P27:AU27)=0,"-",SUMPRODUCT($P$5:$AU$5,P27:AU27)) -> 37.5 | K27: - | L27: - | M27: Sent to Thomas | N27: F2024-0392 | O27: Paid 20/09/2024 | AT27: 150
A28: Aristocrat | B28: USA | C28: 45503 | D28: Workday supplier log in instructions | E28: Megan Nimsgern | F28: Delivered | G28: USA | H28: https://saranistudio.sharepoint.com/:f:/s/SaraniAssets/EkjafVG4VKJBqf747r1_V8ABNM1X7KLOsyC1Fa0avov8yg?e=zf7vpc | I28: =IF(SUM(P28:AU28)=0,"-",SUM(P28:AU28)) -> 600 | J28: =IF(SUMPRODUCT($P$5:$AU$5,P28:AU28)=0,"-",SUMPRODUCT($P$5:$AU$5,P28:AU28)) -> 72 | K28: - | L28: - | M28: Sent to Thomas | N28: F2024-0392 | O28: Paid 20/09/2024 | AS28: 600
A29: Aristocrat | B29: USA | C29: 45508 | D29: Rules of the Road - Spanish | E29: Megan Nimsgern | F29: Delivered | G29: USA | H29: https://saranistudio.sharepoint.com/:f:/s/SaraniAssets/El90XJB1hU1Oved8pG663yEB6o7cYZpgCWrfukMVc7SU_Q?e=TainRa | I29: =IF(SUM(P29:AU29)=0,"-",SUM(P29:AU29)) -> 520 | J29: =IF(SUMPRODUCT($P$5:$AU$5,P29:AU29)=0,"-",SUMPRODUCT($P$5:$AU$5,P29:AU29)) -> 62.4 | K29: - | L29: - | M29: Sent to Thomas | N29: F2024-0392 | O29: Paid 20/09/2024 | AS29: 520
A30: Aristocrat | B30: USA | C30: 45516 | D30: French Advertisement Copy | E30: Megan Nimsgern | F30: Delivered | G30: USA | H30: - Email | I30: =IF(SUM(P30:AU30)=0,"-",SUM(P30:AU30)) -> 50 | J30: =IF(SUMPRODUCT($P$5:$AU$5,P30:AU30)=0,"-",SUMPRODUCT($P$5:$AU$5,P30:AU30)) -> 12.5 | K30: - | L30: - | M30: Sent to Thomas | N30: F2024-0392 | O30: Paid 20/09/2024 | AT30: 50
A31: Aristocrat | B31: USA | C31: 45516 | D31: The baron brochure | E31: Megan Nimsgern | F31: Delivered | G31: USA | H31: - Email | I31: =IF(SUM(P31:AU31)=0,"-",SUM(P31:AU31)) -> 430 | J31: =IF(SUMPRODUCT($P$5:$AU$5,P31:AU31)=0,"-",SUMPRODUCT($P$5:$AU$5,P31:AU31)) -> 51.6 | K31: - | L31: - | M31: Sent to Thomas | N31: F2024-0392 | O31: Paid 20/09/2024 | AS31: =215*2 -> 430
A32: Aristocrat | B32: USA | C32: 45524 | D32: French quotes | E32: Megan Nimsgern | F32: Delivered | G32: USA | H32: https://saranistudio.sharepoint.com/:f:/s/SaraniAssets/EqNVhASVLx1GqoO9fik-2WgB79N-oEll3qcYgUVBeFVSbA?e=Pmw5lb | I32: =IF(SUM(P32:AU32)=0,"-",SUM(P32:AU32)) -> 1270 | J32: =IF(SUMPRODUCT($P$5:$AU$5,P32:AU32)=0,"-",SUMPRODUCT($P$5:$AU$5,P32:AU32)) -> 152.4 | K32: - | L32: - | M32: Sent to Thomas | N32: F2024-0392 | O32: Paid 20/09/2024 | AS32: =445+225+600 -> 1270
A33: Aristocrat | B33: USA | C33: 45524 | D33: Tagline - French Translations | E33: Megan Nimsgern | F33: Delivered | G33: USA | H33: - Email | I33: =IF(SUM(P33:AU33)=0,"-",SUM(P33:AU33)) -> 20 | J33: 10 | K33: - | L33: - | M33: Sent to Thomas | N33: F2024-0392 | O33: Paid 20/09/2024 | AT33: 20
A34: Aristocrat | B34: USA | C34: 45532 | D34: Slick Spanish Translations | E34: Megan Nimsgern | F34: Delivered | G34: USA | H34: https://saranistudio.sharepoint.com/:f:/s/SaraniAssets/EkbtRDSapgtOsCGRr45n3s8BxNwNsJWvG978ep85BJ1GRg?e=4csna7 | I34: =IF(SUM(P34:AU34)=0,"-",SUM(P34:AU34)) -> 665 | J34: =IF(SUMPRODUCT($P$5:$AU$5,P34:AU34)=0,"-",SUMPRODUCT($P$5:$AU$5,P34:AU34)) -> 166.25 | K34: - | L34: - | M34: Sent to Thomas | N34: F2024-0483 | O34: Paid 18/10/2024 | AT34: 665
A35: Aristocrat | B35: USA | C35: 45532 | D35: Bao Zhu Translations | E35: Megan Nimsgern | F35: Delivered | G35: USA | H35: https://saranistudio.sharepoint.com/:f:/s/SaraniAssets/EuvalTHbCp5Epfzl2fnz76YBVf5-e6tI7B7uVbDlHJ47GA?e=WsqRLQ | I35: =IF(SUM(P35:AU35)=0,"-",SUM(P35:AU35)) -> 415 | J35: =IF(SUMPRODUCT($P$5:$AU$5,P35:AU35)=0,"-",SUMPRODUCT($P$5:$AU$5,P35:AU35)) -> 103.75 | K35: - | L35: - | M35: Sent to Thomas | N35: F2024-0483 | O35: Paid 18/10/2024 | AT35: 415
A36: Aristocrat | B36: USA | C36: 45554 | D36: Whisker Wheels Game Rules - Translation | E36: Megan Nimsgern | F36: Delivered | G36: USA | H36: 20240830_Slick Spanish Translations | I36: =IF(SUM(P36:AU36)=0,"-",SUM(P36:AU36)) -> 1801 | J36: =IF(SUMPRODUCT($P$5:$AU$5,P36:AU36)=0,"-",SUMPRODUCT($P$5:$AU$5,P36:AU36)) -> 216.12 | K36: - | L36: - | M36: Sent to Thomas | N36: F2024-0483 | O36: Paid 18/10/2024 | AS36: 1801
A37: Aristocrat | B37: USA | C37: 45562 | D37: Italian translations | E37: Megan Nimsgern | F37: Delivered | G37: USA | H37: - Email | I37: =IF(SUM(P37:AU37)=0,"-",SUM(P37:AU37)) -> 51 | J37: =IF(SUMPRODUCT($P$5:$AU$5,P37:AU37)=0,"-",SUMPRODUCT($P$5:$AU$5,P37:AU37)) -> 6.12 | K37: - | L37: - | M37: Sent to Thomas | N37: F2024-0483 | O37: Paid 18/10/2024 | AS37: 51
A38: Aristocrat | B38: USA | C38: 45562 | D38: Backdrop Graphic - Aristocrat | E38: Megan Nimsgern | F38: Delivered | G38: USA | H38: https://saranistudio.sharepoint.com/:f:/s/SaraniAssets/EmfCNS1dNjVJoVUbuLby2mQBkHLjQHrosRlQN-UqzpuzuA?e=3s2xjn | I38: =IF(SUM(P38:AU38)=0,"-",SUM(P38:AU38)) -> 1 | J38: =IF(SUMPRODUCT($P$5:$AU$5,P38:AU38)=0,"-",SUMPRODUCT($P$5:$AU$5,P38:AU38)) -> 180 | K38: - | L38: - | M38: Sent to Thomas | N38: F2024-0483 | O38: Paid 18/10/2024 | AB38: 1
A39: Aristocrat | B39: USA | C39: 45567 | D39: Cabinet Art work changes | E39: Megan Nimsgern | F39: Delivered | G39: USA | H39: https://saranistudio.sharepoint.com/:f:/s/SaraniAssets/ErWt2eivjgBOiHbZ58kvpZQBuHWAiWWJ_JCRLNww6pXmIQ?e=JBPZDA | I39: =IF(SUM(P39:AU39)=0,"-",SUM(P39:AU39)) -> 4 | J39: =IF(SUMPRODUCT($P$5:$AU$5,P39:AU39)=0,"-",SUMPRODUCT($P$5:$AU$5,P39:AU39)) -> 120 | K39: - | L39: - | M39: Sent to Thomas | N39: F2024-0567 | O39: Paid 06/12/2024 | Q39: 4
A40: Aristocrat | B40: USA | C40: 45574 | D40: Bonus Highlight Video Translations | E40: Tia Shumway | F40: Delivered | G40: USA | H40: https://saranistudio.sharepoint.com/:f:/s/SaraniAssets/EjoYoNRokUJCob2AkQes1eoBOP4MJuo3Zc-1qw_-HiSnuQ?e=WJuuAm | I40: =IF(SUM(P40:AU40)=0,"-",SUM(P40:AU40)) -> 63 | J40: =IF(SUMPRODUCT($P$5:$AU$5,P40:AU40)=0,"-",SUMPRODUCT($P$5:$AU$5,P40:AU40)) -> 7.56 | K40: - | L40: - | M40: Sent to Thomas | N40: F2024-0567 | O40: Paid 06/12/2024 | AS40: 63
...

Sheet Aristocrat (Asia)
J1: =SUBTOTAL(2,J6:J19930) -> 7 | P1: =SUBTOTAL(2,P6:P19883) -> 4 | Q1: =SUBTOTAL(2,Q6:Q19883) -> 1 | R1: =SUBTOTAL(2,R6:R19883) -> 0 | S1: =SUBTOTAL(2,S6:S19883) -> 0 | T1: =SUBTOTAL(2,T6:T19883) -> 0 | U1: =SUBTOTAL(2,U6:U19883) -> 0 | V1: =SUBTOTAL(2,V6:V19883) -> 0 | W1: =SUBTOTAL(2,W6:W19883) -> 1 | ... AK1: =SUBTOTAL(2,AK6:AK19883) -> 0 | AM1: =SUBTOTAL(2,AM6:AM19883) -> 0 | AN1: =SUBTOTAL(2,AN6:AN19883) -> 0 | AO1: =SUBTOTAL(2,AO6:AO19883) -> 0 | AP1: =SUBTOTAL(2,AP6:AP19883) -> 0 | AQ1: =SUBTOTAL(2,AQ6:AQ19883) -> 0 | AR1: =SUBTOTAL(2,AR6:AR19883) -> 0 | AS1: =SUBTOTAL(2,AS6:AS19883) -> 0 | AT1: =SUBTOTAL(2,AT6:AT19883) -> 0
I2: =SUBTOTAL(9,I6:I19931) -> 26 | J2: =SUBTOTAL(9,J6:J19931) -> 11955 | P2: =SUBTOTAL(9,P6:P19884)*P5 -> 1050 | Q2: =SUBTOTAL(9,Q6:Q19884)*Q5 -> 35 | R2: =SUBTOTAL(9,R6:R19884)*R5 -> 0 | S2: =SUBTOTAL(9,S6:S19884)*S5 -> 0 | T2: =SUBTOTAL(9,T6:T19884)*T5 -> 0 | U2: =SUBTOTAL(9,U6:U19884)*U5 -> 0 | V2: =SUBTOTAL(9,V6:V19884)*V5 -> 0 | W2: =SUBTOTAL(9,W6:W19884)*W5 -> 600 | ... AK2: =SUBTOTAL(9,AK6:AK19884)*AK5 -> 0 | AM2: =SUBTOTAL(9,AM6:AM19884)*AM5 -> 0 | AN2: =SUBTOTAL(9,AN6:AN19884)*AN5 -> 0 | AO2: =SUBTOTAL(9,AO6:AO19884)*AO5 -> 0 | AP2: =SUBTOTAL(9,AP6:AP19884)*AP5 -> 0 | AQ2: =SUBTOTAL(9,AQ6:AQ19884)*AQ5 -> 0 | AR2: =SUBTOTAL(9,AR6:AR19884)*AR5 -> 0 | AS2: =SUBTOTAL(9,AS6:AS19884)*AS5 -> 0 | AT2: =SUBTOTAL(9,AT6:AT19884)*AT5 -> 0
A3: Price File | P3: Online | W3: Offline | AC3: Presentations | AD3: Web | AH3: Videos | AO3: Contentful | AS3: Copy
A4: Project | E4: Details | P4: Banner creation (static) | Q4: Banner adaptation (static) | R4: Banner creation (animated) | S4: Banner adaptation (animated) | T4: Buttons | U4: Logo | V4: Wallpapers | W4: Offline creation (standard) | X4: Offline creation (adaptation) | Y4: Leaflet (1 page) | Z4: Leaflet (2 pages) | AA4: Roll-up / Wall creation | AB4: Brochure (20 pages) | AC4: Slide | AD4: Landing page (design only) | AE4: Landing page (complete) | AF4: Website (design only) | AG4: Website (complete) | AH4: Video Edition | AI4: Video Subtitles | AJ4: Social Media Video (up to 30s) | AK4: Social Media Video (up to 1 min) | AL4: Sizzle videos | AM4: Promotional Video (up to 1 min) | AN4: 2D Video (up to 3mn) | AO4: Case study (per article) | AP4: Blog article (per article) | AQ4: Translation (per article) | AR4: Splash (per creation/modification) | AS4: Translation (per word) | AT4: Copywrite (per word)
A5: Customer | B5: Division | C5: Date | D5: Project | E5: Contact | F5: Status | G5: Category | H5: Link | I5: Assets | J5: Total Value | K5: Quote | L5: PO | M5: Invoice | N5: n° Invoice | O5: Statut | P5: 150 | Q5: 35 | R5: 250 | S5: 55 | T5: 20 | U5: 275 | V5: 90 | W5: 150 | X5: 45 | Y5: 200 | Z5: 280 | AA5: 200 | AB5: 2500 | AC5: 35 | AD5: 350 | AE5: 750 | AF5: 5500 | AG5: 7800 | AH5: 90 | AI5: 165 | AJ5: 390 | AK5: 490 | AL5: 900 | AM5: 4500 | AN5: 5500 | AO5: 38 | AP5: 45 | AQ5: 27 | AR5: 35 | AS5: 0.15 | AT5: =0.25*1.08 -> 0.27
A6: Aristocrat | B6: Asia | C6: 45990 | D6: ASIA - Golf cart and Tee marker design | E6: Sandy Cheng | F6: Delivered | G6: Asia | H6: https://saranistudio.sharepoint.com/:f:/s/SaraniAssets/IgBdCWHuWVRfQrbR0t0XwCNIAeRvzdTBf6qlizKedyhzBgQ?e=kH1ara | I6: =IF(SUM(P6:AU6)=0,"-",SUM(P6:AU6)) -> 10 | J6: =IF(SUMPRODUCT($P$5:$AU$5,P6:AU6)=0,"-",SUMPRODUCT($P$5:$AU$5,P6:AU6)) -> 870 | M6: Sent to Sandy | N6: F2026-0011 | O6: Waiting payment for 13/02/2026 | W6: 4 | X6: 6
A7: Aristocrat | B7: Asia | C7: 45992 | D7: ASIA - Breadcrumb Trail Campaign | E7: Kimmi Siu Dewar | F7: Delivered | G7: Asia | H7: https://saranistudio.sharepoint.com/:f:/s/SaraniAssets/IgCuiILQq2S2TrXioMp8gx4fAf8B2IdugBwuN-6fB_VQhSc?e=MXflGl | I7: =IF(SUM(P7:AU7)=0,"-",SUM(P7:AU7)) -> 4 | J7: =IF(SUMPRODUCT($P$5:$AU$5,P7:AU7)=0,"-",SUMPRODUCT($P$5:$AU$5,P7:AU7)) -> 600 | M7: Sent to Sandy | N7: F2026-0011 | O7: Waiting payment for 13/02/2026 | P7: 4
A8: Aristocrat | B8: Asia | C8: 46007 | D8: 2026 APAC golf tournament invitation | E8: Kimmi Siu Dewar | F8: Delivered | G8: Asia | H8: https://saranistudio.sharepoint.com/:f:/s/SaraniAssets/IgC-ZsA9vy8mQbe2tRFmtycDAbz6VH3vle4XWtHaXmd9n8M?e=RWBfi8 | I8: =IF(SUM(P8:AU8)=0,"-",SUM(P8:AU8)) -> 1 | J8: =IF(SUMPRODUCT($P$5:$AU$5,P8:AU8)=0,"-",SUMPRODUCT($P$5:$AU$5,P8:AU8)) -> 150 | M8: Sent to Sandy | N8: F2026-0011 | O8: Waiting payment for 13/02/2026 | P8: 1
A9: Aristocrat | B9: Asia | C9: 46033 | D9: ASIA - Artwork brief BARON LAUNCH VN | E9: Kimmi Siu Dewar | F9: Delivered | G9: Asia | H9: https://saranistudio.sharepoint.com/:f:/s/SaraniAssets/IgALARsc58n_TaIw7pez_8hgAfGR1yqPDQpjLbdcLvgMDL8?e=EqPadB | I9: =IF(SUM(P9:AU9)=0,"-",SUM(P9:AU9)) -> 1 | J9: =IF(SUMPRODUCT($P$5:$AU$5,P9:AU9)=0,"-",SUMPRODUCT($P$5:$AU$5,P9:AU9)) -> 150 | M9: Sent to Sandy | N9: F2026-0094 | O9: Waiting payment for 02/04/2026 | P9: 1
A10: Aristocrat | B10: Asia | C10: 46034 | D10: Artwork brief for Print ads and web banner artwork | E10: Sandy Cheng | F10: Delivered | G10: Asia | H10: 20260112_Artwork brief for Print ads and web banner artwork | I10: =IF(SUM(P10:AU10)=0,"-",SUM(P10:AU10)) -> 2 | J10: =IF(SUMPRODUCT($P$5:$AU$5,P10:AU10)=0,"-",SUMPRODUCT($P$5:$AU$5,P10:AU10)) -> 185 | M10: Sent to Sandy | N10: F2026-0094 | O10: Waiting payment for 02/04/2026 | P10: 1 | Q10: 1
A11: Aristocrat | B11: Asia | C11: 46056 | D11: Aristocrat 3D Models -Part 1 | E11: Stephanie Che | F11: In progress | G11: Asia | H11: 20260203_Aristocrat 3D Models | I11: 4 | J11: 5000 | M11: Sent to Ameena | N11: F2026-0130 | O11: Waiting payment for 24/04/2026
A12: Aristocrat | B12: Asia | C12: 46056 | D12: Aristocrat 3D Models -Part 2 | E12: Stephanie Che | F12: In progress | G12: Asia | H12: 20260203_Aristocrat 3D Models | I12: 4 | J12: 5000
I13: =IF(SUM(P13:AU13)=0,"-",SUM(P13:AU13)) -> - | J13: =IF(SUMPRODUCT($P$5:$AU$5,P13:AU13)=0,"-",SUMPRODUCT($P$5:$AU$5,P13:AU13)) -> -
I14: =IF(SUM(P14:AU14)=0,"-",SUM(P14:AU14)) -> - | J14: =IF(SUMPRODUCT($P$5:$AU$5,P14:AU14)=0,"-",SUMPRODUCT($P$5:$AU$5,P14:AU14)) -> -
I15: =IF(SUM(P15:AU15)=0,"-",SUM(P15:AU15)) -> - | J15: =IF(SUMPRODUCT($P$5:$AU$5,P15:AU15)=0,"-",SUMPRODUCT($P$5:$AU$5,P15:AU15)) -> -
I16: =IF(SUM(P16:AU16)=0,"-",SUM(P16:AU16)) -> - | J16: =IF(SUMPRODUCT($P$5:$AU$5,P16:AU16)=0,"-",SUMPRODUCT($P$5:$AU$5,P16:AU16)) -> -
I17: =IF(SUM(P17:AU17)=0,"-",SUM(P17:AU17)) -> - | J17: =IF(SUMPRODUCT($P$5:$AU$5,P17:AU17)=0,"-",SUMPRODUCT($P$5:$AU$5,P17:AU17)) -> -
I18: =IF(SUM(P18:AU18)=0,"-",SUM(P18:AU18)) -> - | J18: =IF(SUMPRODUCT($P$5:$AU$5,P18:AU18)=0,"-",SUMPRODUCT($P$5:$AU$5,P18:AU18)) -> -
I19: =IF(SUM(P19:AU19)=0,"-",SUM(P19:AU19)) -> - | J19: =IF(SUMPRODUCT($P$5:$AU$5,P19:AU19)=0,"-",SUMPRODUCT($P$5:$AU$5,P19:AU19)) -> -
I20: =IF(SUM(P20:AU20)=0,"-",SUM(P20:AU20)) -> - | J20: =IF(SUMPRODUCT($P$5:$AU$5,P20:AU20)=0,"-",SUMPRODUCT($P$5:$AU$5,P20:AU20)) -> -
I21: =IF(SUM(P21:AU21)=0,"-",SUM(P21:AU21)) -> - | J21: =IF(SUMPRODUCT($P$5:$AU$5,P21:AU21)=0,"-",SUMPRODUCT($P$5:$AU$5,P21:AU21)) -> -
I22: =IF(SUM(P22:AU22)=0,"-",SUM(P22:AU22)) -> - | J22: =IF(SUMPRODUCT($P$5:$AU$5,P22:AU22)=0,"-",SUMPRODUCT($P$5:$AU$5,P22:AU22)) -> -
I23: =IF(SUM(P23:AU23)=0,"-",SUM(P23:AU23)) -> - | J23: =IF(SUMPRODUCT($P$5:$AU$5,P23:AU23)=0,"-",SUMPRODUCT($P$5:$AU$5,P23:AU23)) -> -
I24: =IF(SUM(P24:AU24)=0,"-",SUM(P24:AU24)) -> - | J24: =IF(SUMPRODUCT($P$5:$AU$5,P24:AU24)=0,"-",SUMPRODUCT($P$5:$AU$5,P24:AU24)) -> -
... I35: =IF(SUM(P35:AU35)=0,"-",SUM(P35:AU35)) -> - | J35: =IF(SUMPRODUCT($P$5:$AU$5,P35:AU35)=0,"-",SUMPRODUCT($P$5:$AU$5,P35:AU35)) -> -
