Workbook

Sheet Overview
A1: Performance Dashboard — Ubi (Sarani)
A3: REVENUS (€) | B3: 2025 | F3: 2026
B4: Q1 | C4: Q2 | D4: Q3 | E4: Q4 | F4: Q1 | G4: Q2 | H4: Q3 | I4: Q4
A5: Adidas | B5: =SUMIFS(Ubi!$K:$K,Ubi!$C:$C,">="&DATE(2025,1,1),Ubi!$C:$C,"<="&DATE(2025,3+1,0),Ubi!$B:$B,"*Adidas*") -> 7760 | C5: =SUMIFS(Ubi!$K:$K,Ubi!$C:$C,">="&DATE(2025,4,1),Ubi!$C:$C,"<="&DATE(2025,6+1,0),Ubi!$B:$B,"*Adidas*") -> 22995 | D5: =SUMIFS(Ubi!$K:$K,Ubi!$C:$C,">="&DATE(2025,7,1),Ubi!$C:$C,"<="&DATE(2025,9+1,0),Ubi!$B:$B,"*Adidas*") -> 10105 | E5: =SUMIFS(Ubi!$K:$K,Ubi!$C:$C,">="&DATE(2025,10,1),Ubi!$C:$C,"<="&DATE(2025,12+1,0),Ubi!$B:$B,"*Adidas*") -> 4920 | F5: =SUMIFS(Ubi!$K:$K,Ubi!$C:$C,">="&DATE(2026,1,1),Ubi!$C:$C,"<="&DATE(2026,3+1,0),Ubi!$B:$B,"*Adidas*") -> 1806.6667 | G5: =SUMIFS(Ubi!$K:$K,Ubi!$C:$C,">="&DATE(2026,4,1),Ubi!$C:$C,"<="&DATE(2026,6+1,0),Ubi!$B:$B,"*Adidas*") -> 0 | H5: =SUMIFS(Ubi!$K:$K,Ubi!$C:$C,">="&DATE(2026,7,1),Ubi!$C:$C,"<="&DATE(2026,9+1,0),Ubi!$B:$B,"*Adidas*") -> 0 | I5: =SUMIFS(Ubi!$K:$K,Ubi!$C:$C,">="&DATE(2026,10,1),Ubi!$C:$C,"<="&DATE(2026,12+1,0),Ubi!$B:$B,"*Adidas*") -> 0
A6: Red Bull | B6: =SUMIFS(Ubi!$K:$K,Ubi!$C:$C,">="&DATE(2025,1,1),Ubi!$C:$C,"<="&DATE(2025,3+1,0),Ubi!$B:$B,"*Red Bull*") -> 610 | C6: =SUMIFS(Ubi!$K:$K,Ubi!$C:$C,">="&DATE(2025,4,1),Ubi!$C:$C,"<="&DATE(2025,6+1,0),Ubi!$B:$B,"*Red Bull*") -> 0 | D6: =SUMIFS(Ubi!$K:$K,Ubi!$C:$C,">="&DATE(2025,7,1),Ubi!$C:$C,"<="&DATE(2025,9+1,0),Ubi!$B:$B,"*Red Bull*") -> 0 | E6: =SUMIFS(Ubi!$K:$K,Ubi!$C:$C,">="&DATE(2025,10,1),Ubi!$C:$C,"<="&DATE(2025,12+1,0),Ubi!$B:$B,"*Red Bull*") -> 4680 | F6: =SUMIFS(Ubi!$K:$K,Ubi!$C:$C,">="&DATE(2026,1,1),Ubi!$C:$C,"<="&DATE(2026,3+1,0),Ubi!$B:$B,"*Red Bull*") -> 0 | G6: =SUMIFS(Ubi!$K:$K,Ubi!$C:$C,">="&DATE(2026,4,1),Ubi!$C:$C,"<="&DATE(2026,6+1,0),Ubi!$B:$B,"*Red Bull*") -> 0 | H6: =SUMIFS(Ubi!$K:$K,Ubi!$C:$C,">="&DATE(2026,7,1),Ubi!$C:$C,"<="&DATE(2026,9+1,0),Ubi!$B:$B,"*Red Bull*") -> 0 | I6: =SUMIFS(Ubi!$K:$K,Ubi!$C:$C,">="&DATE(2026,10,1),Ubi!$C:$C,"<="&DATE(2026,12+1,0),Ubi!$B:$B,"*Red Bull*") -> 0
A7: LEGO | B7: =SUMIFS(Ubi!$K:$K,Ubi!$C:$C,">="&DATE(2025,1,1),Ubi!$C:$C,"<="&DATE(2025,3+1,0),Ubi!$B:$B,"*LEGO*") -> 185 | C7: =SUMIFS(Ubi!$K:$K,Ubi!$C:$C,">="&DATE(2025,4,1),Ubi!$C:$C,"<="&DATE(2025,6+1,0),Ubi!$B:$B,"*LEGO*") -> 2520 | D7: =SUMIFS(Ubi!$K:$K,Ubi!$C:$C,">="&DATE(2025,7,1),Ubi!$C:$C,"<="&DATE(2025,9+1,0),Ubi!$B:$B,"*LEGO*") -> 4515 | E7: =SUMIFS(Ubi!$K:$K,Ubi!$C:$C,">="&DATE(2025,10,1),Ubi!$C:$C,"<="&DATE(2025,12+1,0),Ubi!$B:$B,"*LEGO*") -> 0 | F7: =SUMIFS(Ubi!$K:$K,Ubi!$C:$C,">="&DATE(2026,1,1),Ubi!$C:$C,"<="&DATE(2026,3+1,0),Ubi!$B:$B,"*LEGO*") -> 0 | G7: =SUMIFS(Ubi!$K:$K,Ubi!$C:$C,">="&DATE(2026,4,1),Ubi!$C:$C,"<="&DATE(2026,6+1,0),Ubi!$B:$B,"*LEGO*") -> 0 | H7: =SUMIFS(Ubi!$K:$K,Ubi!$C:$C,">="&DATE(2026,7,1),Ubi!$C:$C,"<="&DATE(2026,9+1,0),Ubi!$B:$B,"*LEGO*") -> 0 | I7: =SUMIFS(Ubi!$K:$K,Ubi!$C:$C,">="&DATE(2026,10,1),Ubi!$C:$C,"<="&DATE(2026,12+1,0),Ubi!$B:$B,"*LEGO*") -> 0
A8: Ubisoft | B8: =SUMIFS(Ubi!$K:$K,Ubi!$C:$C,">="&DATE(2025,1,1),Ubi!$C:$C,"<="&DATE(2025,3+1,0),Ubi!$B:$B,"*Ubisoft*")+SUMIFS(Ubi!$K:$K,Ubi!$C:$C,">="&DATE(2025,1,1),Ubi!$C:$C,"<="&DATE(2025,3+1,0),Ubi!$B:$B,"UBI") -> 450 | C8: =SUMIFS(Ubi!$K:$K,Ubi!$C:$C,">="&DATE(2025,4,1),Ubi!$C:$C,"<="&DATE(2025,6+1,0),Ubi!$B:$B,"*Ubisoft*")+SUMIFS(Ubi!$K:$K,Ubi!$C:$C,">="&DATE(2025,4,1),Ubi!$C:$C,"<="&DATE(2025,6+1,0),Ubi!$B:$B,"UBI") -> 1365 | D8: =SUMIFS(Ubi!$K:$K,Ubi!$C:$C,">="&DATE(2025,7,1),Ubi!$C:$C,"<="&DATE(2025,9+1,0),Ubi!$B:$B,"*Ubisoft*")+SUMIFS(Ubi!$K:$K,Ubi!$C:$C,">="&DATE(2025,7,1),Ubi!$C:$C,"<="&DATE(2025,9+1,0),Ubi!$B:$B,"UBI") -> 0 | E8: =SUMIFS(Ubi!$K:$K,Ubi!$C:$C,">="&DATE(2025,10,1),Ubi!$C:$C,"<="&DATE(2025,12+1,0),Ubi!$B:$B,"*Ubisoft*")+SUMIFS(Ubi!$K:$K,Ubi!$C:$C,">="&DATE(2025,10,1),Ubi!$C:$C,"<="&DATE(2025,12+1,0),Ubi!$B:$B,"UBI") -> 740 | F8: =SUMIFS(Ubi!$K:$K,Ubi!$C:$C,">="&DATE(2026,1,1),Ubi!$C:$C,"<="&DATE(2026,3+1,0),Ubi!$B:$B,"*Ubisoft*")+SUMIFS(Ubi!$K:$K,Ubi!$C:$C,">="&DATE(2026,1,1),Ubi!$C:$C,"<="&DATE(2026,3+1,0),Ubi!$B:$B,"UBI") -> 0 | G8: =SUMIFS(Ubi!$K:$K,Ubi!$C:$C,">="&DATE(2026,4,1),Ubi!$C:$C,"<="&DATE(2026,6+1,0),Ubi!$B:$B,"*Ubisoft*")+SUMIFS(Ubi!$K:$K,Ubi!$C:$C,">="&DATE(2026,4,1),Ubi!$C:$C,"<="&DATE(2026,6+1,0),Ubi!$B:$B,"UBI") -> 0 | H8: =SUMIFS(Ubi!$K:$K,Ubi!$C:$C,">="&DATE(2026,7,1),Ubi!$C:$C,"<="&DATE(2026,9+1,0),Ubi!$B:$B,"*Ubisoft*")+SUMIFS(Ubi!$K:$K,Ubi!$C:$C,">="&DATE(2026,7,1),Ubi!$C:$C,"<="&DATE(2026,9+1,0),Ubi!$B:$B,"UBI") -> 0 | I8: =SUMIFS(Ubi!$K:$K,Ubi!$C:$C,">="&DATE(2026,10,1),Ubi!$C:$C,"<="&DATE(2026,12+1,0),Ubi!$B:$B,"*Ubisoft*")+SUMIFS(Ubi!$K:$K,Ubi!$C:$C,">="&DATE(2026,10,1),Ubi!$C:$C,"<="&DATE(2026,12+1,0),Ubi!$B:$B,"UBI") -> 0
A9: Perrier | B9: =SUMIFS(Ubi!$K:$K,Ubi!$C:$C,">="&DATE(2025,1,1),Ubi!$C:$C,"<="&DATE(2025,3+1,0),Ubi!$B:$B,"*Perrier*") -> 0 | C9: =SUMIFS(Ubi!$K:$K,Ubi!$C:$C,">="&DATE(2025,4,1),Ubi!$C:$C,"<="&DATE(2025,6+1,0),Ubi!$B:$B,"*Perrier*") -> 1130 | D9: =SUMIFS(Ubi!$K:$K,Ubi!$C:$C,">="&DATE(2025,7,1),Ubi!$C:$C,"<="&DATE(2025,9+1,0),Ubi!$B:$B,"*Perrier*") -> 0 | E9: =SUMIFS(Ubi!$K:$K,Ubi!$C:$C,">="&DATE(2025,10,1),Ubi!$C:$C,"<="&DATE(2025,12+1,0),Ubi!$B:$B,"*Perrier*") -> 0 | F9: =SUMIFS(Ubi!$K:$K,Ubi!$C:$C,">="&DATE(2026,1,1),Ubi!$C:$C,"<="&DATE(2026,3+1,0),Ubi!$B:$B,"*Perrier*") -> 0 | G9: =SUMIFS(Ubi!$K:$K,Ubi!$C:$C,">="&DATE(2026,4,1),Ubi!$C:$C,"<="&DATE(2026,6+1,0),Ubi!$B:$B,"*Perrier*") -> 0 | H9: =SUMIFS(Ubi!$K:$K,Ubi!$C:$C,">="&DATE(2026,7,1),Ubi!$C:$C,"<="&DATE(2026,9+1,0),Ubi!$B:$B,"*Perrier*") -> 0 | I9: =SUMIFS(Ubi!$K:$K,Ubi!$C:$C,">="&DATE(2026,10,1),Ubi!$C:$C,"<="&DATE(2026,12+1,0),Ubi!$B:$B,"*Perrier*") -> 0
A10: IKEA | B10: =SUMIFS(Ubi!$K:$K,Ubi!$C:$C,">="&DATE(2025,1,1),Ubi!$C:$C,"<="&DATE(2025,3+1,0),Ubi!$B:$B,"*IKEA*") -> 0 | C10: =SUMIFS(Ubi!$K:$K,Ubi!$C:$C,">="&DATE(2025,4,1),Ubi!$C:$C,"<="&DATE(2025,6+1,0),Ubi!$B:$B,"*IKEA*") -> 0 | D10: =SUMIFS(Ubi!$K:$K,Ubi!$C:$C,">="&DATE(2025,7,1),Ubi!$C:$C,"<="&DATE(2025,9+1,0),Ubi!$B:$B,"*IKEA*") -> 6950 | E10: =SUMIFS(Ubi!$K:$K,Ubi!$C:$C,">="&DATE(2025,10,1),Ubi!$C:$C,"<="&DATE(2025,12+1,0),Ubi!$B:$B,"*IKEA*") -> 2700 | F10: =SUMIFS(Ubi!$K:$K,Ubi!$C:$C,">="&DATE(2026,1,1),Ubi!$C:$C,"<="&DATE(2026,3+1,0),Ubi!$B:$B,"*IKEA*") -> 0 | G10: =SUMIFS(Ubi!$K:$K,Ubi!$C:$C,">="&DATE(2026,4,1),Ubi!$C:$C,"<="&DATE(2026,6+1,0),Ubi!$B:$B,"*IKEA*") -> 0 | H10: =SUMIFS(Ubi!$K:$K,Ubi!$C:$C,">="&DATE(2026,7,1),Ubi!$C:$C,"<="&DATE(2026,9+1,0),Ubi!$B:$B,"*IKEA*") -> 0 | I10: =SUMIFS(Ubi!$K:$K,Ubi!$C:$C,">="&DATE(2026,10,1),Ubi!$C:$C,"<="&DATE(2026,12+1,0),Ubi!$B:$B,"*IKEA*") -> 0
A11: L'Oréal | B11: =SUMIFS(Ubi!$K:$K,Ubi!$C:$C,">="&DATE(2025,1,1),Ubi!$C:$C,"<="&DATE(2025,3+1,0),Ubi!$B:$B,"*L'Oréal*") -> 0 | C11: =SUMIFS(Ubi!$K:$K,Ubi!$C:$C,">="&DATE(2025,4,1),Ubi!$C:$C,"<="&DATE(2025,6+1,0),Ubi!$B:$B,"*L'Oréal*") -> 0 | D11: =SUMIFS(Ubi!$K:$K,Ubi!$C:$C,">="&DATE(2025,7,1),Ubi!$C:$C,"<="&DATE(2025,9+1,0),Ubi!$B:$B,"*L'Oréal*") -> 3390 | E11: =SUMIFS(Ubi!$K:$K,Ubi!$C:$C,">="&DATE(2025,10,1),Ubi!$C:$C,"<="&DATE(2025,12+1,0),Ubi!$B:$B,"*L'Oréal*") -> 0 | F11: =SUMIFS(Ubi!$K:$K,Ubi!$C:$C,">="&DATE(2026,1,1),Ubi!$C:$C,"<="&DATE(2026,3+1,0),Ubi!$B:$B,"*L'Oréal*") -> 0 | G11: =SUMIFS(Ubi!$K:$K,Ubi!$C:$C,">="&DATE(2026,4,1),Ubi!$C:$C,"<="&DATE(2026,6+1,0),Ubi!$B:$B,"*L'Oréal*") -> 0 | H11: =SUMIFS(Ubi!$K:$K,Ubi!$C:$C,">="&DATE(2026,7,1),Ubi!$C:$C,"<="&DATE(2026,9+1,0),Ubi!$B:$B,"*L'Oréal*") -> 0 | I11: =SUMIFS(Ubi!$K:$K,Ubi!$C:$C,">="&DATE(2026,10,1),Ubi!$C:$C,"<="&DATE(2026,12+1,0),Ubi!$B:$B,"*L'Oréal*") -> 0
A12: TikTok | B12: =SUMIFS(Ubi!$K:$K,Ubi!$C:$C,">="&DATE(2025,1,1),Ubi!$C:$C,"<="&DATE(2025,3+1,0),Ubi!$B:$B,"*TikTok*") -> 0 | C12: =SUMIFS(Ubi!$K:$K,Ubi!$C:$C,">="&DATE(2025,4,1),Ubi!$C:$C,"<="&DATE(2025,6+1,0),Ubi!$B:$B,"*TikTok*") -> 0 | D12: =SUMIFS(Ubi!$K:$K,Ubi!$C:$C,">="&DATE(2025,7,1),Ubi!$C:$C,"<="&DATE(2025,9+1,0),Ubi!$B:$B,"*TikTok*") -> 0 | E12: =SUMIFS(Ubi!$K:$K,Ubi!$C:$C,">="&DATE(2025,10,1),Ubi!$C:$C,"<="&DATE(2025,12+1,0),Ubi!$B:$B,"*TikTok*") -> 9800 | F12: =SUMIFS(Ubi!$K:$K,Ubi!$C:$C,">="&DATE(2026,1,1),Ubi!$C:$C,"<="&DATE(2026,3+1,0),Ubi!$B:$B,"*TikTok*") -> 0 | G12: =SUMIFS(Ubi!$K:$K,Ubi!$C:$C,">="&DATE(2026,4,1),Ubi!$C:$C,"<="&DATE(2026,6+1,0),Ubi!$B:$B,"*TikTok*") -> 0 | H12: =SUMIFS(Ubi!$K:$K,Ubi!$C:$C,">="&DATE(2026,7,1),Ubi!$C:$C,"<="&DATE(2026,9+1,0),Ubi!$B:$B,"*TikTok*") -> 0 | I12: =SUMIFS(Ubi!$K:$K,Ubi!$C:$C,">="&DATE(2026,10,1),Ubi!$C:$C,"<="&DATE(2026,12+1,0),Ubi!$B:$B,"*TikTok*") -> 0
A13: Barilla | B13: =SUMIFS(Ubi!$K:$K,Ubi!$C:$C,">="&DATE(2025,1,1),Ubi!$C:$C,"<="&DATE(2025,3+1,0),Ubi!$B:$B,"*Barilla*") -> 0 | C13: =SUMIFS(Ubi!$K:$K,Ubi!$C:$C,">="&DATE(2025,4,1),Ubi!$C:$C,"<="&DATE(2025,6+1,0),Ubi!$B:$B,"*Barilla*") -> 0 | D13: =SUMIFS(Ubi!$K:$K,Ubi!$C:$C,">="&DATE(2025,7,1),Ubi!$C:$C,"<="&DATE(2025,9+1,0),Ubi!$B:$B,"*Barilla*") -> 0 | E13: =SUMIFS(Ubi!$K:$K,Ubi!$C:$C,">="&DATE(2025,10,1),Ubi!$C:$C,"<="&DATE(2025,12+1,0),Ubi!$B:$B,"*Barilla*") -> 165 | F13: =SUMIFS(Ubi!$K:$K,Ubi!$C:$C,">="&DATE(2026,1,1),Ubi!$C:$C,"<="&DATE(2026,3+1,0),Ubi!$B:$B,"*Barilla*") -> 0 | G13: =SUMIFS(Ubi!$K:$K,Ubi!$C:$C,">="&DATE(2026,4,1),Ubi!$C:$C,"<="&DATE(2026,6+1,0),Ubi!$B:$B,"*Barilla*") -> 0 | H13: =SUMIFS(Ubi!$K:$K,Ubi!$C:$C,">="&DATE(2026,7,1),Ubi!$C:$C,"<="&DATE(2026,9+1,0),Ubi!$B:$B,"*Barilla*") -> 0 | I13: =SUMIFS(Ubi!$K:$K,Ubi!$C:$C,">="&DATE(2026,10,1),Ubi!$C:$C,"<="&DATE(2026,12+1,0),Ubi!$B:$B,"*Barilla*") -> 0
A14: TOTAL | B14: =SUM(B5:B13) -> 9005 | C14: =SUM(C5:C13) -> 28010 | D14: =SUM(D5:D13) -> 24960 | E14: =SUM(E5:E13) -> 23005 | F14: =SUM(F5:F13) -> 1806.6667 | G14: =SUM(G5:G13) -> 0 | H14: =SUM(H5:H13) -> 0 | I14: =SUM(I5:I13) -> 0
A16: NOMBRE DE PROJETS | B16: 2025 | F16: 2026
B17: Q1 | C17: Q2 | D17: Q3 | E17: Q4 | F17: Q1 | G17: Q2 | H17: Q3 | I17: Q4
A18: Adidas | B18: =COUNTIFS(Ubi!$C:$C,">="&DATE(2025,1,1),Ubi!$C:$C,"<="&DATE(2025,3+1,0),Ubi!$B:$B,"*Adidas*") -> 13 | C18: =COUNTIFS(Ubi!$C:$C,">="&DATE(2025,4,1),Ubi!$C:$C,"<="&DATE(2025,6+1,0),Ubi!$B:$B,"*Adidas*") -> 43 | D18: =COUNTIFS(Ubi!$C:$C,">="&DATE(2025,7,1),Ubi!$C:$C,"<="&DATE(2025,9+1,0),Ubi!$B:$B,"*Adidas*") -> 11 | E18: =COUNTIFS(Ubi!$C:$C,">="&DATE(2025,10,1),Ubi!$C:$C,"<="&DATE(2025,12+1,0),Ubi!$B:$B,"*Adidas*") -> 8 | F18: =COUNTIFS(Ubi!$C:$C,">="&DATE(2026,1,1),Ubi!$C:$C,"<="&DATE(2026,3+1,0),Ubi!$B:$B,"*Adidas*") -> 11 | G18: =COUNTIFS(Ubi!$C:$C,">="&DATE(2026,4,1),Ubi!$C:$C,"<="&DATE(2026,6+1,0),Ubi!$B:$B,"*Adidas*") -> 0 | H18: =COUNTIFS(Ubi!$C:$C,">="&DATE(2026,7,1),Ubi!$C:$C,"<="&DATE(2026,9+1,0),Ubi!$B:$B,"*Adidas*") -> 0 | I18: =COUNTIFS(Ubi!$C:$C,">="&DATE(2026,10,1),Ubi!$C:$C,"<="&DATE(2026,12+1,0),Ubi!$B:$B,"*Adidas*") -> 0
A19: Red Bull | B19: =COUNTIFS(Ubi!$C:$C,">="&DATE(2025,1,1),Ubi!$C:$C,"<="&DATE(2025,3+1,0),Ubi!$B:$B,"*Red Bull*") -> 2 | C19: =COUNTIFS(Ubi!$C:$C,">="&DATE(2025,4,1),Ubi!$C:$C,"<="&DATE(2025,6+1,0),Ubi!$B:$B,"*Red Bull*") -> 0 | D19: =COUNTIFS(Ubi!$C:$C,">="&DATE(2025,7,1),Ubi!$C:$C,"<="&DATE(2025,9+1,0),Ubi!$B:$B,"*Red Bull*") -> 0 | E19: =COUNTIFS(Ubi!$C:$C,">="&DATE(2025,10,1),Ubi!$C:$C,"<="&DATE(2025,12+1,0),Ubi!$B:$B,"*Red Bull*") -> 1 | F19: =COUNTIFS(Ubi!$C:$C,">="&DATE(2026,1,1),Ubi!$C:$C,"<="&DATE(2026,3+1,0),Ubi!$B:$B,"*Red Bull*") -> 0 | G19: =COUNTIFS(Ubi!$C:$C,">="&DATE(2026,4,1),Ubi!$C:$C,"<="&DATE(2026,6+1,0),Ubi!$B:$B,"*Red Bull*") -> 0 | H19: =COUNTIFS(Ubi!$C:$C,">="&DATE(2026,7,1),Ubi!$C:$C,"<="&DATE(2026,9+1,0),Ubi!$B:$B,"*Red Bull*") -> 0 | I19: =COUNTIFS(Ubi!$C:$C,">="&DATE(2026,10,1),Ubi!$C:$C,"<="&DATE(2026,12+1,0),Ubi!$B:$B,"*Red Bull*") -> 0
A20: LEGO | B20: =COUNTIFS(Ubi!$C:$C,">="&DATE(2025,1,1),Ubi!$C:$C,"<="&DATE(2025,3+1,0),Ubi!$B:$B,"*LEGO*") -> 1 | C20: =COUNTIFS(Ubi!$C:$C,">="&DATE(2025,4,1),Ubi!$C:$C,"<="&DATE(2025,6+1,0),Ubi!$B:$B,"*LEGO*") -> 7 | D20: =COUNTIFS(Ubi!$C:$C,">="&DATE(2025,7,1),Ubi!$C:$C,"<="&DATE(2025,9+1,0),Ubi!$B:$B,"*LEGO*") -> 4 | E20: =COUNTIFS(Ubi!$C:$C,">="&DATE(2025,10,1),Ubi!$C:$C,"<="&DATE(2025,12+1,0),Ubi!$B:$B,"*LEGO*") -> 0 | F20: =COUNTIFS(Ubi!$C:$C,">="&DATE(2026,1,1),Ubi!$C:$C,"<="&DATE(2026,3+1,0),Ubi!$B:$B,"*LEGO*") -> 0 | G20: =COUNTIFS(Ubi!$C:$C,">="&DATE(2026,4,1),Ubi!$C:$C,"<="&DATE(2026,6+1,0),Ubi!$B:$B,"*LEGO*") -> 0 | H20: =COUNTIFS(Ubi!$C:$C,">="&DATE(2026,7,1),Ubi!$C:$C,"<="&DATE(2026,9+1,0),Ubi!$B:$B,"*LEGO*") -> 0 | I20: =COUNTIFS(Ubi!$C:$C,">="&DATE(2026,10,1),Ubi!$C:$C,"<="&DATE(2026,12+1,0),Ubi!$B:$B,"*LEGO*") -> 0
A21: Ubisoft | B21: =COUNTIFS(Ubi!$C:$C,">="&DATE(2025,1,1),Ubi!$C:$C,"<="&DATE(2025,3+1,0),Ubi!$B:$B,"*Ubisoft*")+COUNTIFS(Ubi!$C:$C,">="&DATE(2025,1,1),Ubi!$C:$C,"<="&DATE(2025,3+1,0),Ubi!$B:$B,"UBI") -> 2 | C21: =COUNTIFS(Ubi!$C:$C,">="&DATE(2025,4,1),Ubi!$C:$C,"<="&DATE(2025,6+1,0),Ubi!$B:$B,"*Ubisoft*")+COUNTIFS(Ubi!$C:$C,">="&DATE(2025,4,1),Ubi!$C:$C,"<="&DATE(2025,6+1,0),Ubi!$B:$B,"UBI") -> 7 | D21: =COUNTIFS(Ubi!$C:$C,">="&DATE(2025,7,1),Ubi!$C:$C,"<="&DATE(2025,9+1,0),Ubi!$B:$B,"*Ubisoft*")+COUNTIFS(Ubi!$C:$C,">="&DATE(2025,7,1),Ubi!$C:$C,"<="&DATE(2025,9+1,0),Ubi!$B:$B,"UBI") -> 0 | E21: =COUNTIFS(Ubi!$C:$C,">="&DATE(2025,10,1),Ubi!$C:$C,"<="&DATE(2025,12+1,0),Ubi!$B:$B,"*Ubisoft*")+COUNTIFS(Ubi!$C:$C,">="&DATE(2025,10,1),Ubi!$C:$C,"<="&DATE(2025,12+1,0),Ubi!$B:$B,"UBI") -> 2 | F21: =COUNTIFS(Ubi!$C:$C,">="&DATE(2026,1,1),Ubi!$C:$C,"<="&DATE(2026,3+1,0),Ubi!$B:$B,"*Ubisoft*")+COUNTIFS(Ubi!$C:$C,">="&DATE(2026,1,1),Ubi!$C:$C,"<="&DATE(2026,3+1,0),Ubi!$B:$B,"UBI") -> 0 | G21: =COUNTIFS(Ubi!$C:$C,">="&DATE(2026,4,1),Ubi!$C:$C,"<="&DATE(2026,6+1,0),Ubi!$B:$B,"*Ubisoft*")+COUNTIFS(Ubi!$C:$C,">="&DATE(2026,4,1),Ubi!$C:$C,"<="&DATE(2026,6+1,0),Ubi!$B:$B,"UBI") -> 0 | H21: =COUNTIFS(Ubi!$C:$C,">="&DATE(2026,7,1),Ubi!$C:$C,"<="&DATE(2026,9+1,0),Ubi!$B:$B,"*Ubisoft*")+COUNTIFS(Ubi!$C:$C,">="&DATE(2026,7,1),Ubi!$C:$C,"<="&DATE(2026,9+1,0),Ubi!$B:$B,"UBI") -> 0 | I21: =COUNTIFS(Ubi!$C:$C,">="&DATE(2026,10,1),Ubi!$C:$C,"<="&DATE(2026,12+1,0),Ubi!$B:$B,"*Ubisoft*")+COUNTIFS(Ubi!$C:$C,">="&DATE(2026,10,1),Ubi!$C:$C,"<="&DATE(2026,12+1,0),Ubi!$B:$B,"UBI") -> 0
A22: Perrier | B22: =COUNTIFS(Ubi!$C:$C,">="&DATE(2025,1,1),Ubi!$C:$C,"<="&DATE(2025,3+1,0),Ubi!$B:$B,"*Perrier*") -> 0 | C22: =COUNTIFS(Ubi!$C:$C,">="&DATE(2025,4,1),Ubi!$C:$C,"<="&DATE(2025,6+1,0),Ubi!$B:$B,"*Perrier*") -> 4 | D22: =COUNTIFS(Ubi!$C:$C,">="&DATE(2025,7,1),Ubi!$C:$C,"<="&DATE(2025,9+1,0),Ubi!$B:$B,"*Perrier*") -> 0 | E22: =COUNTIFS(Ubi!$C:$C,">="&DATE(2025,10,1),Ubi!$C:$C,"<="&DATE(2025,12+1,0),Ubi!$B:$B,"*Perrier*") -> 0 | F22: =COUNTIFS(Ubi!$C:$C,">="&DATE(2026,1,1),Ubi!$C:$C,"<="&DATE(2026,3+1,0),Ubi!$B:$B,"*Perrier*") -> 0 | G22: =COUNTIFS(Ubi!$C:$C,">="&DATE(2026,4,1),Ubi!$C:$C,"<="&DATE(2026,6+1,0),Ubi!$B:$B,"*Perrier*") -> 0 | H22: =COUNTIFS(Ubi!$C:$C,">="&DATE(2026,7,1),Ubi!$C:$C,"<="&DATE(2026,9+1,0),Ubi!$B:$B,"*Perrier*") -> 0 | I22: =COUNTIFS(Ubi!$C:$C,">="&DATE(2026,10,1),Ubi!$C:$C,"<="&DATE(2026,12+1,0),Ubi!$B:$B,"*Perrier*") -> 0
A23: IKEA | B23: =COUNTIFS(Ubi!$C:$C,">="&DATE(2025,1,1),Ubi!$C:$C,"<="&DATE(2025,3+1,0),Ubi!$B:$B,"*IKEA*") -> 0 | C23: =COUNTIFS(Ubi!$C:$C,">="&DATE(2025,4,1),Ubi!$C:$C,"<="&DATE(2025,6+1,0),Ubi!$B:$B,"*IKEA*") -> 0 | D23: =COUNTIFS(Ubi!$C:$C,">="&DATE(2025,7,1),Ubi!$C:$C,"<="&DATE(2025,9+1,0),Ubi!$B:$B,"*IKEA*") -> 9 | E23: =COUNTIFS(Ubi!$C:$C,">="&DATE(2025,10,1),Ubi!$C:$C,"<="&DATE(2025,12+1,0),Ubi!$B:$B,"*IKEA*") -> 1 | F23: =COUNTIFS(Ubi!$C:$C,">="&DATE(2026,1,1),Ubi!$C:$C,"<="&DATE(2026,3+1,0),Ubi!$B:$B,"*IKEA*") -> 0 | G23: =COUNTIFS(Ubi!$C:$C,">="&DATE(2026,4,1),Ubi!$C:$C,"<="&DATE(2026,6+1,0),Ubi!$B:$B,"*IKEA*") -> 0 | H23: =COUNTIFS(Ubi!$C:$C,">="&DATE(2026,7,1),Ubi!$C:$C,"<="&DATE(2026,9+1,0),Ubi!$B:$B,"*IKEA*") -> 0 | I23: =COUNTIFS(Ubi!$C:$C,">="&DATE(2026,10,1),Ubi!$C:$C,"<="&DATE(2026,12+1,0),Ubi!$B:$B,"*IKEA*") -> 0
A24: L'Oréal | B24: =COUNTIFS(Ubi!$C:$C,">="&DATE(2025,1,1),Ubi!$C:$C,"<="&DATE(2025,3+1,0),Ubi!$B:$B,"*L'Oréal*") -> 0 | C24: =COUNTIFS(Ubi!$C:$C,">="&DATE(2025,4,1),Ubi!$C:$C,"<="&DATE(2025,6+1,0),Ubi!$B:$B,"*L'Oréal*") -> 0 | D24: =COUNTIFS(Ubi!$C:$C,">="&DATE(2025,7,1),Ubi!$C:$C,"<="&DATE(2025,9+1,0),Ubi!$B:$B,"*L'Oréal*") -> 2 | E24: =COUNTIFS(Ubi!$C:$C,">="&DATE(2025,10,1),Ubi!$C:$C,"<="&DATE(2025,12+1,0),Ubi!$B:$B,"*L'Oréal*") -> 0 | F24: =COUNTIFS(Ubi!$C:$C,">="&DATE(2026,1,1),Ubi!$C:$C,"<="&DATE(2026,3+1,0),Ubi!$B:$B,"*L'Oréal*") -> 0 | G24: =COUNTIFS(Ubi!$C:$C,">="&DATE(2026,4,1),Ubi!$C:$C,"<="&DATE(2026,6+1,0),Ubi!$B:$B,"*L'Oréal*") -> 0 | H24: =COUNTIFS(Ubi!$C:$C,">="&DATE(2026,7,1),Ubi!$C:$C,"<="&DATE(2026,9+1,0),Ubi!$B:$B,"*L'Oréal*") -> 0 | I24: =COUNTIFS(Ubi!$C:$C,">="&DATE(2026,10,1),Ubi!$C:$C,"<="&DATE(2026,12+1,0),Ubi!$B:$B,"*L'Oréal*") -> 0
A25: TikTok | B25: =COUNTIFS(Ubi!$C:$C,">="&DATE(2025,1,1),Ubi!$C:$C,"<="&DATE(2025,3+1,0),Ubi!$B:$B,"*TikTok*") -> 0 | C25: =COUNTIFS(Ubi!$C:$C,">="&DATE(2025,4,1),Ubi!$C:$C,"<="&DATE(2025,6+1,0),Ubi!$B:$B,"*TikTok*") -> 0 | D25: =COUNTIFS(Ubi!$C:$C,">="&DATE(2025,7,1),Ubi!$C:$C,"<="&DATE(2025,9+1,0),Ubi!$B:$B,"*TikTok*") -> 0 | E25: =COUNTIFS(Ubi!$C:$C,">="&DATE(2025,10,1),Ubi!$C:$C,"<="&DATE(2025,12+1,0),Ubi!$B:$B,"*TikTok*") -> 1 | F25: =COUNTIFS(Ubi!$C:$C,">="&DATE(2026,1,1),Ubi!$C:$C,"<="&DATE(2026,3+1,0),Ubi!$B:$B,"*TikTok*") -> 0 | G25: =COUNTIFS(Ubi!$C:$C,">="&DATE(2026,4,1),Ubi!$C:$C,"<="&DATE(2026,6+1,0),Ubi!$B:$B,"*TikTok*") -> 0 | H25: =COUNTIFS(Ubi!$C:$C,">="&DATE(2026,7,1),Ubi!$C:$C,"<="&DATE(2026,9+1,0),Ubi!$B:$B,"*TikTok*") -> 0 | I25: =COUNTIFS(Ubi!$C:$C,">="&DATE(2026,10,1),Ubi!$C:$C,"<="&DATE(2026,12+1,0),Ubi!$B:$B,"*TikTok*") -> 0
A26: Barilla | B26: =COUNTIFS(Ubi!$C:$C,">="&DATE(2025,1,1),Ubi!$C:$C,"<="&DATE(2025,3+1,0),Ubi!$B:$B,"*Barilla*") -> 0 | C26: =COUNTIFS(Ubi!$C:$C,">="&DATE(2025,4,1),Ubi!$C:$C,"<="&DATE(2025,6+1,0),Ubi!$B:$B,"*Barilla*") -> 0 | D26: =COUNTIFS(Ubi!$C:$C,">="&DATE(2025,7,1),Ubi!$C:$C,"<="&DATE(2025,9+1,0),Ubi!$B:$B,"*Barilla*") -> 0 | E26: =COUNTIFS(Ubi!$C:$C,">="&DATE(2025,10,1),Ubi!$C:$C,"<="&DATE(2025,12+1,0),Ubi!$B:$B,"*Barilla*") -> 1 | F26: =COUNTIFS(Ubi!$C:$C,">="&DATE(2026,1,1),Ubi!$C:$C,"<="&DATE(2026,3+1,0),Ubi!$B:$B,"*Barilla*") -> 1 | G26: =COUNTIFS(Ubi!$C:$C,">="&DATE(2026,4,1),Ubi!$C:$C,"<="&DATE(2026,6+1,0),Ubi!$B:$B,"*Barilla*") -> 0 | H26: =COUNTIFS(Ubi!$C:$C,">="&DATE(2026,7,1),Ubi!$C:$C,"<="&DATE(2026,9+1,0),Ubi!$B:$B,"*Barilla*") -> 0 | I26: =COUNTIFS(Ubi!$C:$C,">="&DATE(2026,10,1),Ubi!$C:$C,"<="&DATE(2026,12+1,0),Ubi!$B:$B,"*Barilla*") -> 0
A27: TOTAL | B27: =SUM(B18:B26) -> 18 | C27: =SUM(C18:C26) -> 61 | D27: =SUM(D18:D26) -> 26 | E27: =SUM(E18:E26) -> 14 | F27: =SUM(F18:F26) -> 12 | G27: =SUM(G18:G26) -> 0 | H27: =SUM(H18:H26) -> 0 | I27: =SUM(I18:I26) -> 0
A29: SYNTHÈSE ANNUELLE | B29: 2025 | C29: 2026
A30: Revenus (€) | B30: =SUM(B14:E14) -> 84980 | C30: =SUM(F14:I14) -> 1806.6667
A31: Projets | B31: =SUM(B27:E27) -> 119 | C31: =SUM(F27:I27) -> 12
A32: Rev. / Projet (€) | B32: =IFERROR(B30/B31,"—") -> 714.11765 | C32: =IFERROR(C30/C31,"—") -> 150.55556

Sheet Ubi
K1: =SUBTOTAL(2,K6:K19661) -> 131 | Q1: =SUBTOTAL(2,Q6:Q19661) -> 50 | R1: =SUBTOTAL(2,R6:R19661) -> 87 | S1: =SUBTOTAL(2,S6:S19661) -> 30 | T1: =SUBTOTAL(2,T6:T19661) -> 0 | U1: =SUBTOTAL(2,U6:U19661) -> 0 | V1: =SUBTOTAL(2,V6:V19661) -> 0 | W1: =SUBTOTAL(2,W6:W19661) -> 0 | X1: =SUBTOTAL(2,X6:X19661) -> 4 | ... AW1: =SUBTOTAL(2,AW6:AW19661) -> 0
J2: =SUBTOTAL(9,J6:J19662) -> 2687 | K2: =SUBTOTAL(9,K6:K19662) -> 104446.67 | Q2: =SUBTOTAL(9,Q6:Q19662)*Q5 -> 15525 | R2: =SUBTOTAL(9,R6:R19662)*R5 -> 36480 | S2: =SUBTOTAL(9,S6:S19662)*S5 -> 6930 | T2: =SUBTOTAL(9,T6:T19662)*T5 -> 0 | U2: =SUBTOTAL(9,U6:U19662)*U5 -> 0 | V2: =SUBTOTAL(9,V6:V19662)*V5 -> 0 | W2: =SUBTOTAL(9,W6:W19662)*W5 -> 0 | X2: =SUBTOTAL(9,X6:X19662)*X5 -> 2000 | ... AW2: =SUBTOTAL(9,AW6:AW19662)*AW5 -> 0
A3: Tracker Projet | Q3: Online | Y3: Offline | AE3: PreEnvoyéeations | AF3: Web | AJ3: Videos | AS3: Virtualization | AU3: Copy
A4: Projet | F4: Facturation fin de mois | Q4: Création de concepts simples et bannières online (KV, statique) | R4: Adaptations de bannières à partir d'une créa existante (statique) | S4: Déclis d'adaptations (eg: naming, etc.) (statique) | T4: Création de bannières (KV, animée) | U4: Adaptations de bannières à partir d'une créa existante (animées) | V4: Boutons, Icônes | W4: Logo | X4: Rendering 3D d'image lifesyles | Y4: Création de bannières print (KV, statique) | Z4: Adaptations de bannières à partir d'une créa existante (statique) | AA4: Leaflet (1 page) | AB4: Leaflet (2 pages) | AC4: Kakemonos / Murs de stands | AD4: Brochure (20 pages) | AE4: Powerpoint / Google Slides (par slide) | AF4: Newsletter / Landing page (design) | AG4: Newsletter / Landing page (design et implémentation technique) | AH4: Site web (design only) | AI4: Site web (complet) | AJ4: Edition Vidéo simple (sous-titres, bande son, cuts, etc) | AK4: Edition Vidéo avancée (animation over footage) | AL4: Social Media Video (motion, 30s) | AM4: Social Media Video (motion, 1min) | AN4: Sizzles (avec scripts, voix, etc.) | AO4: Vidéo Promotionnelle | AP4: Vidéo 2D | AQ4: Vidéo 3D | AR4: Tournage vidéo avec crew, équipement, lieux, etc. | AS4: Espace Virtuel Interactif | AT4: Showroom Virtuel Interactif | AU4: Traduction (par mot) | AV4: Copywriting (par mot)
A5: Client | B5: Division | C5: Date | D5: Projet | E5: Code Projet | F5: Contact | G5: Statut | H5: Catégorie | I5: Lien Projet | J5: NB Assets | K5: Valeur Totale | L5: Devis | M5: Numéro de PO | N5: Facture | O5: N°Facture | P5: Statut paiement | Q5: 135 | R5: 30 | S5: 10 | T5: 220 | U5: 60 | V5: 15 | W5: 250 | X5: 500 | Y5: 150 | Z5: 35 | AA5: 180 | AB5: 260 | AC5: 250 | AD5: 2000 | AE5: 30 | AF5: 500 | AG5: 650 | AH5: 3500 | AI5: Au projet | AJ5: 80 | AK5: 150 | AL5: 360 | AM5: 460 | AN5: 900 | AO5: 3500 | AP5: Au projet | AQ5: Au projet | AR5: Au projet | AS5: 2500 | AT5: Au projet | AU5: 0.12 | AV5: 0.25
A6: Ubi | B6: Adidas | C6: 45726 | D6: adidas – ADR25 | E6: ADR25 | F6: Clara BONVARLET | G6: Delivered | H6: Exe | I6: https://saranistudio.sharepoint.com/:f:/s/SaraniAssets/Ej6RkjRw02BJv-pEIjZ9w8ABf_Ap6iR_TAA7SAMLrFeAkQ?e=N2LmRH | J6: =IF(SUM(Q6:AW6)=0,"-",SUM(Q6:AW6)) -> 17 | K6: =IF(SUMPRODUCT($Q$5:$AW$5,Q6:AW6)=0,"-",SUMPRODUCT($Q$5:$AW$5,Q6:AW6)) -> 560 | L6: - | M6: - | N6: Envoyé via Whatsapp | O6: F2025-0217 | P6: Paid 15/05/2025 | R6: 16 | AJ6: 1
A7: Ubi | B7: Red Bull | C7: 45727 | D7: ubi - KV Red Bull Wings For Life - RED06 | E7: Red06 | F7: Jeremy LE NILLON | G7: Delivered | H7: Exe | I7: 20250311_KV Red Bull Wings For Life - RED06 | J7: =IF(SUM(Q7:AW7)=0,"-",SUM(Q7:AW7)) -> 15 | K7: =IF(SUMPRODUCT($Q$5:$AW$5,Q7:AW7)=0,"-",SUMPRODUCT($Q$5:$AW$5,Q7:AW7)) -> 450 | L7: - | M7: - | N7: Envoyé via Whatsapp | O7: F2025-0217 | P7: Paid 15/05/2025 | R7: 15
A8: Ubi | B8: LEGO | C8: 45727 | D8: LEG02 : Brief affiche LEGO Le grand tournoi des Champs | E8: LEG02 | F8: Louis Keller | G8: Delivered | H8: Exe | I8: 20250311_Brief affiche LEGO Le grand tournoi des Champs | J8: =IF(SUM(Q8:AW8)=0,"-",SUM(Q8:AW8)) -> 2 | K8: =IF(SUMPRODUCT($Q$5:$AW$5,Q8:AW8)=0,"-",SUMPRODUCT($Q$5:$AW$5,Q8:AW8)) -> 185 | L8: - | M8: - | N8: Envoyé via Whatsapp | O8: F2025-0217 | P8: Paid 15/05/2025 | Y8: 1 | Z8: 1
A9: Ubi | B9: Adidas | C9: 45729 | D9: ADTAT / Flocage textile | E9: ADTAT | F9: Anouck Mottin | G9: Delivered | H9: Exe | I9: https://saranistudio.sharepoint.com/:f:/s/SaraniAssets/Evyqkra13wJEhdYuMBCPa2QBkbIgZr9J3lqx8bYghiqmoA?e=MHdPnX | J9: =IF(SUM(Q9:AW9)=0,"-",SUM(Q9:AW9)) -> 4 | K9: =IF(SUMPRODUCT($Q$5:$AW$5,Q9:AW9)=0,"-",SUMPRODUCT($Q$5:$AW$5,Q9:AW9)) -> 140 | L9: - | M9: - | N9: Envoyé via Whatsapp | O9: F2025-0217 | P9: Paid 15/05/2025 | Z9: 4
A10: Ubi | B10: Adidas | C10: 45729 | D10: Adidas Supercomfort Weekend | E10: ADR25 | F10: Louis Keller | G10: Delivered | H10: Special | I10: https://saranistudio.sharepoint.com/:f:/s/SaraniAssets/EspVANpg4GpEs0PP-J6C5s0B_G6DnxosVSFNUMyaSioBiA?e=z5gPK5 | J10: =IF(SUM(Q10:AW10)=0,"-",SUM(Q10:AW10)) -> 126 | K10: =IF(SUMPRODUCT($Q$5:$AW$5,Q10:AW10)=0,"-",SUMPRODUCT($Q$5:$AW$5,Q10:AW10)) -> 2705 | L10: - | M10: - | N10: Envoyé via Whatsapp | O10: F2025-0218 | P10: Paid 15/05/2025 | Q10: 1 | R10: =46+20 -> 66 | S10: =7+4+3+7+14+7+5+5+7 -> 59
A11: Ubi | B11: Adidas | C11: 45729 | D11: Testings adidas retail – ADRET | E11: ADRET | F11: Clara BONVARLET | G11: Delivered | H11: Exe | I11: https://saranistudio.sharepoint.com/:f:/s/SaraniAssets/Eh0MoH_-2zZEv5a97CjnsRYBBxAk1CdKecRZGQvFQGvgdA?e=k6fI4G | J11: =IF(SUM(Q11:AW11)=0,"-",SUM(Q11:AW11)) -> 5 | K11: =IF(SUMPRODUCT($Q$5:$AW$5,Q11:AW11)=0,"-",SUMPRODUCT($Q$5:$AW$5,Q11:AW11)) -> 150 | L11: - | M11: - | N11: Envoyé via Whatsapp | O11: F2025-0217 | P11: Paid 15/05/2025 | R11: 5
A12: Ubi | B12: Red Bull | C12: 45729 | D12: KV Red Bull Wings For Life - Video | E12: Red06 | F12: Jeremy LE NILLON | G12: Delivered | H12: Exe | I12: https://saranistudio.sharepoint.com/:f:/s/SaraniAssets/EuvKLKORCGNJnpFQDCWR1jMBK3-s4VKysfwEu23qPL0jrA?e=0n9yYC | J12: =IF(SUM(Q12:AW12)=0,"-",SUM(Q12:AW12)) -> 2 | K12: =IF(SUMPRODUCT($Q$5:$AW$5,Q12:AW12)=0,"-",SUMPRODUCT($Q$5:$AW$5,Q12:AW12)) -> 160 | L12: - | M12: - | N12: Envoyé via Whatsapp | O12: F2025-0217 | P12: Paid 15/05/2025 | AJ12: 2
A13: Ubi | B13: Ubisoft | C13: 45730 | D13: Graveur de Pierre Ubisoft | E13: UBI02 | F13: Inès de Laguiche | G13: Delivered | H13: Exe | I13: https://saranistudio.sharepoint.com/:f:/s/SaraniAssets/EswSC5pPpsBNpvHBnzBp7iYBgaH2yzxCR5ZiDBri_V5cTA?e=M8VcRE | J13: =IF(SUM(Q13:AW13)=0,"-",SUM(Q13:AW13)) -> 2 | K13: =IF(SUMPRODUCT($Q$5:$AW$5,Q13:AW13)=0,"-",SUMPRODUCT($Q$5:$AW$5,Q13:AW13)) -> 165 | L13: - | M13: - | N13: Envoyé via Whatsapp | O13: F2025-0217 | P13: Paid 15/05/2025 | Q13: 1 | R13: 1
A14: Ubi | B14: Adidas | C14: 45730 | D14: Branding magasins adidas - ADMAR | E14: ADMAR | F14: Jeremy LE NILLON | G14: Delivered | H14: Exe | I14: https://saranistudio.sharepoint.com/:f:/s/SaraniAssets/Ekt9En4iqM1PjHyA0QwiYp8B5ZpUPIhXgluIK9b7cUxooA?e=CSgTjt | J14: =IF(SUM(Q14:AW14)=0,"-",SUM(Q14:AW14)) -> 12 | K14: =IF(SUMPRODUCT($Q$5:$AW$5,Q14:AW14)=0,"-",SUMPRODUCT($Q$5:$AW$5,Q14:AW14)) -> 780 | L14: - | M14: - | N14: Envoyé via Whatsapp | O14: F2025-0217 | P14: Paid 15/05/2025 | Q14: =4 -> 4 | R14: 8
A15: Ubi | B15: Adidas | C15: 45730 | D15: Stand Marathon adidas - ADM25 | E15: ADM25 | F15: Jeremy LE NILLON | G15: Delivered | H15: Special | I15: https://saranistudio.sharepoint.com/:f:/s/SaraniAssets/Epa8vTKpudRIg5uy_lvnMaIBKLkQT4JXzXd8cYngVnroxA?e=PNydg2 | J15: =IF(SUM(Q15:AW15)=0,"-",SUM(Q15:AW15)) -> 96 | K15: =IF(SUMPRODUCT($Q$5:$AW$5,Q15:AW15)=0,"-",SUMPRODUCT($Q$5:$AW$5,Q15:AW15)) -> 2490 | L15: - | M15: - | N15: Envoyé via Whatsapp | O15: F2025-0218 | P15: Paid 15/05/2025 | R15: =3+10+18+3+29+10 -> 73 | S15: =2+20 -> 22 | AJ15: 1
A16: Ubi | B16: Adidas | C16: 45731 | D16: Plp Hub | E16: ADR25 | F16: Clara BONVARLET | G16: Delivered | H16: Exe | I16: https://saranistudio.sharepoint.com/:f:/s/SaraniAssets/EtTNbkr4dSZFi3TkNEoWuigB73I9k0Ta2TiWc538sv5Gng?e=HzKCVC | J16: =IF(SUM(Q16:AW16)=0,"-",SUM(Q16:AW16)) -> 6 | K16: =IF(SUMPRODUCT($Q$5:$AW$5,Q16:AW16)=0,"-",SUMPRODUCT($Q$5:$AW$5,Q16:AW16)) -> 180 | L16: - | M16: - | N16: Envoyé via Whatsapp | O16: F2025-0217 | P16: Paid 15/05/2025 | R16: 6
A17: Ubi | B17: Adidas | C17: 45741 | D17: Calendrier hebdo Instagram - ADU25 | E17: ADU25 | F17: Clara BONVARLET | G17: Delivered | H17: Exe | I17: https://saranistudio.sharepoint.com/:f:/s/SaraniAssets/EgQrdWCWPFZEkywkgCCVUIEBIddLpyi7r_OGT6myK3K6PA?e=eexic0 | J17: =IF(SUM(Q17:AW17)=0,"-",SUM(Q17:AW17)) -> 8 | K17: =IF(SUMPRODUCT($Q$5:$AW$5,Q17:AW17)=0,"-",SUMPRODUCT($Q$5:$AW$5,Q17:AW17)) -> 345 | L17: - | M17: - | N17: Envoyé via Whatsapp | O17: F2025-0217 | P17: Paid 15/05/2025 | Q17: 1 | R17: 7
A18: Ubi | B18: Adidas | C18: 45742 | D18: Seeding kit | E18: ADR25 | F18: Clara BONVARLET | G18: Delivered | H18: Créa | I18: 20250326_SEEDING KIT | J18: =IF(SUM(Q18:AW18)=0,"-",SUM(Q18:AW18)) -> 1 | K18: Concept Offert | L18: - | M18: - | N18: - | O18: - | P18: - | X18: 1
A19: Ubi | B19: Adidas | C19: 45742 | D19: ADRET / Créas adidas Retail | E19: ADRET | F19: Clara BONVARLET | G19: Delivered | H19: Exe | I19: https://saranistudio.sharepoint.com/:f:/s/SaraniAssets/Eka3DWx13PhPoPbjhloykp8BENQBYxhjzw3qTWiwYKJv0A?e=AhpWxX | J19: =IF(SUM(Q19:AW19)=0,"-",SUM(Q19:AW19)) -> 2 | K19: =IF(SUMPRODUCT($Q$5:$AW$5,Q19:AW19)=0,"-",SUMPRODUCT($Q$5:$AW$5,Q19:AW19)) -> 60 | L19: - | M19: - | N19: Envoyé via Whatsapp | O19: F2025-0217 | P19: Paid 15/05/2025 | R19: 2
A20: Ubi | B20: Ubisoft | C20: 45742 | D20: Ubisoft - boîtes personnalisées et cire parchemins | E20: UBI02 | F20: Inès de Laguiche | G20: Delivered | H20: Exe | I20: 20250326_Ubisoft - boîtes personnalisées | J20: =IF(SUM(Q20:AW20)=0,"-",SUM(Q20:AW20)) -> 6 | K20: =IF(SUMPRODUCT($Q$5:$AW$5,Q20:AW20)=0,"-",SUMPRODUCT($Q$5:$AW$5,Q20:AW20)) -> 285 | L20: - | M20: - | N20: Envoyé via Whatsapp | O20: F2025-0217 | P20: Paid 15/05/2025 | Q20: 1 | R20: 5
A21: Ubi | B21: Adidas | C21: 45743 | D21: ADTAT / Brief oriflammes | E21: ADTAT | F21: Anouck MOTTIN | G21: Delivered | H21: Exe | I21: 20250327_ADTAT - Brief oriflammes | J21: =IF(SUM(Q21:AW21)=0,"-",SUM(Q21:AW21)) -> 2 | K21: =IF(SUMPRODUCT($Q$5:$AW$5,Q21:AW21)=0,"-",SUMPRODUCT($Q$5:$AW$5,Q21:AW21)) -> 60 | L21: - | M21: - | N21: Envoyé via Whatsapp | O21: F2025-0217 | P21: Paid 15/05/2025 | R21: 2
A22: Ubi | B22: Adidas | C22: 45743 | D22: ubi - calendriers Facebook + KV - ADU25 | E22: ADU25 | F22: DROUET Pauline | G22: Delivered | H22: Exe | I22: https://saranistudio.sharepoint.com/:f:/s/SaraniAssets/Et1YZpnGo6xGk_xA-N7mRfMB-fqEThZxNt4zaIzuAVy_sg?e=P89yDW | J22: =IF(SUM(Q22:AW22)=0,"-",SUM(Q22:AW22)) -> 1 | K22: =IF(SUMPRODUCT($Q$5:$AW$5,Q22:AW22)=0,"-",SUMPRODUCT($Q$5:$AW$5,Q22:AW22)) -> 180 | L22: - | M22: - | N22: Envoyée | O22: F2025-0254 | P22: Paid 06/06/2025 | AA22: 1
A23: Ubi | B23: Adidas | C23: 45743 | D23: ADR25 / Créas adidas Brand | E23: ADR25 | F23: Clara BONVARLET | G23: Delivered | H23: Exe | I23: https://saranistudio.sharepoint.com/:f:/s/SaraniAssets/Elk4CkEUM01Ao4tt53VE974BI8_2FTp9DC-yO8ShCT11Lw?e=cgryAD | J23: =IF(SUM(Q23:AW23)=0,"-",SUM(Q23:AW23)) -> 2 | K23: =IF(SUMPRODUCT($Q$5:$AW$5,Q23:AW23)=0,"-",SUMPRODUCT($Q$5:$AW$5,Q23:AW23)) -> 110 | L23: - | M23: - | N23: Envoyé via Whatsapp | O23: F2025-0217 | P23: Paid 15/05/2025 | R23: 1 | AJ23: 1
A24: Ubi | B24: Adidas | C24: 45748 | D24: Sticker Adizero | E24: ADR25 | F24: Clara BONVARLET | G24: Delivered | H24: Exe | I24: https://saranistudio.sharepoint.com/:f:/s/SaraniAssets/EtGyAL-3rTdDmtFlPJybmpYBaroSTyRhVAXNRGshEpzIzQ?e=Obzxog | J24: =IF(SUM(Q24:AW24)=0,"-",SUM(Q24:AW24)) -> 1 | K24: =IF(SUMPRODUCT($Q$5:$AW$5,Q24:AW24)=0,"-",SUMPRODUCT($Q$5:$AW$5,Q24:AW24)) -> 30 | L24: - | M24: - | N24: Envoyée | O24: F2025-0254 | P24: Paid 06/06/2025 | R24: 1
A25: Ubi | B25: Ubisoft | C25: 45748 | D25: Créa Ubisoft 2.0 | E25: UBI02 | F25: Inès de Laguiche | G25: Delivered | H25: Exe | I25: https://saranistudio.sharepoint.com/:f:/s/SaraniAssets/EijnPi44YxZNk-dDVMyMxrkBKXrw34OtgTISSkEdq4vt4w?e=CAexvj | J25: =IF(SUM(Q25:AW25)=0,"-",SUM(Q25:AW25)) -> 3 | K25: =IF(SUMPRODUCT($Q$5:$AW$5,Q25:AW25)=0,"-",SUMPRODUCT($Q$5:$AW$5,Q25:AW25)) -> 105 | L25: - | M25: - | N25: Envoyée | O25: F2025-0254 | P25: Paid 06/06/2025 | Z25: 3
A26: Ubi | B26: Ubisoft | C26: 45748 | D26: CREA UBISOFT 3 | E26: UBI02 | F26: Inès de Laguiche | G26: Delivered | H26: Exe | I26: https://saranistudio.sharepoint.com/:f:/s/SaraniAssets/EkrVaENSDiBCilmmpkVVlWEBQk1GeDWmDw0I5jFz0fX--A?e=3GXKUR | J26: =IF(SUM(Q26:AW26)=0,"-",SUM(Q26:AW26)) -> 5 | K26: =IF(SUMPRODUCT($Q$5:$AW$5,Q26:AW26)=0,"-",SUMPRODUCT($Q$5:$AW$5,Q26:AW26)) -> 400 | L26: - | M26: - | N26: Envoyée | O26: F2025-0254 | P26: Paid 06/06/2025 | Z26: 4 | AB26: 1
A27: Ubi | B27: Adidas | C27: 45749 | D27: ADRET / Créas adidas Retail | E27: ADRET | F27: CLARA-BONVARLET | G27: Delivered | H27: Exe | I27: 20250302_ADRET - Créas adidas Retail | J27: =IF(SUM(Q27:AW27)=0,"-",SUM(Q27:AW27)) -> 1 | K27: =IF(SUMPRODUCT($Q$5:$AW$5,Q27:AW27)=0,"-",SUMPRODUCT($Q$5:$AW$5,Q27:AW27)) -> 135 | L27: - | M27: - | N27: Envoyée | O27: F2025-0254 | P27: Paid 06/06/2025 | Q27: 1
A28: Ubi | B28: Adidas | C28: 45750 | D28: Adidas 10K - ADR25 | E28: ADR25 | F28: CLARA-BONVARLET | G28: Delivered | H28: Exe | I28: 20250403_ADIDAS 10K | J28: =IF(SUM(Q28:AW28)=0,"-",SUM(Q28:AW28)) -> 5 | K28: =IF(SUMPRODUCT($Q$5:$AW$5,Q28:AW28)=0,"-",SUMPRODUCT($Q$5:$AW$5,Q28:AW28)) -> 155 | L28: - | M28: - | N28: Envoyée | O28: F2025-0254 | P28: Paid 06/06/2025 | R28: 4 | Z28: 1
A29: Ubi | B29: Ubisoft | C29: 45751 | D29: Création de dossiers de chaise personnalisés | E29: UBI02 | F29: INÈS DE LAGUICHE | G29: Delivered | H29: Exe | I29: 20250404_création de dossiers de chaise personnalisés | J29: =IF(SUM(Q29:AW29)=0,"-",SUM(Q29:AW29)) -> 1 | K29: =IF(SUMPRODUCT($Q$5:$AW$5,Q29:AW29)=0,"-",SUMPRODUCT($Q$5:$AW$5,Q29:AW29)) -> 30 | L29: - | M29: - | N29: Envoyée | O29: F2025-0254 | P29: Paid 06/06/2025 | R29: 1
A30: Ubi | B30: Adidas | C30: 45754 | D30: ADO25 - Exe adidas originals showroom (Exe uniquement) | E30: ADO25 | F30: MARIE DELGRANGE | G30: Delivered | H30: Exe | I30: 20250404_ADO25 - Exe adidas originals showroom | J30: =IF(SUM(Q30:AW30)=0,"-",SUM(Q30:AW30)) -> 26 | K30: =IF(SUMPRODUCT($Q$5:$AW$5,Q30:AW30)=0,"-",SUMPRODUCT($Q$5:$AW$5,Q30:AW30)) -> 760 | L30: - | M30: - | N30: Envoyée | O30: F2025-0254 | P30: Paid 06/06/2025 | Q30: 4 | S30: 22
A31: Ubi | B31: Adidas | C31: 45754 | D31: ADU25 - Urgence stickers | E31: ADU25 | F31: DROUET Pauline | G31: Delivered | H31: Exe | I31: https://saranistudio.sharepoint.com/:f:/s/SaraniAssets/EmH0-A8nCTtNia70gCbO2lIB2mLpLDiGgCMmmotWvly__A?e=LblSqQ | J31: =IF(SUM(Q31:AW31)=0,"-",SUM(Q31:AW31)) -> 1 | K31: =IF(SUMPRODUCT($Q$5:$AW$5,Q31:AW31)=0,"-",SUMPRODUCT($Q$5:$AW$5,Q31:AW31)) -> 30 | L31: - | M31: - | N31: Envoyée | O31: F2025-0254 | P31: Paid 06/06/2025 | R31: 1
A32: Ubi | B32: Adidas | C32: 45754 | D32: ADTLD / demandes créas | E32: ATTLD | F32: CLARA-BONVARLET | G32: Delivered | H32: Exe | I32: https://saranistudio.sharepoint.com/:f:/s/SaraniAssets/EivsIogcYXJDlu049X2ZJ3wBoVsL-oLt-gorNZ7wk8z36Q?e=XhKG3e | J32: =IF(SUM(Q32:AW32)=0,"-",SUM(Q32:AW32)) -> 6 | K32: =IF(SUMPRODUCT($Q$5:$AW$5,Q32:AW32)=0,"-",SUMPRODUCT($Q$5:$AW$5,Q32:AW32)) -> 285 | L32: - | M32: - | N32: Envoyée | O32: F2025-0254 | P32: Paid 06/06/2025 | Q32: 1 | R32: 5
A33: Ubi | B33: Adidas | C33: 45754 | D33: Adidas 10K custom gift | E33: ADR25 | F33: CLARA-BONVARLET | G33: Delivered | H33: Créa | I33: https://saranistudio.sharepoint.com/:f:/s/SaraniAssets/EkwkV8YCxw9DoN-6W3d8Y40B0YO3ktRfoSp5gPiMZn_r3g?e=m0BnIB | J33: 3 | K33: =IF(SUMPRODUCT($Q$5:$AW$5,Q33:AW33)=0,"-",SUMPRODUCT($Q$5:$AW$5,Q33:AW33)) -> 405 | L33: - | M33: - | N33: Envoyée | O33: F2025-0254 | P33: Paid 06/06/2025 | Q33: 3
A34: Ubi | B34: Adidas | C34: 45754 | D34: Seeding kit Exé | E34: ADR25 | F34: Clara BONVARLET | G34: Delivered | H34: Exe | I34: 20250326_SEEDING KIT | J34: =IF(SUM(Q34:AW34)=0,"-",SUM(Q34:AW34)) -> 63 | K34: =IF(SUMPRODUCT($Q$5:$AW$5,Q34:AW34)=0,"-",SUMPRODUCT($Q$5:$AW$5,Q34:AW34)) -> 1635 | N34: Envoyée | O34: F2025-0316 | P34: Paid 21/07/2025 | Q34: 3 | R34: 7 | S34: 52 | X34: 1
A35: Ubi | B35: Adidas | C35: 45762 | D35: BRIEF Adidas Testing before tasting | E35: ADR25 | F35: Louis KELLER | G35: Delivered | H35: Special | I35: 20250415_BRIEF Adidas Testing before tasting | J35: =IF(SUM(Q35:AW35)=0,"-",SUM(Q35:AW35)) -> 37 | K35: =IF(SUMPRODUCT($Q$5:$AW$5,Q35:AW35)=0,"-",SUMPRODUCT($Q$5:$AW$5,Q35:AW35)) -> 770 | L35: - | M35: - | N35: Envoyée | O35: F2025-0254 | P35: Paid 06/06/2025 | R35: 20 | S35: 17
A36: Ubi | B36: Ubisoft | C36: 45762 | D36: Demande urgente nouveau drapeau | E36: UBI02 | F36: INÈS DE LAGUICHE | G36: Delivered | H36: Exe | I36: https://saranistudio.sharepoint.com/:f:/s/SaraniAssets/EqN-VbwAEzxLt8dI9bxAhL0BDMANZz9z9o9706t-nElyRw?e=WC6cnP | J36: =IF(SUM(Q36:AW36)=0,"-",SUM(Q36:AW36)) -> 1 | K36: =IF(SUMPRODUCT($Q$5:$AW$5,Q36:AW36)=0,"-",SUMPRODUCT($Q$5:$AW$5,Q36:AW36)) -> 30 | L36: - | M36: - | N36: Envoyée | O36: F2025-0254 | P36: Paid 06/06/2025 | R36: 1
A37: Ubi | B37: Adidas | C37: 45763 | D37: Adidas 10K Après course concept | E37: ADR25 | F37: CLARA-BONVARLET | G37: Delivered | H37: Exe | I37: https://saranistudio.sharepoint.com/:f:/s/SaraniAssets/EmR8ktNWJplImqGX_AZgTDUB-qwnT2ZpJ0COt3mm7O5ODw?e=OAW5eO | J37: =IF(SUM(Q37:AW37)=0,"-",SUM(Q37:AW37)) -> 1 | K37: =IF(SUMPRODUCT($Q$5:$AW$5,Q37:AW37)=0,"-",SUMPRODUCT($Q$5:$AW$5,Q37:AW37)) -> 135 | L37: - | M37: - | N37: Envoyée | O37: F2025-0254 | P37: Paid 06/06/2025 | Q37: 1
A38: Ubi | B38: Adidas | C38: 45763 | D38: Adidas 10K Retraits dossards | E38: ADR25 | F38: CLARA-BONVARLET | G38: Delivered | H38: Exe | I38: https://saranistudio.sharepoint.com/:f:/s/SaraniAssets/Euv4WdeFGLJNug8wvC-YPrMBP7k8zO0-QCOLso0JUyu_0w?e=E3WeEX | J38: =IF(SUM(Q38:AW38)=0,"-",SUM(Q38:AW38)) -> 6 | K38: =IF(SUMPRODUCT($Q$5:$AW$5,Q38:AW38)=0,"-",SUMPRODUCT($Q$5:$AW$5,Q38:AW38)) -> 285 | L38: - | M38: - | N38: Envoyée | O38: F2025-0254 | P38: Paid 06/06/2025 | Q38: 1 | R38: 5
A39: Ubi | B39: Adidas | C39: 45763 | D39: Créas Brand | E39: ADR25 | F39: CLARA-BONVARLET | G39: Delivered | H39: Exe | I39: 20250417_Créas Brand | J39: =IF(SUM(Q39:AW39)=0,"-",SUM(Q39:AW39)) -> 19 | K39: =IF(SUMPRODUCT($Q$5:$AW$5,Q39:AW39)=0,"-",SUMPRODUCT($Q$5:$AW$5,Q39:AW39)) -> 570 | L39: - | M39: - | N39: Envoyée | O39: F2025-0254 | P39: Paid 06/06/2025 | R39: 19
A40: Ubi | B40: Adidas | C40: 45764 | D40: ADU25 / Exes Wings for life | E40: ADU25 | F40: Anouck MOTTIN | G40: Delivered | H40: Exe | I40: 20250417_ADU25 - Exes Wings for life | J40: =IF(SUM(Q40:AW40)=0,"-",SUM(Q40:AW40)) -> 24 | K40: =IF(SUMPRODUCT($Q$5:$AW$5,Q40:AW40)=0,"-",SUMPRODUCT($Q$5:$AW$5,Q40:AW40)) -> 720 | L40: - | M40: - | N40: Envoyée | O40: F2025-0254 | P40: Paid 06/06/2025 | R40: 24
...
