Workbook

Sheet Overview
A1: Performance Dashboard — Aujan
A3: REVENUS (€) | B3: 2025 | F3: 2026
B4: Q1 | C4: Q2 | D4: Q3 | E4: Q4 | F4: Q1 | G4: Q2 | H4: Q3 | I4: Q4
A5: Rani | B5: =SUMIFS(AUJAN!$K:$K,AUJAN!$B:$B,"Rani",AUJAN!$C:$C,">="&DATE(2025,1,1),AUJAN!$C:$C,"<="&DATE(2025,3,31)) -> 0 | C5: =SUMIFS(AUJAN!$K:$K,AUJAN!$B:$B,"Rani",AUJAN!$C:$C,">="&DATE(2025,4,1),AUJAN!$C:$C,"<="&DATE(2025,6,30)) -> 9885 | D5: =SUMIFS(AUJAN!$K:$K,AUJAN!$B:$B,"Rani",AUJAN!$C:$C,">="&DATE(2025,7,1),AUJAN!$C:$C,"<="&DATE(2025,9,30)) -> 7615 | E5: =SUMIFS(AUJAN!$K:$K,AUJAN!$B:$B,"Rani",AUJAN!$C:$C,">="&DATE(2025,10,1),AUJAN!$C:$C,"<="&DATE(2025,12,31)) -> 2775 | F5: =SUMIFS(AUJAN!$K:$K,AUJAN!$B:$B,"Rani",AUJAN!$C:$C,">="&DATE(2026,1,1),AUJAN!$C:$C,"<="&DATE(2026,3,31)) -> 1365 | G5: =SUMIFS(AUJAN!$K:$K,AUJAN!$B:$B,"Rani",AUJAN!$C:$C,">="&DATE(2026,4,1),AUJAN!$C:$C,"<="&DATE(2026,6,30)) -> 0 | H5: =SUMIFS(AUJAN!$K:$K,AUJAN!$B:$B,"Rani",AUJAN!$C:$C,">="&DATE(2026,7,1),AUJAN!$C:$C,"<="&DATE(2026,9,30)) -> 0 | I5: =SUMIFS(AUJAN!$K:$K,AUJAN!$B:$B,"Rani",AUJAN!$C:$C,">="&DATE(2026,10,1),AUJAN!$C:$C,"<="&DATE(2026,12,31)) -> 0
A6: Vimto | B6: =SUMIFS(AUJAN!$K:$K,AUJAN!$B:$B,"Vimto",AUJAN!$C:$C,">="&DATE(2025,1,1),AUJAN!$C:$C,"<="&DATE(2025,3,31)) -> 0 | C6: =SUMIFS(AUJAN!$K:$K,AUJAN!$B:$B,"Vimto",AUJAN!$C:$C,">="&DATE(2025,4,1),AUJAN!$C:$C,"<="&DATE(2025,6,30)) -> 0 | D6: =SUMIFS(AUJAN!$K:$K,AUJAN!$B:$B,"Vimto",AUJAN!$C:$C,">="&DATE(2025,7,1),AUJAN!$C:$C,"<="&DATE(2025,9,30)) -> 245 | E6: =SUMIFS(AUJAN!$K:$K,AUJAN!$B:$B,"Vimto",AUJAN!$C:$C,">="&DATE(2025,10,1),AUJAN!$C:$C,"<="&DATE(2025,12,31)) -> 1615 | F6: =SUMIFS(AUJAN!$K:$K,AUJAN!$B:$B,"Vimto",AUJAN!$C:$C,">="&DATE(2026,1,1),AUJAN!$C:$C,"<="&DATE(2026,3,31)) -> 90 | G6: =SUMIFS(AUJAN!$K:$K,AUJAN!$B:$B,"Vimto",AUJAN!$C:$C,">="&DATE(2026,4,1),AUJAN!$C:$C,"<="&DATE(2026,6,30)) -> 0 | H6: =SUMIFS(AUJAN!$K:$K,AUJAN!$B:$B,"Vimto",AUJAN!$C:$C,">="&DATE(2026,7,1),AUJAN!$C:$C,"<="&DATE(2026,9,30)) -> 0 | I6: =SUMIFS(AUJAN!$K:$K,AUJAN!$B:$B,"Vimto",AUJAN!$C:$C,">="&DATE(2026,10,1),AUJAN!$C:$C,"<="&DATE(2026,12,31)) -> 0
A7: Barbican | B7: =SUMIFS(AUJAN!$K:$K,AUJAN!$B:$B,"Barbican",AUJAN!$C:$C,">="&DATE(2025,1,1),AUJAN!$C:$C,"<="&DATE(2025,3,31)) -> 0 | C7: =SUMIFS(AUJAN!$K:$K,AUJAN!$B:$B,"Barbican",AUJAN!$C:$C,">="&DATE(2025,4,1),AUJAN!$C:$C,"<="&DATE(2025,6,30)) -> 0 | D7: =SUMIFS(AUJAN!$K:$K,AUJAN!$B:$B,"Barbican",AUJAN!$C:$C,">="&DATE(2025,7,1),AUJAN!$C:$C,"<="&DATE(2025,9,30)) -> 810 | E7: =SUMIFS(AUJAN!$K:$K,AUJAN!$B:$B,"Barbican",AUJAN!$C:$C,">="&DATE(2025,10,1),AUJAN!$C:$C,"<="&DATE(2025,12,31)) -> 1050 | F7: =SUMIFS(AUJAN!$K:$K,AUJAN!$B:$B,"Barbican",AUJAN!$C:$C,">="&DATE(2026,1,1),AUJAN!$C:$C,"<="&DATE(2026,3,31)) -> 1060 | G7: =SUMIFS(AUJAN!$K:$K,AUJAN!$B:$B,"Barbican",AUJAN!$C:$C,">="&DATE(2026,4,1),AUJAN!$C:$C,"<="&DATE(2026,6,30)) -> 0 | H7: =SUMIFS(AUJAN!$K:$K,AUJAN!$B:$B,"Barbican",AUJAN!$C:$C,">="&DATE(2026,7,1),AUJAN!$C:$C,"<="&DATE(2026,9,30)) -> 0 | I7: =SUMIFS(AUJAN!$K:$K,AUJAN!$B:$B,"Barbican",AUJAN!$C:$C,">="&DATE(2026,10,1),AUJAN!$C:$C,"<="&DATE(2026,12,31)) -> 0
A8: Rani-Barbican | B8: =SUMIFS(AUJAN!$K:$K,AUJAN!$B:$B,"Rani-Barbican",AUJAN!$C:$C,">="&DATE(2025,1,1),AUJAN!$C:$C,"<="&DATE(2025,3,31)) -> 0 | C8: =SUMIFS(AUJAN!$K:$K,AUJAN!$B:$B,"Rani-Barbican",AUJAN!$C:$C,">="&DATE(2025,4,1),AUJAN!$C:$C,"<="&DATE(2025,6,30)) -> 0 | D8: =SUMIFS(AUJAN!$K:$K,AUJAN!$B:$B,"Rani-Barbican",AUJAN!$C:$C,">="&DATE(2025,7,1),AUJAN!$C:$C,"<="&DATE(2025,9,30)) -> 1400 | E8: =SUMIFS(AUJAN!$K:$K,AUJAN!$B:$B,"Rani-Barbican",AUJAN!$C:$C,">="&DATE(2025,10,1),AUJAN!$C:$C,"<="&DATE(2025,12,31)) -> 180 | F8: =SUMIFS(AUJAN!$K:$K,AUJAN!$B:$B,"Rani-Barbican",AUJAN!$C:$C,">="&DATE(2026,1,1),AUJAN!$C:$C,"<="&DATE(2026,3,31)) -> 0 | G8: =SUMIFS(AUJAN!$K:$K,AUJAN!$B:$B,"Rani-Barbican",AUJAN!$C:$C,">="&DATE(2026,4,1),AUJAN!$C:$C,"<="&DATE(2026,6,30)) -> 0 | H8: =SUMIFS(AUJAN!$K:$K,AUJAN!$B:$B,"Rani-Barbican",AUJAN!$C:$C,">="&DATE(2026,7,1),AUJAN!$C:$C,"<="&DATE(2026,9,30)) -> 0 | I8: =SUMIFS(AUJAN!$K:$K,AUJAN!$B:$B,"Rani-Barbican",AUJAN!$C:$C,">="&DATE(2026,10,1),AUJAN!$C:$C,"<="&DATE(2026,12,31)) -> 0
A9: TOTAL | B9: =SUM(B5:B8) -> 0 | C9: =SUM(C5:C8) -> 9885 | D9: =SUM(D5:D8) -> 10070 | E9: =SUM(E5:E8) -> 5620 | F9: =SUM(F5:F8) -> 2515 | G9: =SUM(G5:G8) -> 0 | H9: =SUM(H5:H8) -> 0 | I9: =SUM(I5:I8) -> 0
A11: NOMBRE DE PROJETS | B11: 2025 | F11: 2026
B12: Q1 | C12: Q2 | D12: Q3 | E12: Q4 | F12: Q1 | G12: Q2 | H12: Q3 | I12: Q4
A13: Rani | B13: =COUNTIFS(AUJAN!$B:$B,"Rani",AUJAN!$C:$C,">="&DATE(2025,1,1),AUJAN!$C:$C,"<="&DATE(2025,3,31)) -> 0 | C13: =COUNTIFS(AUJAN!$B:$B,"Rani",AUJAN!$C:$C,">="&DATE(2025,4,1),AUJAN!$C:$C,"<="&DATE(2025,6,30)) -> 6 | D13: =COUNTIFS(AUJAN!$B:$B,"Rani",AUJAN!$C:$C,">="&DATE(2025,7,1),AUJAN!$C:$C,"<="&DATE(2025,9,30)) -> 14 | E13: =COUNTIFS(AUJAN!$B:$B,"Rani",AUJAN!$C:$C,">="&DATE(2025,10,1),AUJAN!$C:$C,"<="&DATE(2025,12,31)) -> 3 | F13: =COUNTIFS(AUJAN!$B:$B,"Rani",AUJAN!$C:$C,">="&DATE(2026,1,1),AUJAN!$C:$C,"<="&DATE(2026,3,31)) -> 2 | G13: =COUNTIFS(AUJAN!$B:$B,"Rani",AUJAN!$C:$C,">="&DATE(2026,4,1),AUJAN!$C:$C,"<="&DATE(2026,6,30)) -> 0 | H13: =COUNTIFS(AUJAN!$B:$B,"Rani",AUJAN!$C:$C,">="&DATE(2026,7,1),AUJAN!$C:$C,"<="&DATE(2026,9,30)) -> 0 | I13: =COUNTIFS(AUJAN!$B:$B,"Rani",AUJAN!$C:$C,">="&DATE(2026,10,1),AUJAN!$C:$C,"<="&DATE(2026,12,31)) -> 0
A14: Vimto | B14: =COUNTIFS(AUJAN!$B:$B,"Vimto",AUJAN!$C:$C,">="&DATE(2025,1,1),AUJAN!$C:$C,"<="&DATE(2025,3,31)) -> 0 | C14: =COUNTIFS(AUJAN!$B:$B,"Vimto",AUJAN!$C:$C,">="&DATE(2025,4,1),AUJAN!$C:$C,"<="&DATE(2025,6,30)) -> 0 | D14: =COUNTIFS(AUJAN!$B:$B,"Vimto",AUJAN!$C:$C,">="&DATE(2025,7,1),AUJAN!$C:$C,"<="&DATE(2025,9,30)) -> 1 | E14: =COUNTIFS(AUJAN!$B:$B,"Vimto",AUJAN!$C:$C,">="&DATE(2025,10,1),AUJAN!$C:$C,"<="&DATE(2025,12,31)) -> 5 | F14: =COUNTIFS(AUJAN!$B:$B,"Vimto",AUJAN!$C:$C,">="&DATE(2026,1,1),AUJAN!$C:$C,"<="&DATE(2026,3,31)) -> 1 | G14: =COUNTIFS(AUJAN!$B:$B,"Vimto",AUJAN!$C:$C,">="&DATE(2026,4,1),AUJAN!$C:$C,"<="&DATE(2026,6,30)) -> 0 | H14: =COUNTIFS(AUJAN!$B:$B,"Vimto",AUJAN!$C:$C,">="&DATE(2026,7,1),AUJAN!$C:$C,"<="&DATE(2026,9,30)) -> 0 | I14: =COUNTIFS(AUJAN!$B:$B,"Vimto",AUJAN!$C:$C,">="&DATE(2026,10,1),AUJAN!$C:$C,"<="&DATE(2026,12,31)) -> 0
A15: Barbican | B15: =COUNTIFS(AUJAN!$B:$B,"Barbican",AUJAN!$C:$C,">="&DATE(2025,1,1),AUJAN!$C:$C,"<="&DATE(2025,3,31)) -> 0 | C15: =COUNTIFS(AUJAN!$B:$B,"Barbican",AUJAN!$C:$C,">="&DATE(2025,4,1),AUJAN!$C:$C,"<="&DATE(2025,6,30)) -> 0 | D15: =COUNTIFS(AUJAN!$B:$B,"Barbican",AUJAN!$C:$C,">="&DATE(2025,7,1),AUJAN!$C:$C,"<="&DATE(2025,9,30)) -> 2 | E15: =COUNTIFS(AUJAN!$B:$B,"Barbican",AUJAN!$C:$C,">="&DATE(2025,10,1),AUJAN!$C:$C,"<="&DATE(2025,12,31)) -> 4 | F15: =COUNTIFS(AUJAN!$B:$B,"Barbican",AUJAN!$C:$C,">="&DATE(2026,1,1),AUJAN!$C:$C,"<="&DATE(2026,3,31)) -> 2 | G15: =COUNTIFS(AUJAN!$B:$B,"Barbican",AUJAN!$C:$C,">="&DATE(2026,4,1),AUJAN!$C:$C,"<="&DATE(2026,6,30)) -> 0 | H15: =COUNTIFS(AUJAN!$B:$B,"Barbican",AUJAN!$C:$C,">="&DATE(2026,7,1),AUJAN!$C:$C,"<="&DATE(2026,9,30)) -> 0 | I15: =COUNTIFS(AUJAN!$B:$B,"Barbican",AUJAN!$C:$C,">="&DATE(2026,10,1),AUJAN!$C:$C,"<="&DATE(2026,12,31)) -> 0
A16: Rani-Barbican | B16: =COUNTIFS(AUJAN!$B:$B,"Rani-Barbican",AUJAN!$C:$C,">="&DATE(2025,1,1),AUJAN!$C:$C,"<="&DATE(2025,3,31)) -> 0 | C16: =COUNTIFS(AUJAN!$B:$B,"Rani-Barbican",AUJAN!$C:$C,">="&DATE(2025,4,1),AUJAN!$C:$C,"<="&DATE(2025,6,30)) -> 0 | D16: =COUNTIFS(AUJAN!$B:$B,"Rani-Barbican",AUJAN!$C:$C,">="&DATE(2025,7,1),AUJAN!$C:$C,"<="&DATE(2025,9,30)) -> 1 | E16: =COUNTIFS(AUJAN!$B:$B,"Rani-Barbican",AUJAN!$C:$C,">="&DATE(2025,10,1),AUJAN!$C:$C,"<="&DATE(2025,12,31)) -> 1 | F16: =COUNTIFS(AUJAN!$B:$B,"Rani-Barbican",AUJAN!$C:$C,">="&DATE(2026,1,1),AUJAN!$C:$C,"<="&DATE(2026,3,31)) -> 0 | G16: =COUNTIFS(AUJAN!$B:$B,"Rani-Barbican",AUJAN!$C:$C,">="&DATE(2026,4,1),AUJAN!$C:$C,"<="&DATE(2026,6,30)) -> 0 | H16: =COUNTIFS(AUJAN!$B:$B,"Rani-Barbican",AUJAN!$C:$C,">="&DATE(2026,7,1),AUJAN!$C:$C,"<="&DATE(2026,9,30)) -> 0 | I16: =COUNTIFS(AUJAN!$B:$B,"Rani-Barbican",AUJAN!$C:$C,">="&DATE(2026,10,1),AUJAN!$C:$C,"<="&DATE(2026,12,31)) -> 0
A17: TOTAL | B17: =SUM(B13:B16) -> 0 | C17: =SUM(C13:C16) -> 6 | D17: =SUM(D13:D16) -> 18 | E17: =SUM(E13:E16) -> 13 | F17: =SUM(F13:F16) -> 5 | G17: =SUM(G13:G16) -> 0 | H17: =SUM(H13:H16) -> 0 | I17: =SUM(I13:I16) -> 0
A19: SYNTHÈSE ANNUELLE | B19: 2025 | C19: 2026
A20: Revenus ($) | B20: =SUM(B9:E9) -> 25575 | C20: =SUM(F9:I9) -> 2515
A21: Projets | B21: =SUM(B17:E17) -> 37 | C21: =SUM(F17:I17) -> 5
A22: Rev. / Projet ($) | B22: =IFERROR(B20/B21,"—") -> 691.21622 | C22: =IFERROR(C20/C21,"—") -> 503

Sheet AUJAN
A1: Price File | Y1: Online | AG1: Offline | AN1: Presentations | AO1: Web | AS1: Videos | BA1: Virtualization | BC1: Contentful | BG1: Copy
A2: Project | E2: Details | I2: Sent to : accbc.ap-uae@aujan.com | Q2: Graphic Design | R2: Video | S2: Copy | T2: Vidéo Production | U2: Ads | V2: Influence | W2: Part-Time Placement | X2: Others | Y2: Banner creation (static) | Z2: Banner adaptation (static) | AA2: Banner creation (animated) | AB2: Banner adaptation (animated) | AC2: Buttons | AD2: Logo | AE2: Lifestyle Picture | AF2: Wallpapers | AG2: Offline creation (standard) | AH2: Offline creation (adaptation) | AI2: Leaflet (1 page) | AJ2: Leaflet (2 pages) | AK2: Roll-up / Wall creation | AL2: Chart | AM2: Brochure (20 pages) | AN2: Slide | AO2: Landing page (design only) | AP2: Landing page (complete) | AQ2: Website (design only) | AR2: Website (complete) | AS2: Video Edition | AT2: Advanced Edition | AU2: Social Media Video (up to 30s) | AV2: Social Media Video (up to 1 min) | AW2: Sizzles | AX2: Promotional Video (up to 1 min) | AY2: 2D Video (up to 3mn) | AZ2: 3D Video (up to 3min) | BA2: Virtual space | BB2: Virtual showroom | BC2: Case study (per article) | BD2: Blog article (per article) | BE2: Translation (per article) | BF2: Splash (per creation/modification) | BG2: Translation (per word) | BH2: Copywrite (per word)
A3: Customer | B3: Division | C3: Date | D3: Project | E3: Contact | F3: Status | G3: Category | H3: Link | I3: FINAL DELIVERABLE | J3: Assets | K3: Total Value | L3: Quote | M3: PO | N3: Invoice | O3: N° invoice | P3: Status | Y3: 140 | Z3: 35 | AA3: 250 | AB3: 55 | AC3: 20 | AD3: 275 | AE3: 450 | AF3: 90 | AG3: 150 | AH3: 45 | AI3: 200 | AJ3: 280 | AK3: 200 | AL3: 450 | AM3: 2500 | AN3: 35 | AO3: 350 | AP3: 750 | AQ3: 5500 | AR3: 7800 | AS3: 90 | AT3: 165 | AU3: 390 | AV3: 490 | AW3: 690 | AX3: 4500 | AY3: 5500 | AZ3: 10000 | BA3: 2500 | BB3: 10000 | BC3: 38 | BD3: 45 | BE3: 27 | BF3: 18 | BG3: 0.15 | BH3: =0.25*1.08 -> 0.27
A4: Aujan | B4: Rani | C4: 45793 | D4: Rani Trucks - Test Brief | E4: Stephanie Barcena | F4: Delivered | H4: https://saranistudio.sharepoint.com/:f:/s/SaraniAssets/EsQuxyIxO5BIgvXL8TsMtLUB_ypDUfxyl7m8F9RiyKhHgQ?e=bP5jsN | J4: =IF(SUM(W4:BH4)=0,"-",SUM(Y4:BH4)) -> 14 | K4: =IF(SUMPRODUCT($Y$3:$BK$3,Y4:BK4)=0,"-",SUMPRODUCT($Y$3:$BK$3,Y4:BK4)) -> 840 | L4: NOT TO INVOICE | M4: - | N4: - | O4: - | P4: - | Q4: =IF(SUM(Y4:AR4)+SUM(AZ4:BA4)+SUM(BB4:BE4)>0,"X","") -> X | R4: =IF(SUM(AS4:AY4)>0,"X","") | S4: =IF(SUM(BF4:BG4)>0,"X","") | AG4: 2 | AH4: =2+4+6 -> 12
A5: Aujan | B5: Rani | C5: 45811 | D5: Rani 2 new flavour labels | E5: Caitlin | F5: Delivered | H5: https://saranistudio.sharepoint.com/:f:/s/SaraniAssets/Eow6L8gkSwZPkHckRk9ZJlUB4yuU12CfH2Kc-hNxZ3gphA?e=VYjoGM | J5: =IF(SUM(W5:BH5)=0,"-",SUM(Y5:BH5)) -> 2 | K5: =IF(SUMPRODUCT($Y$3:$BK$3,Y5:BK5)=0,"-",SUMPRODUCT($Y$3:$BK$3,Y5:BK5)) -> 300 | L5: NOT TO INVOICE | M5: - | N5: - | O5: - | P5: - | Q5: =IF(SUM(Y5:AR5)+SUM(AZ5:BA5)+SUM(BB5:BE5)>0,"X","") -> X | R5: =IF(SUM(AS5:AY5)>0,"X","") | S5: =IF(SUM(BF5:BG5)>0,"X","") | AG5: 2
A6: Aujan | B6: Rani | C6: 45810 | D6: Rani Fridges and Gondolas rework | E6: Stephanie Barcena | F6: Delivered | H6: https://saranistudio.sharepoint.com/:f:/s/SaraniAssets/EguVe0IdKDVGoJTXuCYt7foBorHxPD4nsa_prnu1uH-GIg?e=DU7eZo | J6: =IF(SUM(W6:BH6)=0,"-",SUM(Y6:BH6)) -> 7 | K6: =IF(SUMPRODUCT($Y$3:$BK$3,Y6:BK6)=0,"-",SUMPRODUCT($Y$3:$BK$3,Y6:BK6)) -> 1050 | L6: https://saranistudio.sharepoint.com/:b:/s/SaraniAssets/ERLzEICCYB9JsOanEIfbsbUB24lTwltStsYbTEJZn-KMAQ?e=BnPlLf | M6: ME25-147 | N6: Sent via Whatsapp | O6: F2025-0552 | P6: Paid 02/03/2026 | Q6: =IF(SUM(Y6:AR6)+SUM(AZ6:BA6)+SUM(BB6:BE6)>0,"X","") -> X | R6: =IF(SUM(AS6:AY6)>0,"X","") | S6: =IF(SUM(BF6:BG6)>0,"X","") | AG6: 7
A7: Aujan | B7: Rani | C7: 45827 | D7: Rani VISID Adapts | E7: Stephanie Barcena | F7: Delivered | H7: https://saranistudio.sharepoint.com/:f:/s/SaraniAssets/EsBS1_0woVdEitBoGPhhZWUBfo0ftCRBa2hE6KgwBFsXXw?e=RW8FD4 | J7: =IF(SUM(W7:BH7)=0,"-",SUM(Y7:BH7)) -> 13 | K7: =IF(SUMPRODUCT($Y$3:$BK$3,Y7:BK7)=0,"-",SUMPRODUCT($Y$3:$BK$3,Y7:BK7)) -> 900 | L7: https://saranistudio.sharepoint.com/:b:/s/SaraniAssets/ERLzEICCYB9JsOanEIfbsbUB24lTwltStsYbTEJZn-KMAQ?e=BnPlLf | M7: ME25-147 | N7: Sent via Whatsapp | O7: F2025-0552 | P7: Paid 02/03/2026 | Q7: =IF(SUM(Y7:AR7)+SUM(AZ7:BA7)+SUM(BB7:BE7)>0,"X","") -> X | R7: =IF(SUM(AS7:AY7)>0,"X","") | S7: =IF(SUM(BF7:BG7)>0,"X","") | AG7: 3 | AH7: 10
A8: Aujan | B8: Rani | C8: 45827 | D8: Rani Leaflet AR-EN | E8: Stephanie Barcena | F8: Delivered | H8: https://saranistudio.sharepoint.com/:f:/s/SaraniAssets/EpeLw_mWqaFAj0mBPCpOmpcBYKlEQysu251hVG6CO1ic2w?e=UmEl9s | J8: =IF(SUM(W8:BH8)=0,"-",SUM(Y8:BH8)) -> 2 | K8: =IF(SUMPRODUCT($Y$3:$BK$3,Y8:BK8)=0,"-",SUMPRODUCT($Y$3:$BK$3,Y8:BK8)) -> 195 | L8: https://saranistudio.sharepoint.com/:b:/s/SaraniAssets/ERLzEICCYB9JsOanEIfbsbUB24lTwltStsYbTEJZn-KMAQ?e=BnPlLf | M8: ME25-147 | N8: Sent via Whatsapp | O8: F2025-0552 | P8: Paid 02/03/2026 | Q8: =IF(SUM(Y8:AR8)+SUM(AZ8:BA8)+SUM(BB8:BE8)>0,"X","") -> X | R8: =IF(SUM(AS8:AY8)>0,"X","") | S8: =IF(SUM(BF8:BG8)>0,"X","") | AG8: 1 | AH8: 1
A9: Aujan | B9: Rani | C9: 45828 | D9: Rani Vis ID | E9: Salaheldin Eissa | F9: Delivered | H9: https://saranistudio.sharepoint.com/:f:/s/SaraniAssets/Ek0CFmQWudJHuGpWpz_mKoIB656cp-vVO5fgfxzDzY3qAw?e=vyLO5M | J9: =IF(SUM(W9:BH9)=0,"-",SUM(Y9:BH9)) -> 84 | K9: =IF(SUMPRODUCT($Y$3:$BK$3,Y9:BK9)=0,"-",SUMPRODUCT($Y$3:$BK$3,Y9:BK9)) -> 6600 | L9: https://saranistudio.sharepoint.com/:b:/s/SaraniAssets/ERLzEICCYB9JsOanEIfbsbUB24lTwltStsYbTEJZn-KMAQ?e=BnPlLf | M9: ME25-147 | N9: Sent via Whatsapp | O9: F2025-0552 | P9: Paid 02/03/2026 | Q9: =IF(SUM(Y9:AR9)+SUM(AZ9:BA9)+SUM(BB9:BE9)>0,"X","") -> X | R9: =IF(SUM(AS9:AY9)>0,"X","") -> X | S9: =IF(SUM(BF9:BG9)>0,"X","") | Z9: 6 | AH9: 14 | AS9: =27+37 -> 64
A10: Aujan | B10: Rani | C10: 45857 | D10: Large Display Format | E10: Stephanie Barcena | F10: Delivered | H10: https://saranistudio.sharepoint.com/:f:/s/SaraniAssets/EnFUfyFK_P5GtBm5YfWYqqMBJ5_bIiBFBxxJzQkvpU2gIQ?e=Cj3g1t | J10: =IF(SUM(W10:BH10)=0,"-",SUM(Y10:BH10)) -> 3 | K10: =IF(SUMPRODUCT($Y$3:$BK$3,Y10:BK10)=0,"-",SUMPRODUCT($Y$3:$BK$3,Y10:BK10)) -> 135 | L10: https://saranistudio.sharepoint.com/:b:/s/SaraniAssets/ERLzEICCYB9JsOanEIfbsbUB24lTwltStsYbTEJZn-KMAQ?e=BnPlLf | M10: ME25-147 | N10: Sent via Whatsapp | O10: F2025-0552 | P10: Paid 02/03/2026 | Q10: =IF(SUM(Y10:AR10)+SUM(AZ10:BA10)+SUM(BB10:BE10)>0,"X","") -> X | R10: =IF(SUM(AS10:AY10)>0,"X","") | S10: =IF(SUM(BF10:BG10)>0,"X","") | AH10: 3
A11: Aujan | B11: Rani | C11: 45859 | D11: Mubashir Specifications | E11: Salaheldin Eissa | F11: Delivered | H11: https://saranistudio.sharepoint.com/:f:/s/SaraniAssets/EuPUOCIgz0RNo_9D5AFzW8wBpOGaQ1gyS55evzi4MshL-A?e=Mpy6bF | J11: =IF(SUM(W11:BH11)=0,"-",SUM(Y11:BH11)) -> 3 | K11: =IF(SUMPRODUCT($Y$3:$BK$3,Y11:BK11)=0,"-",SUMPRODUCT($Y$3:$BK$3,Y11:BK11)) -> 270 | L11: https://saranistudio.sharepoint.com/:b:/s/SaraniAssets/ERLzEICCYB9JsOanEIfbsbUB24lTwltStsYbTEJZn-KMAQ?e=BnPlLf | M11: ME25-147 | N11: Sent via Whatsapp | O11: F2025-0552 | P11: Paid 02/03/2026 | Q11: =IF(SUM(Y11:AR11)+SUM(AZ11:BA11)+SUM(BB11:BE11)>0,"X","") | R11: =IF(SUM(AS11:AY11)>0,"X","") -> X | S11: =IF(SUM(BF11:BG11)>0,"X","") | AS11: 3
A12: Aujan | B12: Rani | C12: 45861 | D12: RANI / e-Commerce requirements | E12: Salaheldin Eissa | F12: Delivered | H12: https://saranistudio.sharepoint.com/:f:/s/SaraniAssets/EkGsjWKwWBdNo92cvWcbFmIBDmg7UU7BNHnNnlAV7tbrbQ?e=9kZquS | J12: =IF(SUM(W12:BH12)=0,"-",SUM(Y12:BH12)) -> 20 | K12: =IF(SUMPRODUCT($Y$3:$BK$3,Y12:BK12)=0,"-",SUMPRODUCT($Y$3:$BK$3,Y12:BK12)) -> 700 | L12: https://saranistudio.sharepoint.com/:b:/s/SaraniAssets/ERLzEICCYB9JsOanEIfbsbUB24lTwltStsYbTEJZn-KMAQ?e=BnPlLf | M12: ME25-147 | N12: Sent via Whatsapp | O12: F2025-0552 | P12: Paid 02/03/2026 | Q12: =IF(SUM(Y12:AR12)+SUM(AZ12:BA12)+SUM(BB12:BE12)>0,"X","") -> X | R12: =IF(SUM(AS12:AY12)>0,"X","") | S12: =IF(SUM(BF12:BG12)>0,"X","") | Z12: 20
A13: Aujan | B13: Rani | C13: 45868 | D13: Rani extra adaptations sizes | E13: Salaheldin Eissa | F13: Delivered | J13: =IF(SUM(W13:BH13)=0,"-",SUM(Y13:BH13)) -> 4 | K13: =IF(SUMPRODUCT($Y$3:$BK$3,Y13:BK13)=0,"-",SUMPRODUCT($Y$3:$BK$3,Y13:BK13)) -> 140 | L13: https://saranistudio.sharepoint.com/:b:/s/SaraniAssets/ERLzEICCYB9JsOanEIfbsbUB24lTwltStsYbTEJZn-KMAQ?e=BnPlLf | M13: ME25-147 | N13: Sent via Whatsapp | O13: F2025-0552 | P13: Paid 02/03/2026 | Q13: =IF(SUM(Y13:AR13)+SUM(AZ13:BA13)+SUM(BB13:BE13)>0,"X","") -> X | R13: =IF(SUM(AS13:AY13)>0,"X","") | S13: =IF(SUM(BF13:BG13)>0,"X","") | Z13: 4
A14: Aujan | B14: Rani | C14: 45883 | D14: Rani B2S Assets x Jordan | E14: Salaheldin Eissa | F14: Delivered | H14: https://saranistudio.sharepoint.com/:f:/s/SaraniAssets/Eub3DkmaJ0dArsGysEjNcEQBDJL1OJXsiGkKUt9ytJOTtg?e=8f0Mnv | J14: =IF(SUM(W14:BH14)=0,"-",SUM(Y14:BH14)) -> 4 | K14: =IF(SUMPRODUCT($Y$3:$BK$3,Y14:BK14)=0,"-",SUMPRODUCT($Y$3:$BK$3,Y14:BK14)) -> 245 | L14: https://saranistudio.sharepoint.com/:b:/s/SaraniAssets/ERLzEICCYB9JsOanEIfbsbUB24lTwltStsYbTEJZn-KMAQ?e=BnPlLf | M14: ME25-147 | N14: Sent via Whatsapp | O14: F2025-0552 | P14: Paid 02/03/2026 | Q14: =IF(SUM(Y14:AR14)+SUM(AZ14:BA14)+SUM(BB14:BE14)>0,"X","") -> X | R14: =IF(SUM(AS14:AY14)>0,"X","") | S14: =IF(SUM(BF14:BG14)>0,"X","") | Y14: 1 | Z14: 3
A15: Aujan | B15: Rani | C15: 45883 | D15: Off shelf display to be adapted - BTS 2025 | E15: Ahsan I Sheikh | F15: Delivered | H15: https://saranistudio.sharepoint.com/:f:/s/SaraniAssets/EqhSHDWzlhxKpkyEh-QtEtUB_1srWAMbpRz3H4HzUGoBzg?e=NCXQdU | J15: =IF(SUM(W15:BH15)=0,"-",SUM(Y15:BH15)) -> 1 | K15: =IF(SUMPRODUCT($Y$3:$BK$3,Y15:BK15)=0,"-",SUMPRODUCT($Y$3:$BK$3,Y15:BK15)) -> 45 | L15: https://saranistudio.sharepoint.com/:b:/s/SaraniAssets/Eb47FcBEyepGuJFU0jxIwMUBn5pF4jTRbQkhtS8bIpBv1g?e=UO4dNK | M15: VM25-077 | N15: Sent via Whatsapp | O15: F2025-0553 | P15: Paid 09/02/2026 | Q15: =IF(SUM(Y15:AR15)+SUM(AZ15:BA15)+SUM(BB15:BE15)>0,"X","") -> X | R15: =IF(SUM(AS15:AY15)>0,"X","") | S15: =IF(SUM(BF15:BG15)>0,"X","") | AH15: 1
A16: Aujan | B16: Rani | C16: 45887 | D16: BTS Campaign | E16: Ahsan I Sheikh | F16: Delivered | H16: https://saranistudio.sharepoint.com/:f:/s/SaraniAssets/EjOQJmE1JpxHnpnd6y4fA88Bp0yX1IOXaoOgurZf_e7PuQ?e=BA2fSE | J16: =IF(SUM(W16:BH16)=0,"-",SUM(Y16:BH16)) -> 9 | K16: =IF(SUMPRODUCT($Y$3:$BK$3,Y16:BK16)=0,"-",SUMPRODUCT($Y$3:$BK$3,Y16:BK16)) -> 315 | L16: https://saranistudio.sharepoint.com/:b:/s/SaraniAssets/Eb47FcBEyepGuJFU0jxIwMUBn5pF4jTRbQkhtS8bIpBv1g?e=UO4dNK | M16: VM25-077 | N16: Sent via Whatsapp | O16: F2025-0553 | P16: Paid 09/02/2026 | Q16: =IF(SUM(Y16:AR16)+SUM(AZ16:BA16)+SUM(BB16:BE16)>0,"X","") -> X | R16: =IF(SUM(AS16:AY16)>0,"X","") | S16: =IF(SUM(BF16:BG16)>0,"X","") | Z16: 9
A17: Aujan | B17: Vimto | C17: 45951 | D17: Vimto Annual Gala Dinner in Dubai | E17: Hassaan Nadeem | F17: Delivered | H17: https://saranistudio.sharepoint.com/:f:/s/SaraniAssets/EmoSxgGX0ZFGp9zmOs88OqIBStiujet6TFM19uVkMWmPdA?e=7DsDMK | K17: =IF(SUMPRODUCT($Y$3:$BK$3,Y17:BK17)=0,"-",SUMPRODUCT($Y$3:$BK$3,Y17:BK17)) -> 285 | L17: https://saranistudio.sharepoint.com/:b:/s/SaraniAssets/EZUBdJlRKjBJrld_-xJ9TnEBR3HCFhelng-0tVFfSTOpXg?e=F85sWv | M17: VM25-089 | N17: Sent to Ameena | O17: F2025-0646 | P17: Paid 27/02/2026 | Z17: 1 | AA17: 1
A18: Aujan | B18: Vimto | C18: 45902 | D18: Vimto KV reworked | E18: Nazanin Ahmadian | F18: Delivered | H18: https://saranistudio.sharepoint.com/:f:/s/SaraniAssets/Eml_0HjXGYxOqF-9D8pm-L8BBufffWzZNwbugSrWrPRhLw?e=DwwvYb | J18: =IF(SUM(W18:BH18)=0,"-",SUM(Y18:BH18)) -> 4 | K18: =IF(SUMPRODUCT($Y$3:$BK$3,Y18:BK18)=0,"-",SUMPRODUCT($Y$3:$BK$3,Y18:BK18)) -> 245 | L18: - | M18: PO971910 | N18: Sent via Whatsapp | O18: F2025-0689 | P18: Paid 19/11/2025 | Y18: 1 | Z18: 3
A19: Aujan | B19: Barbican | C19: 45912 | D19: Barbican 16:9 Video Resizing | E19: Hanan El Maghrabi | F19: Delivered | H19: https://saranistudio.sharepoint.com/:f:/s/SaraniAssets/Egp1ysYfju5LsLKMwrOUGv4BTCMXw4VHX4Y225jG2FlTuA?e=djcJKL | J19: =IF(SUM(W19:BH19)=0,"-",SUM(Y19:BH19)) -> 1 | K19: =IF(SUMPRODUCT($Y$3:$BK$3,Y19:BK19)=0,"-",SUMPRODUCT($Y$3:$BK$3,Y19:BK19)) -> 90 | L19: - | M19: PO971910 | N19: Sent via Whatsapp | O19: F2025-0689 | P19: Paid 19/11/2025 | AS19: 1
A20: Aujan | B20: Rani | C20: 45846 | D20: Rani billboard KV for Chad | E20: Nazanin Ahmadian | F20: Delivered | H20: https://saranistudio.sharepoint.com/:f:/s/SaraniAssets/Ek1pw5049QJNpPiOfA04WLwBEwKycWbAF9y_U2YXTG7AAQ?e=pkyrln | J20: =IF(SUM(W20:BH20)=0,"-",SUM(Y20:BH20)) -> 2 | K20: =IF(SUMPRODUCT($Y$3:$BK$3,Y20:BK20)=0,"-",SUMPRODUCT($Y$3:$BK$3,Y20:BK20)) -> 175 | L20: - | M20: PO971867 | N20: Sent via Whatsapp | O20: F2025-0690 | P20: Paid 19/11/2025 | Q20: =IF(SUM(Y20:AR20)+SUM(AZ20:BA20)+SUM(BB20:BE20)>0,"X","") -> X | R20: =IF(SUM(AS20:AY20)>0,"X","") | S20: =IF(SUM(BF20:BG20)>0,"X","") | Y20: 1 | Z20: 1
A21: Aujan | B21: Rani-Barbican | C21: 45849 | D21: POSM menu | E21: Nazanin Ahmadian | F21: Delivered | H21: https://saranistudio.sharepoint.com/:f:/s/SaraniAssets/EiYtSe2Q1_NOgCfbKjo8UbIBLhxyBIv6SF1wRDja2yWAhg?e=k1IEEb | J21: =IF(SUM(W21:BH21)=0,"-",SUM(Y21:BH21)) -> 40 | K21: =IF(SUMPRODUCT($Y$3:$BK$3,Y21:BK21)=0,"-",SUMPRODUCT($Y$3:$BK$3,Y21:BK21)) -> 1400 | L21: - | M21: PO971867 | N21: Sent via Whatsapp | O21: F2025-0690 | P21: Paid 19/11/2025 | Q21: =IF(SUM(Y21:AR21)+SUM(AZ21:BA21)+SUM(BB21:BE21)>0,"X","") -> X | R21: =IF(SUM(AS21:AY21)>0,"X","") | S21: =IF(SUM(BF21:BG21)>0,"X","") | Z21: 40
A22: Aujan | B22: Rani | C22: 45868 | D22: Rani Pinacolada KV for the Netherlands | E22: Nazanin Ahmadian | F22: Delivered | H22: https://saranistudio.sharepoint.com/:f:/s/SaraniAssets/EnIK8mFvWKFEk0VmSFEjspMBoIrCB7NnaI_WDVszuYOWCg?e=JzRgks | J22: =IF(SUM(W22:BH22)=0,"-",SUM(Y22:BH22)) -> 1 | K22: =IF(SUMPRODUCT($Y$3:$BK$3,Y22:BK22)=0,"-",SUMPRODUCT($Y$3:$BK$3,Y22:BK22)) -> 35 | L22: - | M22: PO971867 | N22: Sent via Whatsapp | O22: F2025-0690 | P22: Paid 19/11/2025 | Q22: =IF(SUM(Y22:AR22)+SUM(AZ22:BA22)+SUM(BB22:BE22)>0,"X","") -> X | R22: =IF(SUM(AS22:AY22)>0,"X","") | S22: =IF(SUM(BF22:BG22)>0,"X","") | Z22: 1
A23: Aujan | B23: Rani | C23: 45882 | D23: Rani billboard KV for Chad - Lottery version | E23: Nazanin Ahmadian | F23: Delivered | H23: https://saranistudio.sharepoint.com/:f:/s/SaraniAssets/Ek1pw5049QJNpPiOfA04WLwBEwKycWbAF9y_U2YXTG7AAQ?e=pkyrln | J23: =IF(SUM(W23:BH23)=0,"-",SUM(Y23:BH23)) -> 3 | K23: =IF(SUMPRODUCT($Y$3:$BK$3,Y23:BK23)=0,"-",SUMPRODUCT($Y$3:$BK$3,Y23:BK23)) -> 105 | L23: - | M23: PO971867 | N23: Sent via Whatsapp | O23: F2025-0690 | P23: Paid 19/11/2025 | Q23: =IF(SUM(Y23:AR23)+SUM(AZ23:BA23)+SUM(BB23:BE23)>0,"X","") -> X | R23: =IF(SUM(AS23:AY23)>0,"X","") | S23: =IF(SUM(BF23:BG23)>0,"X","") | Z23: 3
A24: Aujan | B24: Barbican | C24: 45890 | D24: Barbican 330ML soft POSM | E24: Stephanie Barcena | F24: Delivered | H24: 20250821_Barbican 330ML soft POSM | J24: =IF(SUM(W24:BH24)=0,"-",SUM(Y24:BH24)) -> 9 | K24: =IF(SUMPRODUCT($Y$3:$BK$3,Y24:BK24)=0,"-",SUMPRODUCT($Y$3:$BK$3,Y24:BK24)) -> 720 | L24: https://saranistudio.sharepoint.com/:b:/s/SaraniAssets/ESfddoSqq4lOvg16h96mejwBFjtbZ5YU0ofT10bRT98aSw?e=5WJeiy | M24: ME25-177 | N24: Sent via Whatsapp | O24: F2025-0732 | P24: Waiting payment for 11/03/2026 | AG24: 3 | AH24: 6
A25: Aujan | B25: Rani | C25: 45909 | D25: BTS Ecom | E25: Stephanie Barcena | F25: Delivered | J25: =IF(SUM(W25:BH25)=0,"-",SUM(Y25:BH25)) -> 2 | K25: =IF(SUMPRODUCT($Y$3:$BK$3,Y25:BK25)=0,"-",SUMPRODUCT($Y$3:$BK$3,Y25:BK25)) -> 70 | L25: https://saranistudio.sharepoint.com/:b:/s/SaraniAssets/ESfddoSqq4lOvg16h96mejwBFjtbZ5YU0ofT10bRT98aSw?e=5WJeiy | M25: ME25-177 | N25: Sent via Whatsapp | O25: F2025-0732 | P25: Waiting payment for 11/03/2026 | Z25: 2
A26: Aujan | B26: Rani | C26: 45918 | D26: PET 4 Launch | E26: Stephanie Barcena | F26: Delivered | H26: https://saranistudio.sharepoint.com/:f:/s/SaraniAssets/EoESEZvVqVRFv1a_j6EsAvsB5ZpB3O1UEvqV-AocYVbfUg?e=vGND2n | J26: =IF(SUM(W26:BH26)=0,"-",SUM(Y26:BH26)) -> 62 | K26: =IF(SUMPRODUCT($Y$3:$BK$3,Y26:BK26)=0,"-",SUMPRODUCT($Y$3:$BK$3,Y26:BK26)) -> 3445 | L26: https://saranistudio.sharepoint.com/:b:/s/SaraniAssets/ESfddoSqq4lOvg16h96mejwBFjtbZ5YU0ofT10bRT98aSw?e=5WJeiy | M26: ME25-177 | N26: Sent via Whatsapp | O26: F2025-0732 | P26: Waiting payment for 11/03/2026 | AG26: 7 | AH26: 47 | AN26: 8
A27: Aujan | B27: Barbican | C27: 45945 | D27: Kick Off Summer Banner Resize | E27: Ahsan I Sheikh | F27: Delivered | H27: https://saranistudio.sharepoint.com/:f:/s/SaraniAssets/EpWJlFqZCdJNut7rIPRkslEBvEwjqz57JYYODToTI7BTWQ?e=wMvWfn | J27: =IF(SUM(W27:BH27)=0,"-",SUM(Y27:BH27)) -> 4 | K27: =IF(SUMPRODUCT($Y$3:$BK$3,Y27:BK27)=0,"-",SUMPRODUCT($Y$3:$BK$3,Y27:BK27)) -> 140 | L27: https://saranistudio.sharepoint.com/:b:/s/SaraniAssets/ESfddoSqq4lOvg16h96mejwBFjtbZ5YU0ofT10bRT98aSw?e=5WJeiy | M27: ME25-177 | N27: Sent via Whatsapp | O27: F2025-0732 | P27: Waiting payment for 11/03/2026 | Z27: 4
A28: Aujan | B28: Rani | C28: 45937 | D28: White Spaces presentation | E28: Caitlin Morrison | F28: Delivered | H28: https://saranistudio.sharepoint.com/:f:/r/sites/SaraniAssets/Shared%20Documents/03.%20Customers/18.%20Aujan/04.%20Aujan%20Corporate/02.%20Projects/20251007_White%20Spaces%20Presentation?csf=1&web=1&e=Ok9OUJ | J28: =IF(SUM(W28:BH28)=0,"-",SUM(Y28:BH28)) -> 54 | K28: =IF(SUMPRODUCT($Y$3:$BK$3,Y28:BK28)=0,"-",SUMPRODUCT($Y$3:$BK$3,Y28:BK28)) -> 1890 | L28: https://saranistudio.sharepoint.com/:b:/s/SaraniAssets/EU_q1zQnnnREiuFNIoMUmLABjTE7rtNJFHZjIE9D3zdj8g?e=ZTcfKw | M28: ME25-213 | N28: Sent via Whatsapp | O28: F2025-0808 | P28: Waiting payment for 10/04/2026 | AN28: 54
A29: Aujan | B29: Barbican | C29: 46006 | D29: Barbican Video Edits | E29: Nazanin Ahmadian | F29: Delivered | H29: https://saranistudio.sharepoint.com/:f:/s/SaraniAssets/IgAisjKKYxdURbYnIhrcW-0KAanLuUMyPsuaKQ24gb2iWM8?e=oyYvlV | J29: =IF(SUM(W29:BH29)=0,"-",SUM(Y29:BH29)) -> 1 | K29: =IF(SUMPRODUCT($Y$3:$BK$3,Y29:BK29)=0,"-",SUMPRODUCT($Y$3:$BK$3,Y29:BK29)) -> 90 | L29: Quote Proposal - Barbican Summer Fruits Adaptation.pdf | M29: PO971991 | N29: Sent by email | O29: F2026-0013 | P29: Waiting payment for 15/05/2026 | AS29: 1
A30: Aujan | B30: Barbican | C30: 46001 | D30: Barbican AFC - Copy Adaptation | E30: Emily Oswald | F30: Delivered | H30: https://saranistudio.sharepoint.com/:f:/s/SaraniAssets/IgC3g4zVpB29RoNfVgaluIcLASw6kNnkAp8s5yAa14tjA00?e=arxzKB | I30: AFC Barbican Final Videos | J30: =IF(SUM(W30:BH30)=0,"-",SUM(Y30:BH30)) -> 4 | K30: 750 | L30: https://saranistudio.sharepoint.com/:b:/s/SaraniAssets/IQCGv6taHQfQS4cvY4hYyvBCAeWANBK6-JWRqO66t27SNts?e=wsbXIh | M30: ME25-209 | N30: Sent by email | O30: F2026-0043 | P30: Waiting payment for 09/04/2026 | AS30: 2 | AT30: 2
A31: Aujan | B31: Vimto | C31: 45972 | D31: Confidential Vimto Visualisation | E31: Stephanie Barcena | F31: Delivered | H31: https://saranistudio.sharepoint.com/:f:/s/SaraniAssets/IgBXFvpPly7_RZKo-sZ5kBGXAdWXDLN02TayohpseKB6hNg?e=rlQoIu | I31: Deliverables F2026-0050 | J31: =IF(SUM(W31:BH31)=0,"-",SUM(Y31:BH31)) -> 4 | K31: =IF(SUMPRODUCT($Y$3:$BK$3,Y31:BK31)=0,"-",SUMPRODUCT($Y$3:$BK$3,Y31:BK31)) -> 350 | L31: 20251231_Quotation_Aujan_Vimto.pdf | M31: VM26-001 | N31: Sent by email | O31: F2026-0050 | P31: Waiting payment for 07/05/2026 | Y31: 2 | Z31: 2
A32: Aujan | B32: Vimto | C32: 46003 | D32: Hingrish Ramadan KV Adaptation | E32: Stephanie Barcena | F32: Delivered | H32: https://saranistudio.sharepoint.com/:f:/s/SaraniAssets/IgBgD2DxyccRSLTQ12MayhNpAYoA1Htzfj2D1w-k7QS_c1w?e=lzckgn | I32: Deliverables F2026-0050 | J32: =IF(SUM(W32:BH32)=0,"-",SUM(Y32:BH32)) -> 1 | K32: =IF(SUMPRODUCT($Y$3:$BK$3,Y32:BK32)=0,"-",SUMPRODUCT($Y$3:$BK$3,Y32:BK32)) -> 35 | L32: 20251231_Quotation_Aujan_Vimto.pdf | M32: VM26-001 | N32: Sent by email | O32: F2026-0050 | P32: Waiting payment for 07/05/2026 | Z32: 1
A33: Aujan | B33: Vimto | C33: 46006 | D33: Vimto Ramadan Stand Resize | E33: Stephanie Barcena | F33: Delivered | H33: 20251215_Vimto Ramadan Stand Resize | I33: Deliverables F2026-0050 | J33: =IF(SUM(W33:BH33)=0,"-",SUM(Y33:BH33)) -> 4 | K33: =IF(SUMPRODUCT($Y$3:$BK$3,Y33:BK33)=0,"-",SUMPRODUCT($Y$3:$BK$3,Y33:BK33)) -> 180 | L33: 20251231_Quotation_Aujan_Vimto.pdf | M33: VM26-001 | N33: Sent by email | O33: F2026-0050 | P33: Waiting payment for 07/05/2026 | AH33: 4
A34: Aujan | B34: Vimto | C34: 46006 | D34: Vimto Dispenser = NEW SIZE | E34: Stephanie Barcena | F34: Delivered | H34: 20251215_Vimto Dispenser = NEW SIZE | I34: Deliverables F2026-0050 | J34: =IF(SUM(W34:BH34)=0,"-",SUM(Y34:BH34)) -> 17 | K34: =IF(SUMPRODUCT($Y$3:$BK$3,Y34:BK34)=0,"-",SUMPRODUCT($Y$3:$BK$3,Y34:BK34)) -> 765 | L34: 20251231_Quotation_Aujan_Vimto.pdf | M34: VM26-001 | N34: Sent by email | O34: F2026-0050 | P34: Waiting payment for 07/05/2026 | AH34: 17
A35: Aujan | B35: Rani | C35: 45973 | D35: Arabic Asset Correction after Approval | E35: Stephanie Barcena | F35: Delivered | I35: Deliverables F2026-0051 | J35: =IF(SUM(W35:BH35)=0,"-",SUM(Y35:BH35)) -> 14 | K35: 300 | L35: 20251231_Quotation_Aujan_Rani.pdf | M35: ME26-002 | N35: Sent by email | O35: F2026-0051 | P35: Waiting payment for 07/05/2026 | Z35: 3 | AH35: 11
A36: Aujan | B36: Barbican | C36: 45987 | D36: KSA x Ninja camping season campaign | E36: Stephanie Barcena | F36: Delivered | H36: https://saranistudio.sharepoint.com/:f:/s/SaraniAssets/IgBdQWLZ09RTRYBsHKH5LuKlAYZKlnR0RM81Sk3WLA3avDw?e=HyyvZ2 | I36: Deliverables F2026-0051 | J36: =IF(SUM(W36:BH36)=0,"-",SUM(Y36:BH36)) -> 2 | K36: =IF(SUMPRODUCT($Y$3:$BK$3,Y36:BK36)=0,"-",SUMPRODUCT($Y$3:$BK$3,Y36:BK36)) -> 70 | L36: 20251231_Quotation_Aujan_Rani.pdf | M36: ME26-002 | N36: Sent by email | O36: F2026-0051 | P36: Waiting payment for 07/05/2026 | Z36: 2
A37: Aujan | B37: Rani | C37: 45999 | D37: Rani NEW VISID Truck | E37: Stephanie Barcena | F37: Delivered | H37: 20251208_Rani NEW VISID Truck | I37: Deliverables F2026-0051 | J37: =IF(SUM(W37:BH37)=0,"-",SUM(Y37:BH37)) -> 6 | K37: =IF(SUMPRODUCT($Y$3:$BK$3,Y37:BK37)=0,"-",SUMPRODUCT($Y$3:$BK$3,Y37:BK37)) -> 585 | L37: 20251231_Quotation_Aujan_Rani.pdf | M37: ME26-002 | N37: Sent by email | O37: F2026-0051 | P37: Waiting payment for 07/05/2026 | AG37: 3 | AH37: 3
A38: Aujan | B38: Rani-Barbican | C38: 46007 | D38: Rani Ramadan Resize | E38: Stephanie Barcena | F38: Delivered | H38: https://saranistudio.sharepoint.com/:f:/s/SaraniAssets/IgAw6AXp8E4XQ5Jdn3nZsHOiARlCp7F1TEWcOJv9ZGd2SI0?e=dnJgzK | I38: Deliverables F2026-0051 | J38: =IF(SUM(W38:BH38)=0,"-",SUM(Y38:BH38)) -> 4 | K38: =IF(SUMPRODUCT($Y$3:$BK$3,Y38:BK38)=0,"-",SUMPRODUCT($Y$3:$BK$3,Y38:BK38)) -> 180 | L38: 20251231_Quotation_Aujan_Rani.pdf | M38: ME26-002 | N38: Sent by email | O38: F2026-0051 | P38: Waiting payment for 07/05/2026 | AH38: 4
A39: Aujan | B39: Rani | C39: 45847 | D39: Rani Website | E39: Salaheldin Eissa | F39: Delivered | H39: https://www.figma.com/design/wgFWLMt0JyFNo1XIT50Fv8/Rani?node-id=0-1&t=k3t98FHwAj8KThGO-1 | J39: 1 | K39: 200 | L39: https://saranistudio.sharepoint.com/:b:/s/SaraniAssets/EWGmlhUbqwFApPnO3YTnRT8BO9Lf7Lf61DDM7I2hRf_IOQ?e=oP5v9B | M39: - | Q39: =IF(SUM(Y39:AR39)+SUM(AZ39:BA39)+SUM(BB39:BE39)>0,"X","") | R39: =IF(SUM(AS39:AY39)>0,"X","") | S39: =IF(SUM(BF39:BG39)>0,"X","")
A40: Aujan | B40: Rani | C40: 45887 | D40: OOH for Egypt | E40: Salaheldin Eissa | F40: Delivered | H40: https://saranistudio.sharepoint.com/:f:/s/SaraniAssets/Ert6mM-VNFtOnrUSasr1yVgBcPVjZs6cANcKKUG2dDCEtA?e=ScG3EW | J40: =IF(SUM(W40:BH40)=0,"-",SUM(Y40:BH40)) -> 26 | K40: =IF(SUMPRODUCT($Y$3:$BK$3,Y40:BK40)=0,"-",SUMPRODUCT($Y$3:$BK$3,Y40:BK40)) -> 1735 | L40: https://saranistudio.sharepoint.com/:b:/s/SaraniAssets/EWGmlhUbqwFApPnO3YTnRT8BO9Lf7Lf61DDM7I2hRf_IOQ?e=oP5v9B | M40: - | Z40: 11 | AS40: 15
...
